Workbook

Sheet MATRIZ
A1: MATRIZ DE DESPLIEGUE DE POLÍTICA DE CALIDAD DE BIOSTEEL DE COLOMBIA
A4: POLITICA DE CALIDAD | C4: En Biosteel de Colombia S.A, somos una empresa dedicada a la importación, comercialización y distribución de dispositivos médicos de alta calidad. Por ello, nuestros esfuerzos se centran en satisfacer las necesidades y expectativas de especialistas, instituciones del área de la salud y usuarios mediante el compromiso de ejecutar los procedimientos bajo el direccionamiento de altos estándares de calidad, garantizando el cumplimiento de los requisitos legales exigibles, el mejoramiento continuo de nuestros procesos, la optimización de nuestros recursos, el desarrollo integral de nuestros colaboradores, la consolidación de alianzas estratégicas con nuestros proveedores y el fortalecimiento de las relaciones comerciales
A9: PREMISAS | C9: OBJETIVOS | H9: OBJETIVO ESPECIFICO | I9: PROCESO | J9: RESPONSABLE | K9: INVOLUCRADOS DEL PROCESO | L9: PERSONAL RELACIONADO | M9: INDICADOR | N9: APLICA PARA SEDE | O9: FORMULACIÓN | P9: META | Q9: FRECUENCIA | R9: FUENTE DE DATOS | S9: ENERO | T9: FEBRERO | U9: MARZO | V9: ABRIL | W9: MAYO | X9: JUNIO | Y9: JULIO | Z9: AGOSTO | AA9: SEPTIEMBRE | AB9: OCTUBRE | AC9: NOVIEMBRE | AD9: DICIEMBRE
A10: 1 | B10: Importación, comercialización y distribución | C10: Respaldar los procesos de importación, comercialización y distribuición a los clientes mediante la recepción, acondicionamento, almacenamiento, manejo y suministro de dispositivo médicos acorde a las normas vigentes de sanidad. | H10: Evaluar el cumplimiento de entrega de las ordenes de compra de dispositivos medicos mediante el informe mensual de compra. | I10: Almacén Gerencia Administrativa | J10: Coordinador Logistico , Coordinador Asistencial, Gerente Administrativo | K10: Auxiliar Logistico, Asesor Quirúrgico, Auxiliar Administrativo | L10: Todo el personal de Biosteel De Colombia S.A | M10: % de Ordenes de Compra recibidas completas | N10: N/A | O10: (No. Ordenes de Compra recibidas completas/ No. Ordenes recibidas) X 100 | P10: >70% | Q10: Mensual | R10: Formato de Seguimiento a Proveedores | S10: ='1'!D11 -> 0.97798742 | T10: ='1'!D12 -> 0.97188755 | U10: ='1'!D13 -> 0.98653846 | V10: ='1'!D14 -> 0.94364162 | W10: ='1'!D15 -> 0.98432056 | X10: ='1'!D16 -> 0.93445378 | Y10: ='1'!D17 -> 0.95924765 | Z10: ='1'!D18 -> #DIV/0! | AA10: ='1'!D19 -> #DIV/0! | AB10: ='1'!D20 -> #DIV/0! | AC10: ='1'!D21 -> #DIV/0! | AD10: ='1'!D22 -> #DIV/0!
M11: Incumplimiento de disponibilidad de dispositivos médicos | N11: APLICA PARA SEDE | O11: Número de Cirugías canceladas por falta de disponibilidad DM/ Número de Cirugías programas con requerimientos de DM | P11: 0.1 | Q11: Mensual | R11: Formato de Ostesintesis Programas | S11: ='1'!D28 -> #DIV/0! | T11: ='1'!D29 -> #DIV/0! | U11: ='1'!E29 -> 0 | V11: ='1'!F29 -> 0 | W11: ='1'!G29 -> 0 | X11: ='1'!H29 -> 0 | Y11: ='1'!I29 -> 0 | Z11: ='1'!J29 -> 0 | AA11: ='1'!K29 -> 0 | ... AD11: ='1'!N29 -> 0
A12: 2 | B12: satisfacer las necesidades y expectativas de especialistas, instituciones del área de la salud y usuarios | C12: Crear estrategías de buen servicio que permitan optimizar el manejo de procesos y recursos con el fin de establecer mecanismos para garantizar la satisfacción del cliente. | H12: Analizar a través de las evaluciones de seguimiento y atencion de quejas, reclamos y sugerencias el cumplimiento del servicio, las condiciones del material utilizado y la habilidad del soporte tecnico, con el fin de implementar estrategias de buen servicio para garantizar la satisfaccion del cliente. | I12: Asistencia Técnica | J12: Coordinador Asistencial | K12: Asesor Quirúrgico | L12: Todo el personal de Biosteel De Colombia S.A | M12: Atención a Quejas, Reclamos y/o Sugerencias | N12: N/A | O12: No. Quejas, reclamos o sugerencias recibidos = a No. De quejas y reclamos atendidos | P12: 1 | Q12: Mensual | R12: Formato de quejas, reclamos o sugerencias | S12: ='2'!D28 -> #DIV/0! | T12: ='2'!D29 -> 1 | U12: ='2'!D30 -> 1 | V12: ='2'!D31 -> #DIV/0! | W12: ='2'!D32 -> #DIV/0! | X12: ='2'!D33 -> #DIV/0! | Y12: ='2'!D34 -> #DIV/0! | Z12: ='2'!D35 -> #DIV/0! | AA12: ='2'!D36 -> #DIV/0! | AB12: ='2'!D37 -> #DIV/0! | AC12: ='2'!D38 -> #DIV/0! | AD12: ='2'!D39 -> #DIV/0!
M13: Evaluaciones de Seguimiento | N13: APLICA PARA SEDE | O13: Sumatoria del resultado de todas las evaluaciones/ El total de las evaluaciones. | P13: 4.5 | Q13: Mensual | R13: Evaluación de seguimiento de asesorías quirúrgicas | S13: =('2'!B11+'2'!C11+'2'!D11)/3 -> 0 | T13: =('2'!B12+'2'!C12+'2'!D12)/3 -> 0 | U13: =('2'!B13+'2'!C13+'2'!D13)/3 -> 0 | V13: =('2'!B14+'2'!C14+'2'!D14)/3 -> 0 | W13: =('2'!B15+'2'!C15+'2'!D15)/3 -> 0 | X13: =('2'!B16+'2'!C16+'2'!D16)/3 -> 0 | Y13: =('2'!B17+'2'!C17+'2'!D17)/3 -> 0 | Z13: =('2'!B18+'2'!C18+'2'!D18)/3 -> 0 | AA13: =('2'!B19+'2'!C19+'2'!D19)/3 -> 0 | AB13: =('2'!B20+'2'!C20+'2'!D20)/3 -> 0 | AC13: =('2'!B21+'2'!C21+'2'!D21)/3 -> 0 | AD13: =('2'!B22+'2'!C22+'2'!D22)/3 -> 0
A14: 3 | B14: garantizando el cumplimiento de los requisitos legales exigibles, | C14: Garantizar a los clientes confiabilidad con el cumpliento del manual de requisitos de Capacidad de Almacenamiento y/o Acondicionamiento para dispositivos médicos. | H14: Verificar la calidad de los materiales de acuerdo a las especificaciones tecnicas del proveedor mediante el recibo a satisfaccion de mercancia garantizando a los clientes confiabilidad con el cumplimiento del manual de requisitos de capacidad de almacenamiento y/o acondicionamiento para dispositivos medicos | I14: Almacén, Asistencia Técnica | J14: Coordinador Logistico, Coordinador Asistencial | K14: Auxiliar de almacén, Asesor Quirúrgico | L14: Todo el personal de Biosteel De Colombia S.A | M14: Reportes de Tecnivigilancia | N14: N/A | O14: No. De Reportes presentados/ No. De Reportes Notificacos al INVIMA | P14: 1 | Q14: Trimestral | R14: Formato de Eventos o Incidentes Adversos | S14: N/A | T14: N/A | U14: ='3'!D28 -> N/A | V14: N/A | W14: N/A | X14: ='3'!D31 -> N/A | Y14: N/A | Z14: N/A | AA14: ='3'!D34 -> N/A | AB14: N/A | AC14: N/A | AD14: ='3'!D37 -> N/A
M15: % de cumplimientos de especificaciones técnicas | N15: APLICA PARA SEDE | O15: (No. De desviaciones encontradas/ No. De muestras verificadas) X 100 | P15: 1 | Q15: Mensual | R15: Formato de Recibido a satisfacción de DM | S15: ='3'!D11 -> #DIV/0! | T15: ='3'!D12 -> #DIV/0! | U15: ='3'!D13 -> #DIV/0! | V15: ='3'!D14 -> #DIV/0! | W15: ='3'!D15 -> #DIV/0! | X15: ='3'!D16 -> #DIV/0! | Y15: ='3'!D17 -> #DIV/0! | Z15: ='3'!D18 -> #DIV/0! | AA15: ='3'!D19 -> #DIV/0! | AB15: ='3'!D20 -> #DIV/0! | AC15: ='3'!D21 -> #DIV/0! | AD15: ='3'!D22 -> #DIV/0!
A16: 4 | B16: el mejoramiento continuo de nuestros procesos | C16: Planificar, ejecutar, verificar y retroalimentar el sistema de gestión de calidad, a través de identificaciones de acciones correctivas, preventivas y de mejora continúa. | H16: Verificar el cierre de los planes de Accion generados con el fin de comprobar la eficacia del sistema de Gestion de calidad. | I16: Gestión de Calidad | J16: Coordinador de Calidad | K16: _ | L16: Todo el personal de Biosteel De Colombia S.A | M16: Cierre de planes de acción | N16: N/A | O16: Planes de acción cerrados / No. Total de planes de acción | P16: >70% | Q16: Trimestral | R16: Consolidado de acciones correctivas, preventivas y de mejora. | S16: N/A | T16: N/A | U16: ='4'!D11:D13 -> #VALUE! | V16: N/A | W16: N/A | X16: ='4'!D14 -> #DIV/0! | Y16: N/A | Z16: N/A | AA16: ='4'!D17 -> #DIV/0! | AB16: N/A | AC16: N/A | AD16: ='4'!D20 -> #DIV/0!
A17: 5 | B17: optimización de nuestros recursos | C17: Consolidar un adecuado manejo financiero a traves de la contabilización adecuada, con el fin de generar confiabilidad entre los stakeholders de la compañía. | H17: Verificar el cumplimiento del presupuesto,conocer la utilidad generada y comparar lo vendido con lo radicado con el fin de conocer el estado financiero de la Organización. | I17: Contabilidad Facturación | J17: Líder de Contabilidad y Líder de Facturación | K17: Auxiliar de Contabilidad | L17: Todo el personal de Biosteel De Colombia S.A | M17: % Cumplimiento de presupuesto | N17: N/A | O17: Gasto real / Presupuesto | P17: >70% | Q17: Mensual | R17: Formato de Informe de Presupuestos | S17: ='5'!D11 -> 0.8031326 | T17: ='5'!D12 -> 1.0079417 | U17: ='5'!D13 -> 0.635261 | V17: ='5'!D14 -> 0.59411332 | W17: ='5'!D15 -> 0.79877763 | X17: ='5'!D16 -> 0.80764925 | Y17: ='5'!D17 -> 1.060838 | Z17: ='5'!D18 -> #DIV/0! | AA17: ='5'!D19 -> #DIV/0! | AB17: ='5'!D20 -> #DIV/0! | AC17: ='5'!D21 -> #DIV/0! | AD17: ='5'!D22 -> #DIV/0!
M18: Utilidad Mensual | N18: N/A | O18: Ventas - Cuentas por pagar - Gastos | P18: 1000000000 | Q18: Mensual | R18: Informes de cuentas por pagar y cuentas por cobrar | S18: ='5'!E27 -> 1104550109 | T18: ='5'!E28 -> -28701327 | U18: ='5'!E29 -> 48334645 | V18: ='5'!E30 -> 1021648076 | W18: ='5'!E31 -> 1133105517 | X18: ='5'!E32 -> 912417506 | Y18: ='5'!E33 -> 1080261326 | Z18: ='5'!E34 -> 0 | AA18: ='5'!E35 -> 0 | AB18: ='5'!E36 -> 0 | AC18: ='5'!E37 -> 0 | AD18: ='5'!E38 -> 0
M19: % Cumplimiento Facturado | N19: N/A | O19: Total ventas/ Total Facturado | P19: 0.9 | Q19: Mensual | R19: Informes de Facturación | S19: ='5'!E43 -> 1.0387364 | T19: ='5'!E44 -> 0.99662282 | U19: ='5'!E45 -> 0.90064458 | V19: ='5'!E46 -> 1.0397556 | W19: ='5'!E47 -> 1.0603782 | X19: ='5'!E48 -> 0.9756785 | Y19: ='5'!E49 -> 1.0328525 | Z19: ='5'!E50 -> #DIV/0! | AA19: ='5'!E51 -> #DIV/0! | AB19: ='5'!E52 -> #DIV/0! | AC19: ='5'!E53 -> #DIV/0! | AD19: ='5'!E54 -> #DIV/0!
M20: % Cumplimiento Radicado | N20: N/A | O20: Total Facturado/ Total Radicado | P20: 0.95 | Q20: Mensual | R20: Informes de Facturación | S20: ='5'!F43 -> 1.0687428 | T20: ='5'!F44 -> 1 | U20: ='5'!F45 -> 0.99999737 | V20: ='5'!F46 -> 1 | W20: ='5'!F47 -> 1 | X20: ='5'!F48 -> 1 | Y20: ='5'!F49 -> 1 | Z20: ='5'!F50 -> #DIV/0! | AA20: ='5'!F51 -> #DIV/0! | AB20: ='5'!F52 -> #DIV/0! | AC20: ='5'!F53 -> #DIV/0! | AD20: ='5'!F54 -> #DIV/0!
M21: % Facturas Anuladas | N21: N/A | O21: Facturas anuladas/ Facturas Generadas | P21: <5% | Q21: Mensual | R21: Cuadro de Control Facturas | S21: ='5'!D75 -> 0.012811868 | T21: ='5'!D76 -> 0.0074626866 | U21: ='5'!D77 -> 0.007390983 | V21: ='5'!D78 -> 0.0099933378 | W21: ='5'!D79 -> 0.012613875 | X21: ='5'!D80 -> 0.017241379 | Y21: ='5'!D81 -> 0.010323469 | Z21: ='5'!D82 -> #DIV/0! | AA21: ='5'!D83 -> #DIV/0! | AB21: ='5'!D84 -> #DIV/0! | AC21: ='5'!D85 -> #DIV/0! | AD21: ='5'!D86 -> #DIV/0!
M22: % Facturas Glosadas por EPS | N22: N/A | O22: Facturas Glosadas por EPS/ Facturas Generadas a EPS | P22: <30% | Q22: Mensual | R22: Notificaciones de Glosas | S22: ='5'!D91 -> 0.0013486177 | T22: ='5'!D92 -> 0.0052238806 | U22: ='5'!D93 -> 0.0007390983 | V22: ='5'!D94 -> 0.00066622252 | W22: ='5'!D95 -> 0.0021023125 | X22: ='5'!D96 -> 0.0032840722 | Y22: ='5'!D97 -> 0.00068823125 | Z22: ='5'!D98 -> #DIV/0! | AA22: ='5'!D99 -> #DIV/0! | AB22: ='5'!D100 -> #DIV/0! | AC22: ='5'!D101 -> #DIV/0! | AD22: ='5'!D102 -> #DIV/0!
A23: 6 | B23: el desarrollo integral de nuestros colaboradores, | C23: Establecer programas de formación permanentes, los cuales permitirán disponer de un personal con mayor nivel de cualificación para desempeñar las actividades comprendidas en el Sistema de gestión. | H23: Verificar el cumplimiento y eficacia del plan de formacion por medio de la evaluacion de capacitacion, la cual nos permita disponer de un personal con mayor nivel de cualificacion para desempeñar las actividades comprometidas en el sistema de gestion. | I23: Gestión Administrativa | J23: Gerente Administrativa | K23: _ | L23: Todo el personal de Biosteel De Colombia S.A | M23: Ejecución del programa de capacitación | N23: APLICA PARA SEDE | O23: (Capacitaciones ejecutadas / Capacitaciones planeadas)*100% | P23: >70% | Q23: Mensual | R23: Cronograma de capacitación | S23: ='6'!D11 -> 1 | T23: ='6'!D12 -> #DIV/0! | U23: ='6'!D13 -> #DIV/0! | V23: ='6'!D14 -> #DIV/0! | W23: ='6'!D15 -> #DIV/0! | X23: ='6'!D16 -> #DIV/0! | Y23: ='6'!D17 -> #DIV/0! | Z23: ='6'!D18 -> #DIV/0! | AA23: ='6'!D19 -> #DIV/0! | AB23: ='6'!D20 -> #DIV/0! | AC23: ='6'!D21 -> #DIV/0! | AD23: ='6'!D22 -> #DIV/0!
A24: 7 | B24: la consolidación de alianzas estratégicas solidas con nuestros proveedores | C24: Expandir y consolidar la relacion con proveedores buscando nuevas opciones en el mercado, diseñando herramientas y concertando acuerdos para adquirir beneficio mutuo. | H24: Analizar el cumpliento de nuestros proveedores a traves de un seguimiento mensual para determinar el desempeño con la empresa y consolidar la relacion con el proveedor, creando acuerdos para adquirir beneficios mutuos. | I24: Almacén, Gestión Administrativa | J24: Jefe de Almacén | K24: _ | L24: Todo el personal de Biosteel De Colombia S.A | M24: Evalución de Cumplimiento Proveedores | N24: N/A | O24: Sumatoria del resultado de todas las evaluaciones/ El total de las evaluaciones. | P24: >95 | Q24: Mensual | R24: Formato de Evaluación de Proveedores | S24: ='7'!D11 -> 96.944444 | T24: ='7'!D12 -> 96.5 | U24: ='7'!D13 -> 96.15 | V24: ='7'!D14 -> 97.695652 | W24: ='7'!D15 -> 97.6 | X24: ='7'!D16 -> 98.181818 | Y24: ='7'!D17 -> 97.52381 | Z24: ='7'!D18 -> #DIV/0! | AA24: ='7'!D19 -> #DIV/0! | AB24: ='7'!D20 -> #DIV/0! | AC24: ='7'!D21 -> #DIV/0! | AD24: ='7'!D22 -> #DIV/0!
A25: 8 | B25: el fortalecimiento de las relaciones comerciales con los clientes. | C25: Fortalecer las relaciones comerciales con los clientes brindadoles credibilidad en la comercilización de nuestros productos y en la prestación de un buen servicio, atraves de facilidades de pago, entregas oportunas y atención de requerimientos. | H25: Conocer el grado de aceptacion de nuestros clientes mediante la encuesta de satisfaccion con la finalidad de fortalecer las relaciones comerciales, brindandoles credibilidad en la comercializacion de nuestros productos y la prestacion de un buen servicio. | I25: Asistencia Técnica, Almacén, Facturación | J25: Coordinador Asistencial | K25: Auxiliar de Almacén, Asesor Quirúrgico, Auxiliar de Facturación, Auxiliar Administrativo | L25: Todo el personal de Biosteel De Colombia S.A | M25: Satisfacción del Cliente | N25: APLICA PARA SEDE | O25: Sumatoria del resultado de todas las evaluaciones/ El total de las evaluaciones. | P25: >4.5 | Q25: Semestral | R25: Formato de Satisfacción del Cliente | S25: N/A | T25: N/A | U25: N/A | V25: N/A | W25: N/A | X25: ='8'!D11 -> #DIV/0! | Y25: N/A | Z25: N/A | AA25: N/A | AB25: N/A | AC25: N/A | AD25: ='8'!#REF! -> #REF!

Sheet 1
C1: INDICADORES | I1: CODIGO: FOR-GC-011
I2: VERSION: 0
I3: PAGINA: 1 DE 8
A4: OBJETIVO GENERAL | C4: Respaldar los procesos de importación, comercialización y distribuición a los clientes mediante la recepción, acondicionamento, almacenamiento, manejo y suministro de dispositivo médicos acorde a las normas vigentes de sanidad.
A6: OBJETIVO ESPECIFICO | C6: Evaluar el cumplimiento de entrega de las ordenes de compra de dispositivos medicos mediante el informe mensual de compra.
A8: INDICADOR | B8: % de Ordenes de Compra recibidas completas
A9: FORMULA | B9: (No. Ordenes de Compra recibidas completas/ No. Ordenes totales recibidas)
A10: Meses | B10: No. Ordenes de Compra recibidas Completas | C10: No. De ordenes de compra totales | D10: % de Cumplimiento (>70%)
A11: Enero | B11: 622 | C11: 636 | D11: =B11/C11 -> 0.97798742
A12: Febrero | B12: 484 | C12: 498 | D12: =B12/C12 -> 0.97188755
A13: Marzo | B13: 513 | C13: 520 | D13: =B13/C13 -> 0.98653846
A14: Abril | B14: 653 | C14: 692 | D14: =B14/C14 -> 0.94364162
A15: Mayo | B15: 565 | C15: 574 | D15: =B15/C15 -> 0.98432056
A16: Junio | B16: 556 | C16: 595 | D16: =B16/C16 -> 0.93445378
A17: Julio | B17: 612 | C17: 638 | D17: =B17/C17 -> 0.95924765
A18: Agosto | D18: =B18/C18 -> #DIV/0!
A19: Septiembre | D19: =B19/C19 -> #DIV/0!
A20: Octubre | D20: =B20/C20 -> #DIV/0!
A21: Noviembre | D21: =B21/C21 -> #DIV/0!
A22: Diciembre | D22: =B22/C22 -> #DIV/0!
D23: =AVERAGE(D11:D16) -> 0.96647157
A25: INDICADOR | B25: % de incumplimiento de disponibilidad de dispositivos médicos
A26: FORMULA | B26: Número de Cirugías canceladas por falta de disponibilidad DM/ Número de Cirugías programas con requerimientos de DM
A27: Meses | B27: Número de Cirugías canceladas por falta de disponibilidad DM | C27: Número de Cirugías programas con requerimientos de DM | D27: % Incumplimiento de disponibilidad de DM
A28: Enero | D28: =B28/C28 -> #DIV/0!
A29: Febrero | D29: =B29/C29 -> #DIV/0!
A30: Marzo | D30: =B30/C30 -> #DIV/0!
A31: Abril | D31: =B31/C31 -> #DIV/0!
A32: Mayo | D32: =B32/C32 -> #DIV/0!
A33: Junio | D33: =B33/C33 -> #DIV/0!
A34: Julio | D34: =B34/C34 -> #DIV/0!
A35: Agosto | D35: =B35/C35 -> #DIV/0!
A36: Septiembre | D36: =B36/C36 -> #DIV/0!
A37: Octubre | D37: =B37/C37 -> #DIV/0!
A38: Noviembre | D38: =B38/C38 -> #DIV/0!
A39: Diciembre | D39: =B39/C39 -> #DIV/0!
D40: =AVERAGE(D28:D33) -> #DIV/0!
A41: Responsable: Coordinador Asistencial

Sheet 2
C1: INDICADORES | I1: CODIGO: FOR-GC-011
I2: VERSION: 0
I3: PAGINA: 2 DE 8
A4: OBJETIVO | C4: Crear estrategías de buen servicio que permitan optimizar el manejo de procesos y recursos con el fin de establecer mecanismos para garantizar la satisfacción del cliente.
A6: OBJETIVO ESPECIFICO | C6: Analizar a través de las evaluciones de seguimiento y atencion de quejas, reclamos y sugerencias el cumplimiento del servicio, las condiciones del material utilizado y la habilidad del soporte tecnico, con el fin de implementar estrategias de buen servicio para garantizar la satisfaccion del cliente.
A8: INDICADOR | B8: Evaluaciones de Seguimiento
A9: FORMULA | B9: Sumatoria del resultado de todas las evaluaciones/ El No. total de evaluaciones realizadas.
A10: Meses | B10: Cumplimiento del servicio (>4.5) | C10: Condiciones del Material Utilizado (>4.5) | D10: Habilidad Soporte Técnico (>4.5)
A11: Enero
A12: Febrero
A13: Marzo
A14: Abril
A15: Mayo
A16: Junio
A17: Julio
A18: Agosto
A19: Septiembre
A20: Octubre
A21: Noviembre
A22: Diciembre
D23: =AVERAGE(D11:D17) -> #DIV/0!
A25: INDICADOR | B25: Atención a Quejas, Reclamos y/o Sugerencias
A26: FORMULA | B26: No. Quejas, reclamosy/o sugerencias atendidas / a No. De quejas, reclamos y/o Sugerencias presentados * 100
A27: Meses | B27: Total de quejas, reclamos o sugerencias presentados | C27: Total de Quejas, Reclamos o sugerencias atendido | D27: Porcentaje de atención de Quejas, Reclamos o sugerencias
A28: Enero | B28: 0 | C28: 0 | D28: =C28/B28 -> #DIV/0!
A29: Febrero | B29: 2 | C29: 2 | D29: =C29/B29 -> 1
A30: Marzo | B30: 1 | C30: 1 | D30: =C30/B30 -> 1
A31: Abril | B31: 0 | C31: 0 | D31: =C31/B31 -> #DIV/0!
A32: Mayo | B32: 0 | C32: 0 | D32: =C32/B32 -> #DIV/0!
A33: Junio | B33: 0 | C33: 0 | D33: =C33/B33 -> #DIV/0!
A34: Julio | B34: 0 | C34: 0 | D34: =C34/B34 -> #DIV/0!
A35: Agosto | D35: =C35/B35 -> #DIV/0!
A36: Septiembre | D36: =C36/B36 -> #DIV/0!
A37: Octubre | D37: =C37/B37 -> #DIV/0!
A38: Noviembre | D38: =C38/B38 -> #DIV/0!
A39: Diciembre | D39: =C39/B39 -> #DIV/0!
D40: =AVERAGE(D29:D30) -> 1
A42: Responsable: Coordinador Asistencial

Sheet 3
C1: INDICADORES | I1: CODIGO: FOR-GC-011
I2: VERSION: 0
I3: PAGINA: 3 DE 8
A4: OBJETIVO | C4: Garantizar a los clientes confiabilidad con el cumpliento del manual de requisitos de Capacidad de Almacenamiento y/o Acondicionamiento para dispositivos médicos.
A6: OBJETIVO ESPECIFICO | C6: Verificar la calidad de los materiales de acuerdo a las especificaciones tecnicas del proveedor mediante el recibo a satisfaccion de mercancia garantizando a los clientes confiabilidad con el cumplimiento del manual de requisitos de capacidad de almacenamiento y/o acondicionamiento para dispositivos medicos
A8: INDICADOR | B8: % de cumplimientos de especificaciones técnicas
A9: FORMULA | B9: (No. De evaluaciones recibidas satisfactoriamente/ No. De muestras verificadas)
A10: Meses | B10: No. De evaluaciones recibidas satisfactoriamente | C10: No. De muestras verificadas | D10: % de Cumplimiento (100%)
A11: Enero | D11: =B11/C11 -> #DIV/0!
A12: Febrero | D12: =B12/C12 -> #DIV/0!
A13: Marzo | D13: =B13/C13 -> #DIV/0!
A14: Abril | D14: =B14/C14 -> #DIV/0!
A15: Mayo | D15: =B15/C15 -> #DIV/0!
A16: Junio | D16: =B16/C16 -> #DIV/0!
A17: Julio | D17: =B17/C17 -> #DIV/0!
A18: Agosto | D18: =B18/C18 -> #DIV/0!
A19: Septiembre | D19: =B19/C19 -> #DIV/0!
A20: Octubre | D20: =B20/C20 -> #DIV/0!
A21: Noviembre | D21: =B21/C21 -> #DIV/0!
A22: Diciembre | D22: =B22/C22 -> #DIV/0!
D23: =AVERAGE(D11:D16) -> #DIV/0!
A25: INDICADOR | B25: Reportes de Tecnovigilancia
A26: FORMULA | B26: No. De Reportes Notificados al INVIMA / No. De Reportes Presentados * 100
A27: Meses | B27: No. De Reportes presentados | C27: No. De Reportes Notificacos al INVIMA | D27: % de Cumplimiento (100%)
A28: Enero - Marzo | B28: 0 | C28: 0 | D28: N/A
A31: Abril - Junio | B31: 0 | C31: 0 | D31: N/A
A34: Julio - Septiembre | D34: N/A
A37: Octubre - Dicembre | D37: N/A
A41: Responsable: Coordinador Logistico y Coordinador Asistencial

Sheet 4
C1: INDICADORES | I1: CODIGO: FOR-GC-011
I2: VERSION: 0
I3: PAGINA: 4 DE 8
A4: OBJETIVO | C4: Planificar, ejecutar, verificar y retroalimentar el sistema de gestión de calidad, a través de identificaciones de acciones correctivas, preventivas y de mejora continúa.
A6: OBJETIVO ESPECIFICO | C6: Verificar el cierre de los planes de Accion generados con el fin de comprobar la eficacia del sistema de Gestion de calidad.
A8: INDICADOR | B8: Cierre de planes de acción
A9: FORMULA | B9: Planes de acción cerrados / No. Total de planes de acción
A10: Meses | B10: Planes de acción cerrados | C10: No. Total de planes de Accion | D10: % de Cumplimiento (100%)
A11: Enero - Marzo | B11: 3 | C11: 3 | D11: =B11/C11 -> 1
A14: Abril - Junio | B14: 0 | C14: 0 | D14: =B14/C14 -> #DIV/0!
A17: Julio - Septiembre | D17: =B17/C17 -> #DIV/0!
A20: Octubre - Dicembre | D20: =B20/C20 -> #DIV/0!
A25: Responsable: Coordinador De Calidad

Sheet 5
C1: INDICADORES | I1: CODIGO: FOR-GC-011
I2: VERSION: 0
I3: PAGINA: 5 DE 8
A4: OBJETIVO | C4: Consolidar un adecuado manejo financiero a traves de la contabilización adecuada, con el fin de generar confiabilidad entre los stakeholders de la compañía.
A6: OBJETIVO ESPECIFICO | C6: Verificar el cumplimiento del presupuesto,conocer la utilidad generada y comparar lo vendido con lo radicado con el fin de conocer el estado financiero de la Organización.
A8: INDICADOR | B8: Cumplimiento de presupuesto
A9: FORMULA | B9: Gasto real / Presupuesto
A10: Meses | B10: Gasto real | C10: Gasto presupuestado | D10: % de Cumplimiento (>90%)
A11: Enero | B11: 1.1095189e+09 | C11: 1381489054 | D11: =B11/C11 -> 0.8031326
A12: Febrero | B12: 1.5920672e+09 | C12: 1579523063 | D12: =B12/C12 -> 1.0079417
A13: Marzo | B13: 1.1306571e+09 | C13: 1779830840 | D13: =B13/C13 -> 0.635261
A14: Abril | B14: 1.2381869e+09 | C14: 2084092194 | D14: =B14/C14 -> 0.59411332
A15: Mayo | B15: 1.6318471e+09 | C15: 2042930361 | D15: =B15/C15 -> 0.79877763
A16: Junio | B16: 1.8055618e+09 | C16: 2235576684 | D16: =B16/C16 -> 0.80764925
A17: Julio | B17: 1758751035 | C17: 1657888410 | D17: =B17/C17 -> 1.060838
A18: Agosto | D18: =B18/C18 -> #DIV/0!
A19: Septiembre | D19: =B19/C19 -> #DIV/0!
A20: Octubre | D20: =B20/C20 -> #DIV/0!
A21: Noviembre | D21: =B21/C21 -> #DIV/0!
A22: Diciembre | D22: =B22/C22 -> #DIV/0!
A24: INDICADOR | B24: Utilidad Mensual
A25: FORMULA | B25: Ventas - Cuentas por pagar - Gastos
A26: Meses | B26: Ingresos | C26: Gastos | D26: Costo | E26: Utilidad (>1,000,000,000)
A27: Enero | B27: 2901045330 | C27: 447662255 | D27: 1348832966 | E27: =B27-C27-D27 -> 1104550109
A28: Febrero | B28: 2297069805 | C28: 1042547400 | D28: 1283223732 | E28: =B28-C28-D28 -> -28701327
A29: Marzo | B29: 2192281206 | C29: 877476864 | D29: 1266469697 | E29: =B29-C29-D29 -> 48334645
A30: Abril | B30: 2697669020 | C30: 341909709 | D30: 1334111235 | E30: =B30-C30-D30 -> 1021648076
A31: Mayo | B31: 2522854957 | C31: 247669381 | D31: 1142080059 | E31: =B31-C31-D31 -> 1133105517
A32: Junio | B32: 2190139718 | C32: 259613647 | D32: 1018108565 | E32: =B32-C32-D32 -> 912417506
A33: Julio | B33: 2539741539 | C33: 296779525 | D33: 1162700688 | E33: =B33-C33-D33 -> 1080261326
A34: Agosto | E34: =B34-C34-D34 -> 0
A35: Septiembre | E35: =B35-C35-D35 -> 0
A36: Octubre | E36: =B36-C36-D36 -> 0
A37: Noviembre | E37: =B37-C37-D37 -> 0
A38: Diciembre | E38: =B38-C38-D38 -> 0
A40: INDICADOR | B40: % Cumplimiento de Facturación y Radicado
A41: FORMULA | B41: Total ventas/ Total Facturado Total Facturado/ Total Radicado
A42: Meses | B42: Total Ventas Mensual | C42: Total facturado mensual | D42: Total radicado | E42: % de cumplimiento de facturación (>90%) | F42: % de cumplimiento de radicado (>95%)
A43: Enero | B43: 4615615421 | C43: 4794407580 | D43: 5123988584 | E43: =C43/B43 -> 1.0387364 | F43: =D43/C43 -> 1.0687428
A44: Febrero | B44: 3892782823 | C44: 3879636181 | D44: 3879636181 | E44: =C44/B44 -> 0.99662282 | F44: =D44/C44 -> 1
...

Sheet 6
C1: INDICADORES | I1: CODIGO: FOR-GC-011
I2: VERSION: 0
I3: PAGINA: 6 DE 8
A4: OBJETIVO | C4: Establecer programas de formación permanentes, los cuales permitirán disponer de un personal con mayor nivel de cualificación para desempeñar las actividades comprendidas en el Sistema de gestión
A6: OBJETIVO ESPECIFICO | C6: Verificar el cumplimiento y eficacia del plan de formacion por medio de la evaluacion de capacitacion, la cual nos permita disponer de un personal con mayor nivel de cualificacion para desempeñar las actividades comprometidas en el sistema de gestion.
A8: INDICADOR | B8: Ejecución del programa de capacitación
A9: FORMULA | B9: Capacitaciones ejecutadas / Capacitaciones planeadas
A10: Meses | B10: Capacitaciones ejecutadas | C10: Capacitaciones planeadas | D10: % de Cumplimiento (>70%)
A11: Enero | B11: 1 | C11: 1 | D11: =B11/C11 -> 1
A12: Febrero | D12: =B12/C12 -> #DIV/0!
A13: Marzo | D13: =B13/C13 -> #DIV/0!
A14: Abril | D14: =B14/C14 -> #DIV/0!
A15: Mayo | D15: =B15/C15 -> #DIV/0!
A16: Junio | D16: =B16/C16 -> #DIV/0!
A17: Julio | D17: =B17/C17 -> #DIV/0!
A18: Agosto | D18: =B18/C18 -> #DIV/0!
A19: Septiembre | D19: =B19/C19 -> #DIV/0!
A20: Octubre | D20: =B20/C20 -> #DIV/0!
A21: Noviembre | D21: =B21/C21 -> #DIV/0!
A22: Diciembre | D22: =B22/C22 -> #DIV/0!
B23: =SUM(B11:B22)/41 -> 0.024390244 | C23: =SUM(C11:C22)/41 -> 0.024390244
A24: Responsable: Lider de Gestion Humana / coordinador asistencial valle

Sheet 7
C1: INDICADORES | I1: CODIGO: FOR-GC-011
I2: VERSION: 0
I3: PAGINA: 7 DE 8
A4: OBJETIVO | C4: Expandir y consolidar la relacion con proveedores buscando nuevas opciones en el mercado, diseñando herramientas y concertando acuerdos para adquirir beneficio mutuo.
A6: OBJETIVO ESPECIFICO | C6: Analizar el cumpliento de nuestros proveedores a traves de un seguimiento mensual para determinar el desempeño con la empresa y consolidar la relacion con el proveedor, creando acuerdos para adquirir beneficios mutuos.
A8: INDICADOR | B8: Evalución de Cumplimiento Proveedores
A9: FORMULA | B9: Sumatoria del resultado de todas las evaluaciones/ El total de las evaluaciones.
A10: Meses | B10: Sumatoria del resultado de todas las evaluaciones | C10: No. total de evaluaciones realizadas. | D10: Calificación (>95)
A11: Enero | B11: 1745 | C11: 18 | D11: =B11/C11 -> 96.944444
A12: Febrero | B12: 1930 | C12: 20 | D12: =B12/C12 -> 96.5
A13: Marzo | B13: 1923 | C13: 20 | D13: =B13/C13 -> 96.15
A14: Abril | B14: 2247 | C14: 23 | D14: =B14/C14 -> 97.695652
A15: Mayo | B15: 1952 | C15: 20 | D15: =B15/C15 -> 97.6
A16: Junio | B16: 2160 | C16: 22 | D16: =B16/C16 -> 98.181818
A17: Julio | B17: 2048 | C17: 21 | D17: =B17/C17 -> 97.52381
A18: Agosto | D18: =B18/C18 -> #DIV/0!
A19: Septiembre | D19: =B19/C19 -> #DIV/0!
A20: Octubre | D20: =B20/C20 -> #DIV/0!
A21: Noviembre | D21: =B21/C21 -> #DIV/0!
A22: Diciembre | D22: =B22/C22 -> #DIV/0!
A24: Responsable: Jefe De Almacén | B24: Coordinador Logistico

Sheet 8
C1: INDICADORES | I1: CODIGO: FOR-GC-011
I2: VERSION: 0
I3: PAGINA: 8 DE 8
A4: OBJETIVO | C4: Fortalecer las relaciones comerciales con los clientes brindadoles credibilidad en la comercilización de nuestros productos y en la prestación de un buen servicio, atraves de facilidades de pago, entregas oportunas y atención de requerimientos.
A6: OBJETIVO ESPECIFICO | C6: Conocer el grado de aceptacion de nuestros clientes mediante la encuesta de satisfaccion con la finalidad de fortalecer las relaciones comerciales, brindandoles credibilidad en la comercializacion de nuestros productos y la prestacion de un buen servicio.
A8: INDICADOR | B8: Satisfacción del Cliente
A9: FORMULA | B9: Sumatoria del resultado de todas las encuestas/ El total de las encuestas.
A10: Meses | B10: Sumatoria del resultado de todas las encuestas | C10: No. total de encuestas realizadas. | D10: Calificación (>4.5)
A11: Primer trimestre | D11: =B11/C11 -> #DIV/0!
A14: Segundo trimestre | D14: =B14/C14 -> #DIV/0!
A17: Tercer trimestre
A20: Cuarto trimestre
A24: Responsable: Coordinador de Calidad/ asistencial valle

Sheet ANALISIS
A1: ANALISIS DE INDICADORES 2019
A2: 1 | B2: RESPONSABLE | C2: MESES | D2: ENERO | E2: FEBRERO | F2: MARZO | G2: ABRIL | H2: MAYO | I2: JUNIO | J2: JULIO | K2: AGOSTO | L2: SEPTIEMBRE | M2: OCTUBRE | N2: NOVIEMBRE | O2: DICIEMBRE
C3: INDICADOR
B4: Almacen Coordinador Logistico | C4: % de incumplimiento de disponibilidad de dispositivos médicos | D4: En el mes de Enero de 2019 se cumplió con el indicador de incumplimiento de disponibilidad de Dispositivos Medicos debido a que se cumplio con las fechas y tiempos de entregas de lo solicitado. | E4: En el mes de Febrero de 2019 se cumplió con el indicador de incumplimiento de disponibilidad de Dispositivos Medicos debido a que se cumplio con las fechas y tiempos de entregas de lo solicitado. | F4: En el mes de Marzo de 2019 se cumplió con el indicador de incumplimiento de disponibilidad de Dispositivos Medicos debido a que se cumplio con las fechas y tiempos de entregas de lo solicitado. | G4: En el mes de Abril de 2019 se cumplió con el indicador de incumplimiento de disponibilidad de Dispositivos Medicos debido a que se cumplio con las fechas y tiempos de entregas de lo solicitado. | H4: En el mes de Mayo de 2019 se cumplió con el indicador de incumplimiento de disponibilidad de Dispositivos Medicos debido a que se cumplio con las fechas y tiempos de entregas de lo solicitado. | I4: En el mes de Junio de 2019 se cumplió con el indicador de incumplimiento de disponibilidad de Dispositivos Medicos debido a que se cumplio con las fechas y tiempos de entregas de lo solicitado. | J4: En el mes de Julio de 2019 se cumplió con el indicador de incumplimiento de disponibilidad de Dispositivos Medicos debido a que se cumplio con las fechas y tiempos de entregas de lo solicitado.
A5: 2 | B5: Asistencia Tecnica Coordinador Asistencial | C5: Evaluaciones de Seguimiento | D5: En el mes de Enero se cumplio el objetivo sin ningun tipo de inconvenientes | E5: En el mes de Febrero se alcanzaron los objetivos propuestos en nuestros indicadores, cumpliendo con buenas condiciones del material, , teniendo buen servicio y siendo oportunos en las asesorias quirurgicas. | F5: En el mes de marzo se cumplio el objetivo a satisfaccion. | G5: En el mes de Abril se cumplio el objetivo sin ningun tipo de inconvenientes | H5: Mes de mayo el objetivo fue cumplido dentro del promedio del indicdor. | I5: En el mes de junio, fue alcanzado el objetivo, con un excelente cumplimiento del servicio. | J5: En el mes de julio se sostuvo el promedio 4.9 en cuanto a cumplimiento de nuestros servicios, condiciones del material utilizado y habilidad del asesor quirurgico.
A6: 3 | B6: Almacen Coordinador Logistico | C6: % de cumplimientos de especificaciones técnicas | D6: En el mes de Enero de 2019 se cumplió con el indicador de cumplimiento de especificaciones tecnicas porque los dispositivos fueron recibidos en optimas condiciones. | E6: En el mes de Febrero de 2019 se cumplió con el indicador de cumplimiento de especificaciones tecnicas porque los dispositivos fueron recibidos en optimas condiciones. | F6: En el mes de Marzo de 2019 se cumplió con el indicador de cumplimiento de especificaciones tecnicas porque los dispositivos fueron recibidos en optimas condiciones. | G6: En el mes de Abril de 2019 se cumplió con el indicador de cumplimiento de especificaciones tecnicas porque los dispositivos fueron recibidos en optimas condiciones. | H6: En el mes de Mayo de 2019 se cumplió con el indicador de cumplimiento de especificaciones tecnicas porque los dispositivos fueron recibidos en optimas condiciones. | I6: En el mes de Junio de 2019 se cumplió con el indicador de cumplimiento de especificaciones tecnicas porque los dispositivos fueron recibidos en optimas condiciones. | J6: En el mes de Julio de 2019 se cumplió con el indicador de cumplimiento de especificaciones tecnicas porque los dispositivos fueron recibidos en optimas condiciones.
A7: 6 | B7: Gestion Humana Lider de Gestión Humana | C7: Ejecución del programa de capacitación | D7: En el mes de Enero de 2019 se cumplio el objetivo de realizar el 100% de las capacitaciones programadas las cuales fueron ejecutadas satisfactoriamente por cada proceso de nuestra empresa. | E7: En el mes de Febrero de 2019 se logro el cumplimiento de los objetivos propuestos con un puntaje del 100% , asi mismo las capacitaciones fueron desarrolladas para Bienestar de los empleados de Biosteel de colombia S.A. | F7: En el mes de Marzo se alcanzaron 100% de los objetivos propuestos en nuestros indicadores, cumpliendo asi con capacitaciones presenciales y virtuales. | G7: En el mes de Abril de 2019 se cumplió con el indicador de capacitaciones tenieno en cuenta las especificaciones del facilitador y la importancia de cada tema establecido. | H7: En el mes de Mayo se alcanzaron 100% de los objetivos propuestos en nuestros indicadores, en este mes se llevaron a cabo las capacitaciones según las necesidad de cada proceso de Biosteel de colombia S.A. | I7: En el mes de Junio de 2019 se logro el objetivo cumpliendo con el 100% de las capacitaciones, Estableciendo asi el sistema de gestion por competencias el cual permitio desarrollar diferentes habilidades en el Equipo de trabajo de Biosteel de colombia S.A | J7: En el mes de Julio se llevo acabo las capacitaciones correspondientes a Bienestar Laboral y Gestion de la calidad, Creando espacios beneficiosos para los empleados de nuestra empresa.
A8: 8 | B8: Asistencia Tecnica Coordinador Asistencial | C8: Satisfacción del Cliente
