Workbook

Sheet MATRIZ
A1: MATRIZ DE DESPLIEGUE DE POLÍTICA DE CALIDAD DE BIOSTEEL DE COLOMBIA
A4: POLITICA DE CALIDAD | C4: En Biosteel de Colombia S.A, somos una empresa dedicada a la importación, comercialización y distribución de dispositivos médicos de alta calidad. Por ello, nuestros esfuerzos se centran en satisfacer las necesidades y expectativas de especialistas, instituciones del área de la salud y usuarios mediante el compromiso de ejecutar los procedimientos bajo el direccionamiento de altos estándares de calidad, garantizando el cumplimiento de los requisitos legales exigibles, el mejoramiento continuo de nuestros procesos, la optimización de nuestros recursos, el desarrollo integral de nuestros colaboradores, la consolidación de alianzas estratégicas con nuestros proveedores y el fortalecimiento de las relaciones comerciales
A9: PREMISAS | C9: OBJETIVOS | H9: PROCESO | I9: INDICADOR | J9: FORMULACIÓN | K9: META | L9: FRECUENCIA | M9: FUENTE DE DATOS | N9: ENERO | O9: FEBRERO | P9: MARZO | Q9: ABRIL | R9: MAYO | S9: JUNIO | T9: JULIO | U9: AGOSTO | V9: SEPTIEMBRE | W9: OCTUBRE | X9: NOVIEMBRE | Y9: TOTAL
A10: 1 | B10: Importación, comercialización y distribución | C10: Respaldar los procesos de importación, comercialización y distribuición a los clientes mediante la recepción, acondicionamento, almacenamiento, manejo y suministro de dispositivo médicos acorde a las normas vigentes de sanidad. | H10: Almacén Gerencia Administrativa | I10: % de Ordenes de Compra recibidas completas | J10: (No. Ordenes de Compra recibidas completas/ No. Ordenes recibidas) X 100 | K10: >70% | L10: Mensual | M10: Formato de Seguimiento a Proveedores | N10: ='1'!D11 -> 0.9559387 | O10: ='1'!D12 -> 0.98396794 | P10: ='1'!D13 -> 0.98529412 | Q10: ='1'!D14 -> 0.9671848 | R10: ='1'!D15 -> 0.92130518 | S10: ='1'!D16 -> 0.94849023 | T10: ='1'!D17 -> 0.89102564 | U10: ='1'!D18 -> 0.93306288 | V10: ='1'!D19 -> 0.89911504 | W10: ='1'!D20 -> 0.925 | X10: ='1'!D21 -> 0.96496815 | Y10: =AVERAGE(N10:X10) -> 0.94321388
I11: % Incumplimiento de tiempos de entrega de dispositivos médicos especiales | J11: Número de DM especiales solicitados/ cumplimiento de tiempos de entrega de DM especiales | K11: 0.9 | L11: Mensual | M11: Formato de Ostesintesis Programas | N11: N/A | O11: N/A | P11: N/A | Q11: N/A | R11: N/A | S11: N/A | T11: ='1'!D35 -> 1 | U11: ='1'!D36 -> 1 | V11: ='1'!D37 -> 1 | W11: ='1'!D38 -> 1 | X11: ='1'!D39 -> 0.95348837 | Y11: =AVERAGE(N11:X11) -> 0.99069767
A12: 2 | B12: satisfacer las necesidades y expectativas de especialistas, instituciones del área de la salud y usuarios | C12: Crear estrategías de buen servicio que permitan optimizar el manejo de procesos y recursos con el fin de establecer mecanismos para garantizar la satisfacción del cliente. | H12: Asistencia Técnica | I12: Atención a Quejas, Reclamos y/o Sugerencias | J12: No. Quejas, reclamos o sugerencias recibidos = a No. De quejas y reclamos atendidos | K12: 1 | L12: Mensual | M12: Formato de quejas, reclamos o sugerencias | N12: 1 | O12: 1 | P12: ='2'!D31 -> N/A | Q12: 1 | R12: ='2'!D33 -> N/A | S12: 1 | T12: 1 | U12: ='2'!D36 -> N/A | V12: 1 | W12: 1 | X12: ='2'!D39 -> N/A | Y12: =AVERAGE(N12:X12) -> 1
I13: Evaluaciones de Seguimiento | J13: Sumatoria del resultado de todas las evaluaciones/ El total de las evaluaciones. | K13: 4.5 | L13: Mensual | M13: Evaluación de seguimiento de asesorías quirúrgicas | N13: =('2'!B11+'2'!C11+'2'!D11)/3 -> 4.7333333 | O13: =('2'!B12+'2'!C12+'2'!D12)/3 -> 4.8 | P13: =('2'!B13+'2'!C13+'2'!D13)/3 -> 4.7 | Q13: =('2'!B14+'2'!C14+'2'!D14)/3 -> 4.6333333 | R13: =('2'!B15+'2'!C15+'2'!D15)/3 -> 4.8 | S13: =('2'!B16+'2'!C16+'2'!D16)/3 -> 4.6333333 | T13: =('2'!B17+'2'!C17+'2'!D17)/3 -> 4.7 | U13: =('2'!B18+'2'!C18+'2'!D18)/3 -> 4.8 | V13: =('2'!B19+'2'!C19+'2'!D19)/3 -> 4.6666667 | W13: =('2'!B20+'2'!C20+'2'!D20)/3 -> 4.6666667 | X13: =('2'!B21+'2'!C21+'2'!D21)/3 -> 4.5 | Y13: =AVERAGE(N13:X13) -> 4.6939394
A14: 3 | B14: garantizando el cumplimiento de los requisitos legales exigibles, | C14: Garantizar a los clientes confiabilidad con el cumpliento del manual de requisitos de Capacidad de Almacenamiento y/o Acondicionamiento para dispositivos médicos. | H14: Almacén, Asistencia Técnica | I14: Reportes de Tecnivigilancia | J14: No. De Reportes presentados/ No. De Reportes Notificacos al INVIMA | K14: 1 | L14: Trimestral | M14: Formato de Eventos o Incidentes Adversos | N14: 1 | O14: 1 | P14: 1 | Q14: 1 | R14: 1 | S14: 1 | T14: 1 | U14: 1 | V14: 1 | W14: 1 | X14: 1 | Y14: 1
I15: % de cumplimientos de especificaciones técnicas | J15: (No. De desviaciones encontradas/ No. De muestras verificadas) X 100 | K15: 1 | L15: Mensual | M15: Formato de Seguimiento a Proveedores | N15: ='3'!D11 -> 1 | O15: ='3'!D12 -> 1 | P15: ='3'!D13 -> 1 | Q15: ='3'!D14 -> 1 | R15: ='3'!D15 -> 1 | S15: ='3'!D16 -> 1 | T15: ='3'!D17 -> 1 | U15: ='3'!D18 -> 1 | V15: ='3'!D19 -> 1 | W15: ='3'!D20 -> 1 | X15: ='3'!D21 -> 1 | Y15: =AVERAGE(N15:X15) -> 1
A16: 4 | B16: el mejoramiento continuo de nuestros procesos | C16: Planificar, ejecutar, verificar y retroalimentar el sistema de gestión de calidad, a través de identificaciones de acciones correctivas, preventivas y de mejora continúa. | H16: Gestión de Calidad | I16: Cierre de planes de acción | J16: Planes de acción cerrados / No. Total de planes de acción | K16: >70% | L16: Trimestral | M16: Consolidado de acciones correctivas, preventivas y de mejora. | N16: N/A | O16: N/A | P16: 1 | Q16: N/A | R16: N/A | S16: ='4'!D14 -> 1 | T16: N/A | U16: N/A | V16: ='4'!D17 -> 1 | W16: N/A | X16: N/A | Y16: =AVERAGE(P16,V16) -> 1
A17: 5 | B17: optimización de nuestros recursos | C17: Consolidar un adecuado manejo financiero a traves de la contabilización adecuada, con el fin de generar confiabilidad entre los stakeholders de la compañía. | H17: Contabilidad Facturación | I17: % Cumplimiento de presupuesto | J17: Gasto real / Presupuesto | K17: >70% | L17: Mensual | M17: Formato de Informe de Presupuestos | N17: ='5'!D11 -> 1.8489525 | O17: ='5'!D12 -> 1.511815 | P17: ='5'!D13 -> 1.3305288 | Q17: ='5'!D14 -> 1.0975338 | R17: ='5'!D15 -> 1.4060509 | S17: ='5'!D16 -> 1.106836 | T17: ='5'!D17 -> 1.298126 | U17: ='5'!D18 -> 1.2202305 | V17: ='5'!D19 -> 1.3101974 | W17: ='5'!D20 -> 1.1520154 | X17: ='5'!D21 -> 1.1191177 | Y17: =AVERAGE(N17:X17) -> 1.3092185
I18: Utilidad Mensual | J18: Ventas - Cuentas por pagar - Gastos | K18: 100% /1.000.000.000 | L18: Mensual | M18: Informes de cuentas por pagar y cuentas por cobrar | N18: ='5'!F28 -> 1.3623263 | O18: ='5'!F29 -> 1.6299052 | P18: ='5'!F30 -> 1.2958468 | Q18: ='5'!F31 -> 1.9858999 | R18: ='5'!F32 -> 1.6003363 | S18: ='5'!F33 -> 1.4817418 | T18: ='5'!F34 -> 1.6924407 | U18: ='5'!F35 -> 1.912227 | V18: ='5'!F36 -> 1.3940611 | W18: ='5'!F37 -> 1.3724601 | X18: ='5'!F38 -> 1.3655381 | Y18: =AVERAGE(N18:X18) -> 1.5538894
I19: % Cumplimiento Facturado | J19: Total ventas/ Total Facturado | K19: 0.9 | L19: Mensual | M19: Informes de Facturación | N19: ='5'!F46 -> 1.0052021 | O19: ='5'!F47 -> 0.9449315 | P19: ='5'!F48 -> 1.3071061 | Q19: ='5'!F49 -> 0.83199529 | R19: ='5'!F50 -> 0.99659985 | S19: ='5'!F51 -> 1.0376519 | T19: ='5'!F52 -> 0.93921546 | U19: ='5'!F53 -> 0.96539841 | V19: ='5'!F54 -> 1.0401505 | W19: ='5'!F55 -> 0.98306778 | X19: ='5'!F56 -> 0.97931303 | Y19: =AVERAGE(N19:X19) -> 1.0027847
I20: % Cumplimiento Radicado | J20: Total Facturado/ Total Radicado | K20: 0.95 | L20: Mensual | M20: Informes de Facturación | N20: ='5'!G46 -> 1.0568158 | O20: ='5'!G47 -> 0.98748077 | P20: ='5'!G48 -> 0.95391619 | Q20: ='5'!G49 -> 1.0018323 | R20: ='5'!G50 -> 1.0499855 | S20: ='5'!G51 -> 0.9985794 | T20: ='5'!G52 -> 0.99136228 | U20: ='5'!G53 -> 0.83762436 | V20: ='5'!G54 -> 1.1834116 | W20: ='5'!G55 -> 0.9946145 | X20: ='5'!G56 -> 1.0048764 | Y20: =AVERAGE(N20:X20) -> 1.0054999
I21: % Facturas Anuladas | J21: Facturas anuladas/ Facturas Generadas | K21: <5% | L21: Mensual | M21: Cuadro de Control Facturas | N21: ='5'!D79 -> 0.0090157776 | O21: ='5'!D80 -> 0.020895522 | P21: ='5'!D81 -> 0.011054422 | Q21: ='5'!D82 -> 0.020685197 | R21: ='5'!D83 -> 0.01443769 | S21: ='5'!D84 -> 0.010744436 | T21: ='5'!D85 -> 0.01340861 | U21: ='5'!D86 -> 0.0087778528 | V21: ='5'!D87 -> 0.0039277298 | W21: ='5'!D88 -> 0.00513573 | X21: ='5'!D89 -> 0.0063875089 | Y21: =AVERAGE(N21:X21) -> 0.011315498
I22: % Facturas Glosadas por EPS | J22: Facturas Glosadas por EPS/ Facturas Generadas a EPS | K22: <30% | L22: Mensual | M22: Notificaciones de Glosas | N22: ='5'!D95 -> 0 | O22: ='5'!D96 -> 0 | P22: ='5'!D97 -> 0 | Q22: ='5'!D98 -> 0 | R22: ='5'!D99 -> 0 | S22: ='5'!D100 -> 0 | T22: ='5'!D101 -> 0 | U22: ='5'!D102 -> 0 | V22: ='5'!D103 -> 0 | W22: ='5'!D104 -> 0 | X22: ='5'!D105 -> 0 | Y22: 0
A23: 6 | B23: el desarrollo integral de nuestros colaboradores, | C23: Establecer programas de formación permanentes, los cuales permitirán disponer de un personal con mayor nivel de cualificación para desempeñar las actividades comprendidas en el Sistema de gestión. | H23: Gestión Administrativa | I23: Ejecución del programa de capacitación | J23: (Capacitaciones ejecutadas / Capacitaciones planeadas)*100% | K23: >70% | L23: Mensual | M23: Cronograma de capacitación | N23: ='6'!D11 -> 1 | O23: ='6'!D12 -> 0.85714286 | P23: ='6'!D13 -> 0.85714286 | Q23: ='6'!D14 -> 0.85714286 | R23: ='6'!D15 -> 1 | S23: ='6'!D16 -> 0.8 | T23: ='6'!D17 -> 1 | U23: ='6'!D18 -> 1 | V23: ='6'!C23 -> 0.90243902 | W23: ='6'!D20 -> 1 | X23: ='6'!D21 -> 1 | Y23: =AVERAGE(N23:X23) -> 0.93398796
A24: 7 | B24: la consolidación de alianzas estratégicas solidas con nuestros proveedores | C24: Expandir y consolidar la relacion con proveedores buscando nuevas opciones en el mercado, diseñando herramientas y concertando acuerdos para adquirir beneficio mutuo. | H24: Almacén, Gestión Administrativa | I24: Evalución de Cumplimiento Proveedores | J24: Sumatoria del resultado de todas las evaluaciones/ El total de las evaluaciones. | K24: >95 | L24: Mensual | M24: Formato de Evaluación de Proveedores | N24: ='7'!D11 -> 99.875 | O24: ='7'!D12 -> 97.277778 | P24: ='7'!D13 -> 97.35 | Q24: ='7'!D14 -> 97.45 | R24: ='7'!D15 -> 97.9 | S24: ='7'!D16 -> 97.055556 | T24: ='7'!D17 -> 95.8 | U24: ='7'!D18 -> 96.368421 | V24: ='7'!D19 -> 97 | W24: ='7'!D20 -> 97.235294 | X24: ='7'!D21 -> 97.45 | Y24: =AVERAGE(N24:X24) -> 97.342004
A25: 8 | B25: el fortalecimiento de las relaciones comerciales con los clientes. | C25: Fortalecer las relaciones comerciales con los clientes brindadoles credibilidad en la comercilización de nuestros productos y en la prestación de un buen servicio, atraves de facilidades de pago, entregas oportunas y atención de requerimientos. | H25: Asistencia Técnica, Almacén, Facturación | I25: Satisfacción del Cliente | J25: Sumatoria del resultado de todas las evaluaciones/ El total de las evaluaciones. | K25: >4.5 | L25: Semestral | M25: Formato de Satisfacción del Cliente | N25: N/A | O25: N/A | P25: N/A | Q25: N/A | R25: N/A | S25: ='8'!D11 -> 4.7 | T25: N/A | U25: N/A | V25: N/A | W25: N/A | X25: N/A | Y25: =AVERAGE(S25) -> 4.7

Sheet 1
C1: INDICADORES | I1: CODIGO: FOR-GC-011
I2: VERSION: 0
I3: PAGINA: 1 DE 8
A4: OBJETIVO GENERAL | C4: Respaldar los procesos de importación, comercialización y distribuición a los clientes mediante la recepción, acondicionamento, almacenamiento, manejo y suministro de dispositivo médicos acorde a las normas vigentes de sanidad.
A6: OBJETIVO ESPECIFICO | C6: Evaluar el cumplimiento de entrega de las ordenes de compra de dispositivos medicos mediante el informe mensual de compra.
A8: INDICADOR | B8: % de Ordenes de Compra recibidas completas
A9: FORMULA | B9: (No. Ordenes de Compra recibidas completas/ No. Ordenes totales recibidas)
A10: Meses | B10: No. Ordenes de Compra recibidas Completas | C10: No. De ordenes de compra totales | D10: % de Cumplimiento (>70%)
A11: Enero | B11: 499 | C11: 522 | D11: =B11/C11 -> 0.9559387
A12: Febrero | B12: 491 | C12: 499 | D12: =B12/C12 -> 0.98396794
A13: Marzo | B13: 469 | C13: 476 | D13: =B13/C13 -> 0.98529412
A14: Abril | B14: 560 | C14: 579 | D14: =B14/C14 -> 0.9671848
A15: Mayo | B15: 480 | C15: 521 | D15: =B15/C15 -> 0.92130518
A16: Junio | B16: 534 | C16: 563 | D16: =B16/C16 -> 0.94849023
A17: Julio | B17: 556 | C17: 624 | D17: =B17/C17 -> 0.89102564
A18: Agosto | B18: 460 | C18: 493 | D18: =B18/C18 -> 0.93306288
A19: Septiembre | B19: 508 | C19: 565 | D19: =B19/C19 -> 0.89911504
A20: Octubre | B20: 518 | C20: 560 | D20: =B20/C20 -> 0.925
A21: Noviembre | B21: 606 | C21: 628 | D21: =B21/C21 -> 0.96496815
A22: Diciembre | B22: 596 | C22: 636 | D22: =B22/C22 -> 0.93710692
D23: =AVERAGE(D11:D22) -> 0.94270497
L24: =AVERAGE(D23,D40) -> 0.96192096
A25: INDICADOR | B25: % de incumplimiento de tiempos de entrega de dispositivos médicos
A26: FORMULA | B26: Número de DM especiales solicitados/ cumplimiento de tiempos de entrega de DM especiales
A27: Meses | B27: Número de DME solicitados | C27: Cumplimiento de tiempos de entrega de DME | D27: % Incumplimiento de disponibilidad de DME >90%
A28: Enero | B28: N/A | C28: N/A | D28: N/A
A29: Febrero | B29: N/A | C29: N/A | D29: N/A
A30: Marzo | B30: N/A | C30: N/A | D30: N/A
A31: Abril | B31: N/A | C31: N/A | D31: N/A
A32: Mayo | B32: N/A | C32: N/A | D32: N/A
A33: Junio | B33: N/A | C33: N/A | D33: N/A
A34: Julio | B34: 15 | C34: 14 | D34: =C34/B34 -> 0.93333333
A35: Agosto | B35: 15 | C35: 15 | D35: =C35/B35 -> 1
A36: Septiembre | B36: 23 | C36: 23 | D36: =C36/B36 -> 1
A37: Octubre | B37: 28 | C37: 28 | D37: =C37/B37 -> 1
A38: Noviembre | B38: 13 | C38: 13 | D38: =C38/B38 -> 1
A39: Diciembre | B39: 43 | C39: 41 | D39: =C39/B39 -> 0.95348837
B40: =SUM(B34:B39) -> 137 | C40: =SUM(C34:C39) -> 134 | D40: =AVERAGE(D34:D39) -> 0.98113695
A41: Responsable: Coordinador Logistico

Sheet 2
C1: INDICADORES | I1: CODIGO: FOR-GC-011
I2: VERSION: 0
I3: PAGINA: 2 DE 8
A4: OBJETIVO | C4: Crear estrategías de buen servicio que permitan optimizar el manejo de procesos y recursos con el fin de establecer mecanismos para garantizar la satisfacción del cliente.
A6: OBJETIVO ESPECIFICO | C6: Analizar a través de las evaluciones de seguimiento y atencion de quejas, reclamos y sugerencias el cumplimiento del servicio, las condiciones del material utilizado y la habilidad del soporte tecnico, con el fin de implementar estrategias de buen servicio para garantizar la satisfaccion del cliente.
A8: INDICADOR | B8: Evaluaciones de Seguimiento
A9: FORMULA | B9: Sumatoria del resultado de todas las evaluaciones/ El No. total de evaluaciones realizadas.
A10: Meses | B10: Cumplimiento del servicio (>4.5) | C10: Condiciones del Material Utilizado (>4.5) | D10: Habilidad Soporte Técnico (>4.5)
A11: Enero | B11: 4.9 | C11: 4.5 | D11: 4.8
A12: Febrero | B12: 4.8 | C12: 4.7 | D12: 4.9
A13: Marzo | B13: 4.8 | C13: 4.4 | D13: 4.9
A14: Abril | B14: 4.7 | C14: 4.6 | D14: 4.6
A15: Mayo | B15: 4.8 | C15: 4.7 | D15: 4.9
A16: Junio | B16: 4.8 | C16: 4.4 | D16: 4.7
A17: Julio | B17: 4.7 | C17: 4.6 | D17: 4.8
A18: Agosto | B18: 4.8 | C18: 4.8 | D18: 4.8 | L18: (
A19: Septiembre | B19: 4.7 | C19: 4.6 | D19: 4.7
A20: Octubre | B20: 4.7 | C20: 4.6 | D20: 4.7
A21: Noviembre | B21: 4.5 | C21: 4.5 | D21: 4.5
A22: Diciembre | B22: 4.56 | C22: 4.64 | D22: 4.74
B23: =AVERAGE(B11:B22) -> 4.73 | C23: =AVERAGE(C11:C22) -> 4.5866667 | D23: =AVERAGE(D11:D22) -> 4.7533333 | K23: =AVERAGE(B23:D23) -> 4.69 | L23: =K23/K24*L24 -> 0.938
K24: 5 | L24: 1
A25: INDICADOR | B25: Atención a Quejas, Reclamos y/o Sugerencias
A26: FORMULA | B26: No. Quejas, reclamosy/o sugerencias atendidas / a No. De quejas, reclamos y/o Sugerencias presentados * 100 | L26: =AVERAGE(L23:L24) -> 0.969
A27: Meses | B27: Total de quejas, reclamos o sugerencias presentados | C27: Total de Quejas, Reclamos o sugerencias atendido | D27: Porcentaje de atención de Quejas, Reclamos o sugerencias
A28: Enero | B28: 0 | C28: 0 | D28: N/A
A29: Febrero | B29: 0 | C29: 0 | D29: N/A
A30: Marzo | B30: 3 | C30: 3 | D30: =C30/B30 -> 1
A31: Abril | B31: 0 | C31: 0 | D31: N/A
A32: Mayo | B32: 1 | C32: 1 | D32: =C32/B32 -> 1
A33: Junio | B33: 0 | C33: 0 | D33: N/A
A34: Julio | B34: 0 | C34: 0 | D34: N/A
A35: Agosto | B35: 1 | C35: 1 | D35: =C35/B35 -> 1
A36: Septiembre | B36: 0 | C36: 0 | D36: N/A
A37: Octubre | B37: 0 | C37: 0 | D37: N/A
A38: Noviembre | B38: 1 | C38: 1 | D38: =C38/B38 -> 1
A39: Diciembre | B39: 0 | C39: 0 | D39: N/A
A42: Responsable: Coordinador Asistencial

Sheet 3
C1: INDICADORES | I1: CODIGO: FOR-GC-011
I2: VERSION: 0
I3: PAGINA: 3 DE 8
A4: OBJETIVO | C4: Garantizar a los clientes confiabilidad con el cumpliento del manual de requisitos de Capacidad de Almacenamiento y/o Acondicionamiento para dispositivos médicos.
A6: OBJETIVO ESPECIFICO | C6: Verificar la calidad de los materiales de acuerdo a las especificaciones tecnicas del proveedor mediante el recibo a satisfaccion de mercancia garantizando a los clientes confiabilidad con el cumplimiento del manual de requisitos de capacidad de almacenamiento y/o acondicionamiento para dispositivos medicos
A8: INDICADOR | B8: % de cumplimientos de especificaciones técnicas
A9: FORMULA | B9: (No. De evaluaciones recibidas satisfactoriamente/ No. De muestras verificadas)
A10: Meses | B10: No. De evaluaciones recibidas satisfactoriamente | C10: No. De muestras verificadas | D10: % de Cumplimiento (100%)
A11: Enero | B11: 117 | C11: 117 | D11: =B11/C11 -> 1
A12: Febrero | B12: 105 | C12: 105 | D12: =B12/C12 -> 1
A13: Marzo | B13: 123 | C13: 123 | D13: =B13/C13 -> 1
A14: Abril | B14: 120 | C14: 120 | D14: =B14/C14 -> 1
A15: Mayo | B15: 121 | C15: 121 | D15: =B15/C15 -> 1
A16: Junio | B16: 161 | C16: 161 | D16: =B16/C16 -> 1
A17: Julio | B17: 110 | C17: 110 | D17: =B17/C17 -> 1
A18: Agosto | B18: 298 | C18: 298 | D18: =B18/C18 -> 1
A19: Septiembre | B19: 571 | C19: 571 | D19: =B19/C19 -> 1
A20: Octubre | B20: 527 | C20: 527 | D20: =B20/C20 -> 1
A21: Noviembre | B21: 510 | C21: 510 | D21: =B21/C21 -> 1
A22: Diciembre | B22: 372 | C22: 372 | D22: =B22/C22 -> 1
A24: INDICADOR | B24: Reportes de Tecnovigilancia
A25: FORMULA | B25: No. De Reportes Notificados al INVIMA / No. De Reportes Presentados * 100
A26: Meses | B26: No. De Reportes presentados | C26: No. De Reportes Notificacos al INVIMA | D26: % de Cumplimiento (100%)
A27: Enero - Marzo | B27: 0 | C27: 0 | D27: 1
A30: Abril - Junio | B30: 0 | C30: 0 | D30: 1
A33: Julio - Septiembre | B33: 0 | C33: 0 | D33: 1
A36: Octubre - Dicembre | B36: 0 | C36: 0 | D36: 1
A40: Responsable: Coordinador Logistico y Coordinador Asistencial

Sheet 4
C1: INDICADORES | I1: CODIGO: FOR-GC-011
I2: VERSION: 0
I3: PAGINA: 4 DE 8
A4: OBJETIVO | C4: Planificar, ejecutar, verificar y retroalimentar el sistema de gestión de calidad, a través de identificaciones de acciones correctivas, preventivas y de mejora continúa.
A6: OBJETIVO ESPECIFICO | C6: Verificar el cierre de los planes de Accion generados con el fin de comprobar la eficacia del sistema de Gestion de calidad.
A8: INDICADOR | B8: Cierre de planes de acción
A9: FORMULA | B9: Planes de acción cerrados / No. Total de planes de acción
A10: Meses | B10: Planes de acción cerrados | C10: No. Total de planes de Accion | D10: % de Cumplimiento (100%)
A11: Enero - Marzo | B11: 1 | C11: 1 | D11: =B11/C11 -> 1
A14: Abril - Junio | B14: 8 | C14: 8 | D14: =B14/C14 -> 1
A17: Julio - Septiembre | B17: 6 | C17: 6 | D17: =B17/C17 -> 1
A20: Octubre - Dicembre | B20: 0 | C20: 0 | D20: 0
D23: =AVERAGE(D11:D19) -> 1
A25: Responsable: Coordinador De Calidad

Sheet 5
C1: INDICADORES | I1: CODIGO: FOR-GC-011
I2: VERSION: 0
I3: PAGINA: 5 DE 8
A4: OBJETIVO | C4: Consolidar un adecuado manejo financiero a traves de la contabilización adecuada, con el fin de generar confiabilidad entre los stakeholders de la compañía.
A6: OBJETIVO ESPECIFICO | C6: Verificar el cumplimiento del presupuesto,conocer la utilidad generada y comparar lo vendido con lo radicado con el fin de conocer el estado financiero de la Organización.
A8: INDICADOR | B8: Cumplimiento de presupuesto
A9: FORMULA | B9: Gasto real / Presupuesto
A10: Meses | B10: Gasto real | C10: Gasto presupuestado | D10: % de Cumplimiento (>90%)
A11: Enero | B11: 2574378491 | C11: 1392344324 | D11: =B11/C11 -> 1.8489525
A12: Febrero | B12: 2013264678 | C12: 1331687190 | D12: =B12/C12 -> 1.511815
A13: Marzo | B13: 1.852132e+09 | C13: 1392027000 | D13: =B13/C13 -> 1.3305288
A14: Abril | B14: 1516821347 | C14: 1382027000 | D14: =B14/C14 -> 1.0975338
A15: Mayo | B15: 2533285826 | C15: 1801702771 | D15: =B15/C15 -> 1.4060509
A16: Junio | B16: 1994189417 | C16: 1801702771 | D16: =B16/C16 -> 1.106836
A17: Julio | B17: 2338837194 | C17: 1801702771 | D17: =B17/C17 -> 1.298126 | L17: =100*0.2 -> 20
A18: Agosto | B18: 2198492641 | C18: 1801702771 | D18: =B18/C18 -> 1.2202305
A19: Septiembre | B19: 2360586272 | C19: 1801702771 | D19: =B19/C19 -> 1.3101974
A20: Octubre | B20: 2075589295 | C20: 1801702771 | D20: =B20/C20 -> 1.1520154
A21: Noviembre | B21: 2016317502 | C21: 1801702771 | D21: =B21/C21 -> 1.1191177
A22: Diciembre | B22: 1443397437 | C22: 1801702771 | D22: =B22/C22 -> 0.80112961
D23: =AVERAGE(D11:D22) -> 1.2668778
A25: INDICADOR | B25: Utilidad Mensual
A26: FORMULA | B26: Ventas - Cuentas por pagar - Gastos
A27: Meses | B27: Ingresos | C27: Gastos | D27: Costo | E27: Utilidad (>1,000,000,000) | F27: % | G27: 1000000000
A28: Enero | B28: 2882988682 | C28: 3.7281224e+08 | D28: 1.1478502e+09 | E28: =B28-C28-D28 -> 1.3623263e+09 | F28: =E28*100%/$G$27 -> 1.3623263
A29: Febrero | B29: 3059505887 | C29: 2.812491e+08 | D29: 1.1483516e+09 | E29: =B29-C29-D29 -> 1.6299052e+09 | F29: =E29*100%/$G$27 -> 1.6299052
A30: Marzo | B30: 2626896812 | C30: 3.3247605e+08 | D30: 9.98574e+08 | E30: =B30-C30-D30 -> 1.2958468e+09 | F30: =E30*100%/$G$27 -> 1.2958468
A31: Abril | B31: 3679739696 | C31: 251924149 | D31: 1441915670 | E31: =B31-C31-D31 -> 1985899877 | F31: =E31*100%/$G$27 -> 1.9858999
A32: Mayo | B32: 2953010536 | C32: 242818908 | D32: 1109855298 | E32: =B32-C32-D32 -> 1600336330 | F32: =E32*100%/$G$27 -> 1.6003363
A33: Junio | B33: 2835120888 | C33: 272175091 | D33: 1081203976 | E33: =B33-C33-D33 -> 1481741821 | F33: =E33*100%/$G$27 -> 1.4817418
A34: Julio | B34: 3226505903 | C34: 291977681 | D34: 1242087477 | E34: =B34-C34-D34 -> 1692440745 | F34: =E34*100%/$G$27 -> 1.6924407
A35: Agosto | B35: 3433025588 | C35: 321321793 | D35: 1199476770 | E35: =B35-C35-D35 -> 1912227025 | F35: =E35*100%/$G$27 -> 1.912227
A36: Septiembre | B36: 2867011036 | C36: 267052289 | D36: 1205897615 | E36: =B36-C36-D36 -> 1394061132 | F36: =E36*100%/$G$27 -> 1.3940611
A37: Octubre | B37: 2972782996 | C37: 394425298 | D37: 1205897615 | E37: =B37-C37-D37 -> 1372460083 | F37: =E37*100%/$G$27 -> 1.3724601
A38: Noviembre | B38: 3284165521 | C38: 318563363 | D38: 1600064054 | E38: =B38-C38-D38 -> 1365538104 | F38: =E38*100%/$G$27 -> 1.3655381
A39: Diciembre | B39: 3063713121 | C39: 502200607 | D39: 1365350423 | E39: =B39-C39-D39 -> 1196162091 | F39: =E39*100%/$G$27 -> 1.1961621
A40: TOTALES | B40: =SUM(B28:B39) -> 36884466666 | C40: =SUM(C28:C39) -> 3.8489966e+09 | D40: =SUM(D28:D39) -> 1.4746525e+10 | E40: =SUM(E28:E39) -> 1.8288945e+10 | F40: =AVERAGE(F28:F39) -> 1.5240788
F41: =AVERAGE(F28:F40) -> 1.5240788
A43: INDICADOR | B43: % Cumplimiento de Facturación y Radicado
A44: FORMULA | B44: Total ventas/ Total Facturado Total Facturado/ Total Radicado
...

Sheet 6
C1: INDICADORES | I1: CODIGO: FOR-GC-011
I2: VERSION: 0
I3: PAGINA: 6 DE 8
A4: OBJETIVO | C4: Establecer programas de formación permanentes, los cuales permitirán disponer de un personal con mayor nivel de cualificación para desempeñar las actividades comprendidas en el Sistema de gestión
A6: OBJETIVO ESPECIFICO | C6: Verificar el cumplimiento y eficacia del plan de formacion por medio de la evaluacion de capacitacion, la cual nos permita disponer de un personal con mayor nivel de cualificacion para desempeñar las actividades comprometidas en el sistema de gestion.
A8: INDICADOR | B8: Ejecución del programa de capacitación
A9: FORMULA | B9: Capacitaciones ejecutadas / Capacitaciones planeadas
A10: Meses | B10: Capacitaciones ejecutadas | C10: Capacitaciones planeadas | D10: % de Cumplimiento (>70%)
A11: Enero | B11: 1 | C11: 1 | D11: =B11/C11 -> 1
A12: Febrero | B12: 6 | C12: 7 | D12: =B12/C12 -> 0.85714286
A13: Marzo | B13: 6 | C13: 7 | D13: =B13/C13 -> 0.85714286
A14: Abril | B14: 6 | C14: 7 | D14: =B14/C14 -> 0.85714286
A15: Mayo | B15: 1 | C15: 1 | D15: =B15/C15 -> 1
A16: Junio | B16: 4 | C16: 5 | D16: =B16/C16 -> 0.8
A17: Julio | B17: 1 | C17: 1 | D17: =B17/C17 -> 1
A18: Agosto | B18: 2 | C18: 2 | D18: =B18/C18 -> 1
A19: Septiembre | B19: 1 | C19: 1 | D19: =B19/C19 -> 1
A20: Octubre | B20: 2 | C20: 2 | D20: =B20/C20 -> 1
A21: Noviembre | B21: 1 | C21: 1 | D21: =B21/C21 -> 1
A22: Diciembre | B22: 2 | C22: 2 | D22: =B22/C22 -> 1
B23: =SUM(B11:B22)/41 -> 0.80487805 | C23: =SUM(C11:C22)/41 -> 0.90243902 | D23: =AVERAGE(D11:E22) -> 0.94761905
A24: Responsable: Lider de Gestion Humana

Sheet 7
C1: INDICADORES | I1: CODIGO: FOR-GC-011
I2: VERSION: 0
I3: PAGINA: 7 DE 8
A4: OBJETIVO | C4: Expandir y consolidar la relacion con proveedores buscando nuevas opciones en el mercado, diseñando herramientas y concertando acuerdos para adquirir beneficio mutuo.
A6: OBJETIVO ESPECIFICO | C6: Analizar el cumpliento de nuestros proveedores a traves de un seguimiento mensual para determinar el desempeño con la empresa y consolidar la relacion con el proveedor, creando acuerdos para adquirir beneficios mutuos.
A8: INDICADOR | B8: Evalución de Cumplimiento Proveedores
A9: FORMULA | B9: Sumatoria del resultado de todas las evaluaciones/ El total de las evaluaciones.
A10: Meses | B10: Sumatoria del resultado de todas las evaluaciones | C10: No. total de evaluaciones realizadas. | D10: Calificación (>95)
A11: Enero | B11: 1598 | C11: 16 | D11: =B11/C11 -> 99.875
A12: Febrero | B12: 1751 | C12: 18 | D12: =B12/C12 -> 97.277778
A13: Marzo | B13: 1947 | C13: 20 | D13: =B13/C13 -> 97.35
A14: Abril | B14: 1949 | C14: 20 | D14: =B14/C14 -> 97.45
A15: Mayo | B15: 1958 | C15: 20 | D15: =B15/C15 -> 97.9
A16: Junio | B16: 1747 | C16: 18 | D16: =B16/C16 -> 97.055556
A17: Julio | B17: 1916 | C17: 20 | D17: =B17/C17 -> 95.8
A18: Agosto | B18: 1831 | C18: 19 | D18: =B18/C18 -> 96.368421
A19: Septiembre | B19: 1940 | C19: 20 | D19: =B19/C19 -> 97
A20: Octubre | B20: 1653 | C20: 17 | D20: =B20/C20 -> 97.235294
A21: Noviembre | B21: 1949 | C21: 20 | D21: =B21/C21 -> 97.45
A22: Diciembre | B22: 1863 | C22: 19 | D22: =B22/C22 -> 98.052632
D23: =AVERAGE(D11:D22) -> 97.401223
A24: Responsable: Jefe De Almacén | B24: Coordinador Logistico

Sheet 8
C1: INDICADORES | I1: CODIGO: FOR-GC-011
I2: VERSION: 0
I3: PAGINA: 8 DE 8
A4: OBJETIVO | C4: Fortalecer las relaciones comerciales con los clientes brindadoles credibilidad en la comercilización de nuestros productos y en la prestación de un buen servicio, atraves de facilidades de pago, entregas oportunas y atención de requerimientos.
A6: OBJETIVO ESPECIFICO | C6: Conocer el grado de aceptacion de nuestros clientes mediante la encuesta de satisfaccion con la finalidad de fortalecer las relaciones comerciales, brindandoles credibilidad en la comercializacion de nuestros productos y la prestacion de un buen servicio.
A8: INDICADOR | B8: Satisfacción del Cliente
A9: FORMULA | B9: Sumatoria del resultado de todas las evaluaciones/ El total de las evaluaciones.
A10: Meses | B10: Sumatoria del resultado de todas las evaluaciones | C10: No. total de evaluaciones realizadas. | D10: Calificación (>4.5)
A11: Primer Semestre | B11: 23.5 | C11: 5 | D11: =B11/C11 -> 4.7
A17: Segundo Semestre | B17: 22.82 | C17: 5 | D17: =B17/C17 -> 4.564
D23: =AVERAGE(D11:D22) -> 4.632
A24: Responsable: Coordinador Asistencial - coordinador de Calidad
D26: 5 | E26: 1
D27: =AVERAGE(D11:D17) -> 4.632 | E27: =E26*D27/D26 -> 0.9264

Sheet ANALISIS
A1: ANALISIS DE INDICADORES
A2: 1 | B2: RESPONSABLE | C2: MESES | D2: ENERO | E2: FEBRERO | F2: MARZO | G2: ABRIL | H2: MAYO | I2: JUNIO | J2: JULIO | K2: AGOSTO | L2: SEPTIEMBRE | M2: OCTUBRE | N2: NOVIEMBRE | O2: DICIEMBRE
C3: INDICADOR
B4: Almacen Coordinador Logistico | C4: % de Ordenes de Compra recibidas completas | D4: En el mes de Enero de 2018 se cumplió con el indicador de compras debido a que los proveedores fueron oportunos en los tiempos de entrega. | E4: En el mes de Febrero de 2018 se cumplió con el indicador de compras debido a que los proveedores fueron oportunos en los tiempos de entrega. | F4: En el mes de Marzo de 2018 se cumplió con el indicador de compras debido a que los proveedores fueron oportunos en los tiempos de entrega. | G4: En el mes de Abril de 2018 se cumplió con el indicador de compras debido a que los proveedores fueron oportunos en los tiempos de entrega. | H4: En el mes de Mayo de 2018 se cumplió con el indicador de compras debido a que los proveedores fueron oportunos en los tiempos de entrega. | I4: En el mes de Junio de 2018 se cumplió con el indicador de compras debido a que los proveedores fueron oportunos en los tiempos de entrega. | J4: En el mes de Julio de 2018 se cumplió con el indicador de compras debido a que los proveedores fueron oportunos en los tiempos de entrega. | K4: En el mes de Agosto de 2018 se cumplió con el indicador de compras debido a que los proveedores fueron oportunos en los tiempos de entrega. | L4: En el mes de Septiembre de 2018 se cumplió con el indicador de compras debido a que los proveedores fueron oportunos en los tiempos de entrega. | M4: En el mes de Octubre de 2018 se cumplió con el indicador de compras debido a que los proveedores fueron oportunos en los tiempos de entrega. | N4: En el mes de Noviembre de 2018 se cumplió con el indicador de compras debido a que los proveedores fueron oportunos en los tiempos de entrega. | O4: En el mes de Diciembre de 2018 se cumplió con el indicador de compras debido a que los proveedores fueron oportunos en los tiempos de entrega.
B5: Almacen Coordinador Logistico | C5: % de incumplimiento de disponibilidad de dispositivos médicos | D5: N/A | E5: N/A | F5: N/A | G5: N/A | H5: N/A | I5: N/A | J5: En el mes de Julio de 2018 se cumplió con el indicador de incumplimiento de disponibilidad de Dispositivos Medicos debido a que se cumplio con las fechas y tiempos de entregas de lo solicitado. | K5: En el mes de Agsosto 2018 se cumplió con el indicador de incumplimiento de disponibilidad de Dispositivos Medicos debido a que se cumplio con las fechas y tiempos de entregas de lo solicitado. | L5: En el mes de Septiembre de 2018 se cumplió con el indicador de incumplimiento de disponibilidad de Dispositivos Medicos debido a que se cumplio con las fechas y tiempos de entregas de lo solicitado. | M5: En el mes de Octubre de 2018 se cumplió con el indicador de incumplimiento de disponibilidad de Dispositivos Medicos debido a que se cumplio con las fechas y tiempos de entregas de lo solicitado. | N5: En el mes de Noviembre de 2018 se cumplió con el indicador de incumplimiento de disponibilidad de Dispositivos Medicos debido a que se cumplio con las fechas y tiempos de entregas de lo solicitado. | O5: En el mes de Diciembre de 2018 se cumplió con el indicador de incumplimiento de disponibilidad de Dispositivos Medicos debido a que se cumplio con las fechas y tiempos de entregas de lo solicitado.
A6: 2 | B6: Asistencia Tecnica Coordinador Asistencial | C6: Evaluaciones de Seguimiento | D6: En el mes deEnero se cumplio con el indicador, ya que el servicio fue oportuno,, tanto por la asesoria quirurgica como por el material utilizado. | E6: En el mes de febrero se alcanzaron los objetivos propuestos en nuestros indicadores , teniendo buen servicio, cumpliendo con buenas condiciones del material y prestando buenas asesorias quirurgicas. | F6: En el mes de marzo, se logro mantener el buen servicio, tannto en el material como en la prestacion de asesorias quirurgicas. | G6: En el mes de Abril se cumplio con el indicador, ya que el servicio fue oportuno,, tanto por la asesoria quirurgica como por el material utilizado. | H6: En el mes de mayo se cumplio con el indicador, ya que el servicio fue oportuno,, tanto por la asesoria quirurgica como por el material utilizado. | I6: En el mes de junio se cumplio el objetivo sin ningun tipo de inconvenientes | J6: Indicador cumplido, cn un promedio de 4.7, manteniendo un servicio optimo y oportuno | K6: En el mes deagosto se alcanzaron los objetivos propuestos en nuestros indicadores , teniendo buen servicio, cumpliendo con buenas condiciones del material y prestando buenas asesorias quirurgicas. | L6: El indicador en el mes de septiembre fue alcanzado reiterando buen servicio con asesorias quirurgicas y material en optimas condiciones | M6: En el mes de octubre se cumplio con el indicador, ya que el servicio fue oportuno,, tanto por la asesoria quirurgica como por el material utilizado. | N6: En el mes de noviembre se cumplio el objetivo sin ningun tipo de inconvenientes | O6: En el mes de diciembre se alcanzaron los objetivos propuestos en nuestros indicadores
B7: Asistencia Tecnica Coordinador Asistencial | C7: Atención a Quejas, Reclamos y/o Sugerencias | D7: En el mes de enero no se genero, quejas, sugerencias o reclamos. | E7: En el mes de febrero no se ejecutaron, quejas, sugerencias o reclamos. | F7: En el mes de marzo recibimos dos queja y una sugerencia por parte de dos especialista, los cuales se hizo su respectiva accion correctiva para mantener el buen servicio que se ha presentado en meses anteriores. | G7: En el mes de abril, no se recepciono quejas reclamos o sugerencias. | H7: En el mes de mayo, se recepciono una quejas , la cual se le dio respuesta oportuna se le hizo el reporte al proveedor y se tomaron acciones pertinentes. | I7: En el mes de juniol, no se recepciono quejas reclamos o sugerencias. | J7: En el mes de julio, no se recepciono quejas reclamos o sugerencias. | K7: En el mes de agosto se evidencio una queja por parte de un especialista(santa marta), a la que se le dio respuesta y accion correctiva a la falla presentada. | L7: En el mes de septiembre no se recepciono quejas reclamos o sugerencias. | M7: En el mes de octubre no se recepciono quejas reclamos o sugerencias. | N7: En el mes de noviembre se presento por parte de la ips de santa marta una sugerencia, la cual fue atendida oportunamente tomandola como referencia para mejorar nuestros procesos. | O7: En el mes de diciembre no se recepciono quejas reclamos o sugerencias.
A8: 3 | B8: Almacen Coordinador Logistico | C8: % de cumplimientos de especificaciones técnicas | D8: En el mes de Enero de 2018 se cumplió con el indicador de cumplimiento de especificaciones tecnicas porque los dispositivos fueron recibidos en optimas condiciones. | E8: En el mes de Febrero de 2018 se cumplió con el indicador de cumplimiento de especificaciones tecnicas porque los dispositivos fueron recibidos en optimas condiciones. | F8: En el mes de Marzo de 2018 se cumplió con el indicador de cumplimiento de especificaciones tecnicas porque los dispositivos fueron recibidos en optimas condiciones. | G8: En el mes de Abril de 2018 se cumplió con el indicador de cumplimiento de especificaciones tecnicas porque los dispositivos fueron recibidos en optimas condiciones. | H8: En el mes de Mayo de 2018 se cumplió con el indicador de cumplimiento de especificaciones tecnicas porque los dispositivos fueron recibidos en optimas condiciones. | I8: En el mes de Junio de 2018 se cumplió con el indicador de cumplimiento de especificaciones tecnicas porque los dispositivos fueron recibidos en optimas condiciones. | J8: En el mes de Julio de 2018 se cumplió con el indicador de cumplimiento de especificaciones tecnicas porque los dispositivos fueron recibidos en optimas condiciones. | K8: En el mes de Agosto de 2018 se cumplió con el indicador de cumplimiento de especificaciones tecnicas porque los dispositivos fueron recibidos en optimas condiciones. | L8: En el mes de Septiembre de 2018 se cumplió con el indicador de cumplimiento de especificaciones tecnicas porque los dispositivos fueron recibidos en optimas condiciones. | M8: En el mes de Octubre de 2018 se cumplió con el indicador de cumplimiento de especificaciones tecnicas porque los dispositivos fueron recibidos en optimas condiciones. | N8: En el mes de Noviembre de 2018 se cumplió con el indicador de cumplimiento de especificaciones tecnicas porque los dispositivos fueron recibidos en optimas condiciones. | O8: En el mes de Diciembre de 2018 se cumplió con el indicador de cumplimiento de especificaciones tecnicas porque los dispositivos fueron recibidos en optimas condiciones.
B9: Tecnovigilancia Coordinador Asistencial | C9: Reportes de Tecnovigilancia | F9: En el primer trimestre que comprende 1 de enero a 30 de marzo de 2018 no se presentaron incidentes o eventos adversos relacionados con los dispositivos medicos comercializados por BioSteel de Colombia S.A. debido a la adquisicion de dispositivos y equipos medicos de alta calidad | I9: En el segundo trimestre que comprende 1 de abril a 30 de junio de 2018 no se presentaron incidentes o eventos adversos relacionados con los dispositivos medicos comercializados por BioSteel de Colombia S.A. debido a la adquisicion de dispositivos y equipos medicos de alta calidad | L9: En el tercer trimestre que comprende 1 de Julio a 30 de Septiembre de 2018 no se presentaron incidentes o eventos adversos relacionados con los dispositivos medicos comercializados por BioSteel de Colombia S.A. debido a la adquisicion de dispositivos y equipos medicos de alta calidad | O9: En el cuarto trimestre que comprende 1 de Octubre a 31 de Diciembre de 2018 no se presentaron incidentes o eventos adversos relacionados con los dispositivos medicos comercializados por BioSteel de Colombia S.A. debido a la adquisicion de dispositivos y equipos medicos de alta calidad
A10: 4 | B10: Sistema de Gestion de Calidad Coordinador de Calidad | C10: Cierre de planes de acción | F10: En este trimestre que comprende Enero- Marzo 2018, el indicador se cumplio ya que se cerraron los planes de accion abordados para corregir las no conformidades presentadas en auditorias internas, externas y comites de calidad | I10: En este trimestre que comprende abril- junio 2018, el indicador se cumplio ya que se cerraron los planes de accion abordados para corregir las no conformidades presentadas en auditorias internas, externas y comites de calidad | L10: En este trimestre que comprende julio - septiembre 2018, el indicador se cumplio ya que se cerraron los planes de accion abordados para corregir las no conformidades presentadas en auditorias internas, externas y comites de calidad | O10: En este trimestre que comprende octubre - diciembre 2018,no se presetaron acciones correctivas, ni planes de accion ya que se estaba trabajando en en el segumiento a los planes de accion de la auditoria de actualizacion y recertificacion.
A11: 5 | B11: Contabilidad Lider de Contabilidad | C11: Cumplimiento de presupuesto | D11: En el mes de Enero de 2018 se cumplio el presupuesto porque se recaudo lo esperado para este mes | E11: En el mes de Febrero de 2018 se cumplio el presupuesto porque se recaudo lo esperado para este mes | F11: En el mes de Marzo de 2018 se cumplio el presupuesto porque se recaudo lo esperado para este mes | G11: En el mes de Abril de 2018 se cumplio el presupuesto porque se recaudo lo esperado para este mes | H11: En el mes de Mayo de 2018 se cumplio el presupuesto porque se recaudo lo esperado para este mes | I11: En el mes de Junio de 2018 se cumplio el presupuesto porque se recaudo lo esperado para este mes | J11: En el mes de Julio de 2018 se cumplio el presupuesto porque se recaudo lo esperado para este mes | K11: En el mes de Agosto de 2018 se cumplio el presupuesto porque se recaudo lo esperado para este mes | L11: En el mes de Septiembre de 2018 se cumplio el presupuesto porque se recaudo lo esperado para este mes | M11: En el mes de Octubre de 2018 se cumplio el presupuesto porque se recaudo lo esperado para este mes | N11: En el mes de Noviembre de 2018 se cumplio el presupuesto porque se recaudo lo esperado para este mes | O11: En el mes de Diciembre de 2018 se cumplio el presupuesto porque se recaudo lo esperado para este mes
B12: Contabilidad Lider de Contabilidad | C12: Utilidad Mensual | D12: En el mes de Enero del 2018 se cumplio el indicador de utilidad porque las ventas superaron las expectativas. | E12: En el mes de Febrero del 2018 se cumplio el indicador de utilidad porque las ventas superaron las expectativas. | F12: En el mes de Marzo del 2018 se cumplio el indicador de utilidad porque las ventas superaron las expectativas. | G12: En el mes de Abril del 2018 se cumplio el indicador de utilidad porque las ventas superaron las expectativas. | H12: En el mes de Mayo del 2018 se cumplio el indicador de utilidad porque las ventas superaron las expectativas. | I12: En el mes de Junio del 2018 se cumplio el indicador de utilidad porque las ventas superaron las expectativas. | J12: En el mes de Julio del 2018 se cumplio el indicador de utilidad porque las ventas superaron las expectativas. | K12: En el mes de Agostoo del 2018 se cumplio el indicador de utilidad porque las ventas superaron las expectativas. | L12: En el mes de Septiembre del 2018 se cumplio el indicador de utilidad porque las ventas superaron las expectativas. | M12: En el mes de Octubre del 2018 se cumplio el indicador de utilidad porque las ventas superaron las expectativas. | N12: En el mes de Noviembre del 2018 se cumplio el indicador de utilidad porque las ventas superaron las expectativas. | O12: En el mes de Diciembre del 2018 se cumplio el indicador de utilidad porque las ventas superaron las expectativas.
B13: Facturación Lider de Facturación | C13: % Cumplimiento de Facturación y Radicado | D13: En el mes de Enero del 2018 se cumplio con el indicador de lo facturado ya que lo vendido del mes en curso se facturo teniendo en cuenta los cortes de cierre. se cumplio el indicador de lo Radicado ya que quedaron tres relaciones radicadas con fecha del mes siguiente por parte de las Ips. | E13: En el mes de Febrero del 2018 se cumplio con el indicador de lo facturado ya que se facturo lo vendido del mes en curso y lo pendiente del mes anterior. se cumplio el indicador de lo Radicado ya que quedo una relacion radicada con fecha del mes siguiente por parte de las Ips. | F13: En el mes de Marzo del 2018 no se cumplio con el indicador de lo facturado ya que en el mes se suspendieron labores 4 dias festivos religiosos. No se cumplio el indicador de lo Radicado ya que quedaron dos relaciones radicadas con fecha del mes siguiente por parte de las Ips. | G13: En el mes de Abril del 2018 se cumplio con el indicador de lo facturado ya que se facturo lo vendido del mes en curso y lo pendiente del mes anterior. se cumplio el indicador de lo Radicado ya que quedaron dos relacion radicada con fecha del mes siguiente por parte de la Ips Baru. | H13: En el mes de Mayo del 2018 se cumplio con el indicador de lo facturado ya que se facturo lo vendido del mes en curso y lo pendiente del mes anterior. se cumplio el indicador de lo Radicado ya que quedaron en Abril dos relaciones radicadas de Baru con fecha del mes de Mayo. | I13: En el mes de Junio del 2018 se cumplio con el indicador de lo facturado ya que se facturo lo vendido del mes en curso y lo pendiente del mes anterior. se cumplio el indicador de lo Radicado ya que quedo en Mayo una relacion radicada de Odontotrans con fecha del mes de Junio. | J13: En el mes de Julio del 2018 se cumplio con el indicador de lo facturado ya que se facturo lo vendido del mes en curso y lo pendiente del mes anterior. se cumplio el indicador de lo Radicado ya que quedo en Junio dos relaciones radicadas de Trauma Oriente con fecha del mes de Julio. | K13: En el mes de Agosto del 2018 se cumplio con el indicador de lo facturado ya que se facturo lo vendido del mes en curso y lo pendiente del mes anterior. No se cumplio el indicador de lo Radicado ya que quedaron nueve relaciones radicadas con fecha del mes siguiente por parte de las Ips. | L13: En el mes de Septiembre del 2018 se cumplio con el indicador de lo facturado ya que se facturo aproximadamente lo vendido del mes en curso. Se cumplio el indicador de lo Radicado ya que quedo en Agosto nueve relaciones radicada de cali con fecha del mes de Septiembre.
B14: Facturación Lider de Facturación | C14: % Facturas Anuladas | D14: En el mes de Enero del 2018 se cumplio con el indicador de Anuladas ya que no hubo un alto nivel de error en las facturas Generadas | E14: En el mes de Febrero del 2018 se cumplio con el indicador de Anuladas ya que no hubo un alto nivel de error en las facturas Generadas | F14: En el mes de Marzo del 2018 se cumplio con el indicador de Anuladas ya que no hubo un alto nivel de error en las facturas Generadas | G14: En el mes de Abril del 2018 se cumplio con el indicador de Anuladas ya que no hubo un alto nivel de error en las facturas Generadas | H14: En el mes de Mayo del 2018 se cumplio con el indicador de Anuladas ya que no hubo un alto nivel de error en las facturas Generadas | I14: En el mes de Junio del 2018 se cumplio con el indicador de Anuladas ya que no hubo un alto nivel de error en las facturas Generadas | J14: En el mes de Julio del 2018 se cumplio con el indicador de Anuladas ya que no hubo un alto nivel de error en las facturas Generadas | K14: En el mes de Julio del 2018 se cumplio con el indicador de Anuladas ya que no hubo un alto nivel de error en las facturas Generadas | L14: En el mes de Septiembre del 2018 se cumplio con el indicador de Anuladas ya que no hubo un alto nivel de error en las facturas Generadas
B15: Facturación Lider de Facturación | C15: % Facturas Glosadas por EPS | D15: En el mes de Enero del 2018 no se objetaron facturas por glosas. | E15: En el mes de Febrero del 2018 no se objetaron facturas por glosas. | F15: En el mes de marzo del 2018 no se objetaron facturas por glosas. | G15: En el mes de Abril del 2018 no se objetaron facturas por glosas. | H15: En el mes de Mayo del 2018 no se objetaron facturas por glosas. | I15: En el mes de Junio del 2018 no se objetaron facturas por glosas. | J15: En el mes de Julio del 2018 no se objetaron facturas por glosas. | K15: En el mes de Julio del 2018 no se objetaron facturas por glosas. | L15: En el mes de Septiembre del 2018 no se objetaron facturas por glosas.
A16: 6 | B16: Gestion Humana Lider de Gestión Humana | C16: Ejecución del programa de capacitación | D16: En este mes el indicador se cumplio debido las alianzas con nuestros proveedores para capacitar a nuestro personal tecnico con las nuevas tecnicas en los nuevos materiales adicionados a nuestro portafolio de productos. | E16: En este mes el indicador de ejecucion de l programa de capacitacion se cumplio debido a nuevos temas como lo fueron la facturacion electronica, reinduccion en el proceso de calidad de la organización y las constantes capacitaciones con nuestros proveedores. | F16: El cumplimiento de este indicador en el mes de marzo se debio a la negociacion con gente estrategica los cuales nos ayudaron a realizar una serie de capacitaciones de motivacion y gerencia personal | G16: Este indicador alcanzo su meta al mantenerse en 86 % , este logro se debio al enfoque al area de seguridad y salud en el trabajo, aprovechando los convenios que el grupo empresarial campbell tiene con entidades educativas como el sena , universidades y corporaciones tecnica/tecnologicas.. | H16: Debido a la situación economica por la que viene atravesando al organización, en este mes solo se pudo planear y ejecutar una capacitación la cual fue proporcionada por la camara de comercio de barranquilla a traves de los privilegios que tenemos como afiliados. el indicador se cumplió. | I16: En este mes el indicador se cumplio pese a el estado economico que estamos presentando, lo cumplimos por medio del apoyo de nuestros aliados, los proveedores. | J16: En este mes el indicador se cumplio pese a el estado economico que estamos presentando, lo cumplimos por medio del apoyo de la camara de comercio de barranquilla. | K16: En este mes el indicador se cumplio pese a el estado economico que estamos presentando, lo cumplimos por medio del apoyo de la camara de comercio de barranquilla. | L16: En este mes el indicador se cumplio pese a el estado economico que estamos presentando, lo cumplimos por medio del apoyo de la camara de comercio de barranquilla. | M16: En este mes el indicador se cumplio pese a el estado economico que estamos presentando, lo cumplimos por medio del apoyo de la camara de comercio de barranquilla. | N16: En este mes el indicador se cumplio pese a el estado economico que estamos presentando, lo cumplimos por medio del apoyo de la camara de comercio de barranquilla. | O16: En este mes el indicador se cumplio pese a el estado economico que estamos presentando, lo cumplimos por medio del apoyo de la camara de comercio de barranquilla y a los convenios de entidades educativas a traves de sus practicantes.
A17: 7 | B17: Almacen Coordinador Logistico | C17: Evaluación de Cumplimiento Proveedores | D17: En el mes de Enero del 2018 se cumplió el indicador de evaluación de cumplimiento de proveedores, debido a que cumplieron con los parametros establecidos en la evaluación mensual, | E17: En el mes de Febrero del 2018 se cumplió el indicador de evaluación de cumplimiento de proveedores, debido a que cumplieron con los parametros establecidos en la evaluación mensual, | F17: En el mes de Marzo del 2018 se cumplió el indicador de evaluación de cumplimiento de proveedores, debido a que cumplieron con los parametros establecidos en la evaluación mensual, | G17: En el mes de Abril del 2018 se cumplió el indicador de evaluación de cumplimiento de proveedores, debido a que cumplieron con los parametros establecidos en la evaluación mensual, | H17: En el mes de Mayo del 2018 se cumplió el indicador de evaluación de cumplimiento de proveedores, debido a que cumplieron con los parametros establecidos en la evaluación mensual, | I17: En el mes de Junio del 2018 se cumplió el indicador de evaluación de cumplimiento de proveedores, debido a que cumplieron con los parametros establecidos en la evaluación mensual, | J17: En el mes de Julio del 2018 se cumplió el indicador de evaluación de cumplimiento de proveedores, debido a que cumplieron con los parametros establecidos en la evaluación mensual, | K17: En el mes de Agosto del 2018 se cumplió el indicador de evaluación de cumplimiento de proveedores, debido a que cumplieron con los parametros establecidos en la evaluación mensual, | L17: En el mes de Septiembre del 2018 se cumplió el indicador de evaluación de cumplimiento de proveedores, debido a que cumplieron con los parametros establecidos en la evaluación mensual, | M17: En el mes de Octubre del 2018 se cumplió el indicador de evaluación de cumplimiento de proveedores, debido a que cumplieron con los parametros establecidos en la evaluación mensual, | N17: En el mes de Noviembre del 2018 se cumplió el indicador de evaluación de cumplimiento de proveedores, debido a que cumplieron con los parametros establecidos en la evaluación mensual, | O17: En el mes de Diciembre del 2018 se cumplió el indicador de evaluación de cumplimiento de proveedores, debido a que cumplieron con los parametros establecidos en la evaluación mensual,
A18: 8 | B18: Asistencia Tecnica Coordinador Asistencial | C18: Satisfacción del Cliente
