Workbook

Sheet MATRIZ
A1: MATRIZ DE DESPLIEGUE DE POLÍTICA DE CALIDAD DE BIOSTEEL DE COLOMBIA
A4: POLITICA DE CALIDAD | C4: En Biosteel de Colombia S.A, somos una empresa dedicada a la importación, comercialización y distribución de dispositivos médicos de alta calidad. Por ello, nuestros esfuerzos se centran en satisfacer las necesidades y expectativas de especialistas, instituciones del área de la salud y usuarios mediante el compromiso de ejecutar los procedimientos bajo el direccionamiento de altos estándares de calidad, garantizando el cumplimiento de los requisitos legales exigibles, el mejoramiento continuo de nuestros procesos, la optimización de nuestros recursos, el desarrollo integral de nuestros colaboradores, la consolidación de alianzas estratégicas con nuestros proveedores y el fortalecimiento de las relaciones comerciales
A9: PREMISAS | C9: OBJETIVOS | H9: OBJETIVO ESPECIFICO | I9: PROCESO | J9: RESPONSABLE | K9: INVOLUCRADOS DEL PROCESO | L9: PERSONAL RELACIONADO | M9: INDICADOR | N9: FORMULACIÓN | O9: META | P9: FRECUENCIA | Q9: FUENTE DE DATOS | R9: ENERO | S9: FEBRERO | T9: MARZO | U9: ABRIL | V9: MAYO | W9: JUNIO | X9: JULIO | Y9: AGOSTO | Z9: SEPTIEMBRE | AA9: OCTUBRE | AB9: NOVIEMBRE | AC9: DICIEMBRE | AD9: PROMEDIO
A10: 1 | B10: Importación, comercialización y distribución | C10: Respaldar los procesos de importación, comercialización y distribuición a los clientes mediante la recepción, acondicionamento, almacenamiento, manejo y suministro de dispositivo médicos acorde a las normas vigentes de sanidad. | H10: Evaluar el cumplimiento de entrega de las ordenes de compra de dispositivos medicos mediante el informe mensual de compra. | I10: Almacén Gerencia Administrativa | J10: Coordinador Logistico , Coordinador Asistencial, Gerente Administrativo | K10: Auxiliar de almacén, Asesor Quirúrgico, Auxiliar Administrativo | L10: Todo el personal de Biosteel De Colombia S.A | M10: % de Ordenes de Compra recibidas completas | N10: (No. Ordenes de Compra recibidas completas/ No. Ordenes recibidas) X 100 | O10: >70% | P10: Mensual | Q10: Formato de Seguimiento a Proveedores | R10: ='1'!D11 -> 0.95604396 | S10: ='1'!D12 -> 0.97704918 | T10: ='1'!D13 -> 0.9751693 | U10: ='1'!D14 -> 0.97947214 | V10: ='1'!D15 -> 0.97389034 | W10: ='1'!D16 -> 0.9875 | X10: ='1'!D17 -> 0.98540146 | Y10: ='1'!D18 -> 0.99052133 | Z10: ='1'!D19 -> 0.97575758 | AA10: ='1'!D20 -> 0.98198198 | AB10: ='1'!D21 -> 0.95 | AC10: ='1'!D22 -> 0.91981132 | AD10: =AVERAGE(R10:AC10) -> 0.97104988
M11: Incumplimiento de disponibilidad de dispositivos médicos | N11: Número de Cirugías canceladas por falta de disponibilidad DM/ Número de Cirugías programas con requerimientos de DM | O11: 0 | P11: Mensual | Q11: Formato de Ostesintesis Programas | R11: ='1'!D27 -> 0 | S11: ='1'!D28 -> 0 | T11: ='1'!D29 -> 0 | U11: ='1'!D30 -> 0 | V11: ='1'!D31 -> 0 | W11: ='1'!D32 -> 0 | X11: ='1'!D33 -> 0 | Y11: ='1'!D34 -> 0 | Z11: ='1'!D35 -> 0 | AA11: ='1'!D36 -> 0 | AB11: ='1'!D37 -> 0 | AC11: ='1'!D38 -> 0 | AD11: =AVERAGE(R11:AC11) -> 0
A12: 2 | B12: satisfacer las necesidades y expectativas de especialistas, instituciones del área de la salud y usuarios | C12: Crear estrategías de buen servicio que permitan optimizar el manejo de procesos y recursos con el fin de establecer mecanismos para garantizar la satisfacción del cliente. | H12: Analizar a través de las evaluciones de seguimiento y atencion de quejas, reclamos y sugerencias el cumplimiento del servicio, las condiciones del material utilizado y la habilidad del soporte tecnico, con el fin de implementar estrategias de buen servicio para garantizar la satisfaccion del cliente. | I12: Asistencia Técnica | J12: Coordinador Asistencial | K12: Asesor Quirúrgico | L12: Todo el personal de Biosteel De Colombia S.A | M12: Atención a Quejas, Reclamos y/o Sugerencias | N12: No. Quejas, reclamos o sugerencias recibidos = a No. De quejas y reclamos atendidos | O12: 1 | P12: Mensual | Q12: Formato de quejas, reclamos o sugerencias | R12: ='2'!D27 -> 0 | S12: ='2'!D28 -> 0 | T12: ='2'!D29 -> 1 | U12: ='2'!D30 -> 0 | V12: ='2'!D31 -> 0 | W12: ='2'!D32 -> 0 | X12: ='2'!D33 -> 0 | Y12: ='2'!D34 -> 0 | Z12: ='2'!D35 -> 0 | AA12: ='2'!D36 -> 0 | AB12: ='2'!D37 -> 0 | AC12: ='2'!D38 -> 0 | AD12: =AVERAGE(R12:AC12) -> 0.083333333
M13: Evaluaciones de Seguimiento | N13: Sumatoria del resultado de todas las evaluaciones/ El total de las evaluaciones. | O13: 4 | P13: Mensual | Q13: Evaluación de seguimiento de asesorías quirúrgicas | R13: =('2'!B11+'2'!C11+'2'!D11)/3 -> 4.7666667 | S13: =('2'!B12+'2'!C12+'2'!D12)/3 -> 4.7666667 | T13: =('2'!B13+'2'!C13+'2'!D13)/3 -> 4.6 | U13: =('2'!B14+'2'!C14+'2'!D14)/3 -> 4.8 | V13: =('2'!B15+'2'!C15+'2'!D15)/3 -> 4.7833333 | W13: =('2'!B16+'2'!C16+'2'!D16)/3 -> 4.56 | X13: =('2'!B17+'2'!C17+'2'!D17)/3 -> 4.4666667 | Y13: =('2'!B18+'2'!C18+'2'!D18)/3 -> 4.7666667 | Z13: =('2'!B19+'2'!C19+'2'!D19)/3 -> 4.7666667 | AA13: =('2'!B20+'2'!C20+'2'!D20)/3 -> 4.4888889 | AB13: =('2'!B21+'2'!C21+'2'!D21)/3 -> 4.3 | AC13: =('2'!B22+'2'!C22+'2'!D22)/3 -> 4.8 | AD13: =AVERAGE(R13:AC13) -> 4.655463
A14: 3 | B14: garantizando el cumplimiento de los requisitos legales exigibles, | C14: Garantizar a los clientes confiabilidad con el cumpliento del manual de requisitos de Capacidad de Almacenamiento y/o Acondicionamiento para dispositivos médicos. | H14: Verificar la calidad de los materiales de acuerdo a las especificaciones tecnicas del proveedor mediante el recibo a satisfaccion de mercancia garantizando a los clientes confiabilidad con el cumplimiento del manual de requisitos de capacidad de almacenamiento y/o acondicionamiento para dispositivos medicos | I14: Almacén, Asistencia Técnica | J14: Coordinador Logistico, Coordinador Asistencial | K14: Auxiliar de almacén, Asesor Quirúrgico | L14: Todo el personal de Biosteel De Colombia S.A | M14: Reportes de Tecnivigilancia | N14: No. De Reportes presentados/ No. De Reportes Notificacos al INVIMA | O14: 1 | P14: Trimestral | Q14: Formato de Eventos o Incidentes Adversos | R14: N/A | S14: N/A | T14: ='3'!D27 -> N/A | U14: N/A | V14: N/A | W14: ='3'!D30 -> N/A | X14: N/A | Y14: N/A | Z14: ='3'!D33 -> N/A | AA14: N/A | AB14: N/A | AC14: ='3'!D36 -> N/A | AD14: N/A
M15: % de cumplimientos de especificaciones técnicas | N15: (No. De desviaciones encontradas/ No. De muestras verificadas) X 100 | O15: 1 | P15: Mensual | Q15: Formato de Seguimiento a Proveedores | R15: ='3'!D11 -> 1 | S15: ='3'!D12 -> 1 | T15: ='3'!D13 -> 1 | U15: ='3'!D14 -> 1 | V15: ='3'!D15 -> 1 | W15: ='3'!D16 -> 1 | X15: ='3'!D17 -> 1 | Y15: ='3'!D18 -> 1 | Z15: ='3'!D19 -> 1 | AA15: ='3'!D20 -> 1 | AB15: ='3'!D21 -> 1 | AC15: ='3'!D22 -> 1 | AD15: =AVERAGE(R15:AC15) -> 1
A16: 4 | B16: el mejoramiento continuo de nuestros procesos | C16: Planificar, ejecutar, verificar y retroalimentar el sistema de gestión de calidad, a través de identificaciones de acciones correctivas, preventivas y de mejora continúa. | H16: Verificar el cierre de los planes de Accion generados con el fin de comprobar la eficacia del sistema de Gestion de calidad. | I16: Gestión de Calidad | J16: Coordinador de Calidad | K16: _ | L16: Todo el personal de Biosteel De Colombia S.A | M16: Cierre de planes de acción | N16: Planes de acción cerrados / No. Total de planes de acción | O16: >70% | P16: Trimestral | Q16: Consolidado de acciones correctivas, preventivas y de mejora. | R16: N/A | S16: N/A | T16: ='4'!D11 -> 1 | U16: N/A | V16: N/A | W16: ='4'!D14 -> 1 | X16: N/A | Y16: N/A | Z16: ='4'!D17 -> 0.81818182 | AA16: N/A | AB16: N/A | AC16: ='4'!D20 -> 1 | AD16: =AVERAGE(R16:AC16) -> 0.95454545
A17: 5 | B17: optimización de nuestros recursos | C17: Consolidar un adecuado manejo financiero a traves de la contabilización adecuada, con el fin de generar confiabilidad entre los stakeholders de la compañía. | H17: Verificar el cumplimiento del presupuesto,conocer la utilidad generada y comparar lo vendido con lo radicado con el fin de conocer el estado financiero de la Organización. | I17: Contabilidad Facturación | J17: Líder de Contabilidad y Líder de Facturación | K17: Auxiliar de Contabilidad | L17: Todo el personal de Biosteel De Colombia S.A | M17: % Cumplimiento de presupuesto | N17: Gasto real / Presupuesto | O17: >70% | P17: Mensual | Q17: Formato de Informe de Presupuestos | R17: ='5'!D11 -> 1.0394709 | S17: ='5'!D12 -> 1.2957935 | T17: ='5'!D13 -> 1.0316239 | U17: ='5'!D14 -> 0.96562588 | V17: ='5'!D15 -> 0.91303022 | W17: ='5'!D16 -> 1.1123368 | X17: ='5'!D17 -> 0.93308703 | Y17: ='5'!D18 -> 0.89613564 | Z17: ='5'!D19 -> 0.92409686 | AA17: ='5'!D20 -> 0.80859627 | AB17: ='5'!D21 -> 0.6941837 | AC17: ='5'!D22 -> 0.80945856 | AD17: =AVERAGE(R17:AC17) -> 0.95195328
M18: Utilidad Mensual | N18: Ventas - Cuentas por pagar - Gastos | O18: 1000000000 | P18: Mensual | Q18: Informes de cuentas por pagar y cuentas por cobrar | R18: ='5'!E27 -> 1.699415e+09 | S18: ='5'!E28 -> 9.2883319e+08 | T18: ='5'!E29 -> 1.3358751e+09 | U18: ='5'!E30 -> 1.1807446e+09 | V18: ='5'!E31 -> 1.2677173e+09 | W18: ='5'!E32 -> 1.2853307e+09 | X18: ='5'!E33 -> 1.4158962e+09 | Y18: ='5'!E34 -> 1.1465908e+09 | Z18: ='5'!E35 -> 1.6892728e+09 | AA18: ='5'!E36 -> 1.3955912e+09 | AB18: ='5'!E37 -> 1.8896526e+09 | AC18: ='5'!E38 -> 1.6303955e+09 | AD18: =AVERAGE(R18:AC18) -> 1.4054429e+09
M19: % Cumplimiento Facturado | N19: Total ventas/ Total Facturado | O19: 0.9 | P19: Mensual | Q19: Informes de Facturación | R19: ='5'!E43 -> 1.2051101 | S19: ='5'!E44 -> 0.86518896 | T19: ='5'!E45 -> 1.0557841 | U19: ='5'!E46 -> 0.95591992 | V19: ='5'!E47 -> 0.92793284 | W19: ='5'!E48 -> 0.99433296 | X19: ='5'!E49 -> 1.0224115 | Y19: ='5'!E50 -> 0.90685598 | Z19: ='5'!E51 -> 0.99864694 | AA19: ='5'!E52 -> 0.91756689 | AB19: ='5'!E53 -> 1.114261 | AC19: ='5'!E54 -> 1.0248275 | AD19: =AVERAGE(R19:AC19) -> 0.99906989
M20: % Cumplimiento Radicado | N20: Total Facturado/ Total Radicado | O20: 0.95 | P20: Mensual | Q20: Informes de Facturación | R20: ='5'!F43 -> 0.9430875 | S20: ='5'!F44 -> 0.91264951 | T20: ='5'!F45 -> 0.80070661 | U20: ='5'!F46 -> 0.97321754 | V20: ='5'!F47 -> 0.99684598 | W20: ='5'!F48 -> 1 | X20: ='5'!F49 -> 1 | Y20: ='5'!F50 -> 1 | Z20: ='5'!F51 -> 1 | AA20: ='5'!F52 -> 1 | AB20: ='5'!F53 -> 1 | AC20: ='5'!F54 -> 0.94606479 | AD20: =AVERAGE(R20:AC20) -> 0.96438099
M21: % Facturas Anuladas | N21: Facturas anuladas/ Facturas Generadas | O21: <5% | P21: Mensual | Q21: Cuadro de Control Facturas | R21: ='5'!D75 -> 0.012664394 | S21: ='5'!D76 -> 0.009556314 | T21: ='5'!D77 -> 0.012086514 | U21: ='5'!D78 -> 0.0087440382 | V21: ='5'!D79 -> 0.0043936731 | W21: ='5'!D80 -> 0.015993907 | X21: ='5'!D81 -> 0.011041009 | Y21: ='5'!D82 -> 0.0093062606 | Z21: ='5'!D83 -> 0.0090027701 | AA21: ='5'!D84 -> 0.013127413 | AB21: ='5'!D85 -> 0.010989011 | AC21: ='5'!D86 -> 0.014788732 | AD21: =AVERAGE(R21:AC21) -> 0.010974503
M22: % Facturas Glosadas por EPS | N22: Facturas Glosadas por EPS/ Facturas Generadas a EPS | O22: <30% | P22: Mensual | Q22: Notificaciones de Glosas | R22: ='5'!D91 -> 0 | S22: ='5'!D92 -> 0 | T22: ='5'!D93 -> 0 | U22: ='5'!D94 -> 0 | V22: ='5'!D95 -> 0 | W22: ='5'!D96 -> 0 | X22: ='5'!D97 -> 0 | Y22: ='5'!D98 -> 0 | Z22: ='5'!D99 -> 0.0020775623 | AA22: ='5'!D100 -> 0 | AB22: ='5'!D101 -> 0 | AC22: ='5'!D102 -> 0 | AD22: =AVERAGE(R22:AC22) -> 0.00017313019
A23: 6 | B23: el desarrollo integral de nuestros colaboradores, | C23: Establecer programas de formación permanentes, los cuales permitirán disponer de un personal con mayor nivel de cualificación para desempeñar las actividades comprendidas en el Sistema de gestión. | H23: Verificar el cumplimiento y eficacia del plan de formacion por medio de la evaluacion de capacitacion, la cual nos permita disponer de un personal con mayor nivel de cualificacion para desempeñar las actividades comprometidas en el sistema de gestion. | I23: Gestión Administrativa | J23: Gerente Administrativa | K23: _ | L23: Todo el personal de Biosteel De Colombia S.A | M23: Ejecución del programa de capacitación | N23: (Capacitaciones ejecutadas / Capacitaciones planeadas)*100% | O23: >70% | P23: Mensual | Q23: Cronograma de capacitación | R23: ='6'!D11 -> 1 | S23: ='6'!D12 -> 0.5 | T23: ='6'!D13 -> 1 | U23: ='6'!D14 -> 0.5 | V23: ='6'!D15 -> 0.8 | W23: ='6'!D16 -> 1 | X23: ='6'!D17 -> 1 | Y23: ='6'!D18 -> 0.66666667 | Z23: ='6'!D19 -> 0.83333333 | AA23: ='6'!D20 -> 0 | AB23: ='6'!D21 -> 0.25 | AC23: ='6'!D22 -> 1 | AD23: =AVERAGE(R23:AC23) -> 0.7125
A24: 7 | B24: la consolidación de alianzas estratégicas solidas con nuestros proveedores | C24: Expandir y consolidar la relacion con proveedores buscando nuevas opciones en el mercado, diseñando herramientas y concertando acuerdos para adquirir beneficio mutuo. | H24: Analizar el cumpliento de nuestros proveedores a traves de un seguimiento mensual para determinar el desempeño con la empresa y consolidar la relacion con el proveedor, creando acuerdos para adquirir beneficios mutuos. | I24: Almacén, Gestión Administrativa | J24: Jefe de Almacén | K24: _ | L24: Todo el personal de Biosteel De Colombia S.A | M24: Evalución de Cumplimiento Proveedores | N24: Sumatoria del resultado de todas las evaluaciones/ El total de las evaluaciones. | O24: >95 | P24: Mensual | Q24: Formato de Evaluación de Proveedores | R24: ='7'!D11 -> 99.875 | S24: ='7'!D12 -> 99.3 | T24: ='7'!D13 -> 97.611111 | U24: ='7'!D14 -> 97.761905 | V24: ='7'!D15 -> 98.117647 | W24: ='7'!D16 -> 97.2 | X24: ='7'!D17 -> 95.65 | Y24: ='7'!D18 -> 94.722222 | Z24: ='7'!D19 -> 94.842105 | AA24: ='7'!D20 -> 96.444444 | AB24: ='7'!D21 -> 96.315789 | AC24: ='7'!D22 -> 96.45 | AD24: 0.97
A25: 8 | B25: el fortalecimiento de las relaciones comerciales con los clientes. | C25: Fortalecer las relaciones comerciales con los clientes brindadoles credibilidad en la comercilización de nuestros productos y en la prestación de un buen servicio, atraves de facilidades de pago, entregas oportunas y atención de requerimientos. | H25: Conocer el grado de aceptacion de nuestros clientes mediante la encuesta de satisfaccion con la finalidad de fortalecer las relaciones comerciales, brindandoles credibilidad en la comercializacion de nuestros productos y la prestacion de un buen servicio. | I25: Asistencia Técnica, Almacén, Facturación | J25: Coordinador Asistencial | K25: Auxiliar de Almacén, Asesor Quirúrgico, Auxiliar de Facturación, Auxiliar Administrativo | L25: Todo el personal de Biosteel De Colombia S.A | M25: Satisfacción del Cliente | N25: Sumatoria del resultado de todas las evaluaciones/ El total de las evaluaciones. | O25: >4.5 | P25: Semestral | Q25: Formato de Satisfacción del Cliente | R25: N/A | S25: N/A | T25: N/A | U25: N/A | V25: N/A | W25: ='8'!D11 -> 4.64 | X25: N/A | Y25: N/A | Z25: N/A | AA25: N/A | AB25: N/A | AC25: ='8'!D17 -> 5 | AD25: =AVERAGE(W25,AC25) -> 4.82
W30: 4.6
W31: 5
W32: =SUM(W30:W31) -> 9.6 | X32: =AVERAGE(W30,W31) -> 4.8

Sheet 1
C1: INDICADORES | I1: CODIGO: FOR-GC-011
I2: VERSION: 0
I3: PAGINA: 1 DE 8
A4: OBJETIVO GENERAL | C4: Respaldar los procesos de importación, comercialización y distribuición a los clientes mediante la recepción, acondicionamento, almacenamiento, manejo y suministro de dispositivo médicos acorde a las normas vigentes de sanidad.
A6: OBJETIVO ESPECIFICO | C6: Evaluar el cumplimiento de entrega de las ordenes de compra de dispositivos medicos mediante el informe mensual de compra.
A8: INDICADOR | B8: % de Ordenes de Compra recibidas completas
A9: FORMULA | B9: (No. Ordenes de Compra recibidas completas/ No. Ordenes totales recibidas)
A10: Meses | B10: No. Ordenes de Compra recibidas Completas | C10: No. De ordenes de compra totales | D10: % de Cumplimiento (>70%)
A11: Enero | B11: 348 | C11: 364 | D11: =B11/C11 -> 0.95604396
A12: Febrero | B12: 298 | C12: 305 | D12: =B12/C12 -> 0.97704918
A13: Marzo | B13: 432 | C13: 443 | D13: =B13/C13 -> 0.9751693
A14: Abril | B14: 334 | C14: 341 | D14: =B14/C14 -> 0.97947214
A15: Mayo | B15: 373 | C15: 383 | D15: =B15/C15 -> 0.97389034
A16: Junio | B16: 395 | C16: 400 | D16: =B16/C16 -> 0.9875
A17: Julio | B17: 405 | C17: 411 | D17: =B17/C17 -> 0.98540146
A18: Agosto | B18: 418 | C18: 422 | D18: =B18/C18 -> 0.99052133
A19: Septiembre | B19: 483 | C19: 495 | D19: =B19/C19 -> 0.97575758
A20: Octubre | B20: 436 | C20: 444 | D20: =B20/C20 -> 0.98198198
A21: Noviembre | B21: 418 | C21: 440 | D21: =B21/C21 -> 0.95
A22: Diciembre | B22: 390 | C22: 424 | D22: =B22/C22 -> 0.91981132
A24: INDICADOR | B24: % de incumplimiento de disponibilidad de dispositivos médicos
A25: FORMULA | B25: Número de Cirugías canceladas por falta de disponibilidad DM/ Número de Cirugías programas con requerimientos de DM
A26: Meses | B26: Número de Cirugías canceladas por falta de disponibilidad DM | C26: Número de Cirugías programas con requerimientos de DM | D26: % Incumplimiento de disponibilidad de DM
A27: Enero | B27: 0 | C27: 98 | D27: =B27/C27 -> 0
A28: Febrero | B28: 0 | C28: 69 | D28: =B28/C28 -> 0
A29: Marzo | B29: 0 | C29: 82 | D29: =B29/C29 -> 0
A30: Abril | B30: 0 | C30: 72 | D30: =B30/C30 -> 0
A31: Mayo | B31: 0 | C31: 119 | D31: =B31/C31 -> 0
A32: Junio | B32: 0 | C32: 99 | D32: =B32/C32 -> 0
A33: Julio | B33: 0 | C33: 85 | D33: =B33/C33 -> 0
A34: Agosto | B34: 0 | C34: 72 | D34: =B34/C34 -> 0
A35: Septiembre | B35: 0 | C35: 61 | D35: =B35/C35 -> 0
A36: Octubre | B36: 0 | C36: 69 | D36: =B36/C36 -> 0
A37: Noviembre | B37: 0 | C37: 70 | D37: =B37/C37 -> 0
A38: Diciembre | B38: 0 | C38: 57 | D38: =B38/C38 -> 0
A40: Responsable: Coordinador Logistico

Sheet 2
C1: INDICADORES | I1: CODIGO: FOR-GC-011
I2: VERSION: 0
I3: PAGINA: 2 DE 8
A4: OBJETIVO | C4: Crear estrategías de buen servicio que permitan optimizar el manejo de procesos y recursos con el fin de establecer mecanismos para garantizar la satisfacción del cliente.
A6: OBJETIVO ESPECIFICO | C6: Analizar a través de las evaluciones de seguimiento y atencion de quejas, reclamos y sugerencias el cumplimiento del servicio, las condiciones del material utilizado y la habilidad del soporte tecnico, con el fin de implementar estrategias de buen servicio para garantizar la satisfaccion del cliente.
A8: INDICADOR | B8: Evaluaciones de Seguimiento
A9: FORMULA | B9: Sumatoria del resultado de todas las evaluaciones/ El No. total de evaluaciones realizadas.
A10: Meses | B10: Cumplimiento del servicio (>4.0) | C10: Condiciones del Material Utilizado (>4.0) | D10: Habilidad Soporte Técnico (>4.0)
A11: Enero | B11: 4.8 | C11: 4.7 | D11: 4.8
A12: Febrero | B12: 4.7 | C12: 4.8 | D12: 4.8
A13: Marzo | B13: 4.4 | C13: 4.6 | D13: 4.8 | L13: =56.4/12 -> 4.7
A14: Abril | B14: 5 | C14: 4.7 | D14: 4.7
A15: Mayo | B15: 4.75 | C15: 4.8 | D15: 4.8
A16: Junio | B16: 4.5 | C16: 4.59 | D16: 4.59
A17: Julio | B17: 4.5 | C17: 4.4 | D17: 4.5
A18: Agosto | B18: 4.8 | C18: 4.7 | D18: 4.8
A19: Septiembre | B19: 4.7 | C19: 4.8 | D19: 4.8
A20: Octubre | B20: 4.5 | C20: 4.4 | D20: 4.5666666
A21: Noviembre | B21: 4.4 | C21: 4.2 | D21: 4.3
A22: Diciembre | B22: 4.8 | C22: 4.7 | D22: 4.9
A24: INDICADOR | B24: Atención a Quejas, Reclamos y/o Sugerencias
A25: FORMULA | B25: No. Quejas, reclamosy/o sugerencias atendidas / a No. De quejas, reclamos y/o Sugerencias presentados * 100
A26: Meses | B26: Total de quejas, reclamos o sugerencias presentados | C26: Total de Quejas, Reclamos o sugerencias atendido | D26: Porcentaje de atención de Quejas, Reclamos o sugerencias
A27: Enero | B27: 0 | C27: 0 | D27: 0
A28: Febrero | B28: 0 | C28: 0 | D28: 0
A29: Marzo | B29: 1 | C29: 1 | D29: =C29/B29 -> 1
A30: Abril | B30: 0 | C30: 0 | D30: 0
A31: Mayo | B31: 0 | C31: 0 | D31: 0
A32: Junio | B32: 0 | C32: 0 | D32: 0
A33: Julio | B33: 0 | C33: 0 | D33: 0
A34: Agosto | B34: 0 | C34: 0 | D34: 0
A35: Septiembre | B35: 0 | C35: 0 | D35: 0
A36: Octubre | B36: 0 | C36: 0 | D36: 0
A37: Noviembre | B37: 0 | C37: 0 | D37: 0
A38: Diciembre | B38: 0 | C38: 0 | D38: 0
A41: Responsable: Coordinador Asistencial

Sheet 3
C1: INDICADORES | I1: CODIGO: FOR-GC-011
I2: VERSION: 0
I3: PAGINA: 3 DE 8
A4: OBJETIVO | C4: Garantizar a los clientes confiabilidad con el cumpliento del manual de requisitos de Capacidad de Almacenamiento y/o Acondicionamiento para dispositivos médicos.
A6: OBJETIVO ESPECIFICO | C6: Verificar la calidad de los materiales de acuerdo a las especificaciones tecnicas del proveedor mediante el recibo a satisfaccion de mercancia garantizando a los clientes confiabilidad con el cumplimiento del manual de requisitos de capacidad de almacenamiento y/o acondicionamiento para dispositivos medicos
A8: INDICADOR | B8: % de cumplimientos de especificaciones técnicas
A9: FORMULA | B9: (No. De evaluaciones recibidas satisfactoriamente/ No. De muestras verificadas)
A10: Meses | B10: No. De evaluaciones recibidas satisfactoriamente | C10: No. De muestras verificadas | D10: % de Cumplimiento (100%)
A11: Enero | B11: 97 | C11: 97 | D11: =B11/C11 -> 1
A12: Febrero | B12: 91 | C12: 91 | D12: =B12/C12 -> 1
A13: Marzo | B13: 71 | C13: 71 | D13: =B13/C13 -> 1
A14: Abril | B14: 108 | C14: 108 | D14: =B14/C14 -> 1
A15: Mayo | B15: 93 | C15: 93 | D15: =B15/C15 -> 1
A16: Junio | B16: 91 | C16: 91 | D16: =B16/C16 -> 1
A17: Julio | B17: 99 | C17: 99 | D17: =B17/C17 -> 1
A18: Agosto | B18: 104 | C18: 104 | D18: =B18/C18 -> 1
A19: Septiembre | B19: 128 | C19: 128 | D19: =B19/C19 -> 1
A20: Octubre | B20: 99 | C20: 99 | D20: =B20/C20 -> 1
A21: Noviembre | B21: 91 | C21: 91 | D21: =B21/C21 -> 1
A22: Diciembre | B22: 92 | C22: 92 | D22: =B22/C22 -> 1
A24: INDICADOR | B24: Reportes de Tecnovigilancia
A25: FORMULA | B25: No. De Reportes Notificados al INVIMA / No. De Reportes Presentados * 100
A26: Meses | B26: No. De Reportes presentados | C26: No. De Reportes Notificacos al INVIMA | D26: % de Cumplimiento (100%)
A27: Enero - Marzo | B27: 0 | C27: 0 | D27: N/A
A30: Abril - Junio | B30: 0 | C30: 0 | D30: N/A
A33: Julio - Septiembre | B33: 0 | C33: 0 | D33: N/A
A36: Octubre - Dicembre | B36: 0 | C36: 0 | D36: N/A
A40: Responsable: Coordinador Logistico y Director Técnico

Sheet 4
C1: INDICADORES | I1: CODIGO: FOR-GC-011
I2: VERSION: 0
I3: PAGINA: 4 DE 8
A4: OBJETIVO | C4: Planificar, ejecutar, verificar y retroalimentar el sistema de gestión de calidad, a través de identificaciones de acciones correctivas, preventivas y de mejora continúa.
A6: OBJETIVO ESPECIFICO | C6: Verificar el cierre de los planes de Accion generados con el fin de comprobar la eficacia del sistema de Gestion de calidad.
A8: INDICADOR | B8: Cierre de planes de acción
A9: FORMULA | B9: Planes de acción cerrados / No. Total de planes de acción
A10: Meses | B10: Planes de acción cerrados | C10: No. Total de planes de Accion | D10: % de Cumplimiento (100%)
A11: Enero - Marzo | B11: 104 | C11: 104 | D11: =B11/C11 -> 1
A14: Abril - Junio | B14: 2 | C14: 2 | D14: =B14/C14 -> 1
A17: Julio - Septiembre | B17: 9 | C17: 11 | D17: =B17/C17 -> 0.81818182
A20: Octubre - Diciembre | B20: 1 | C20: 1 | D20: =B20/C20 -> 1
A25: Responsable: Coordinador De Calidad

Sheet 5
C1: INDICADORES | I1: CODIGO: FOR-GC-011
I2: VERSION: 0
I3: PAGINA: 5 DE 8
A4: OBJETIVO | C4: Consolidar un adecuado manejo financiero a traves de la contabilización adecuada, con el fin de generar confiabilidad entre los stakeholders de la compañía.
A6: OBJETIVO ESPECIFICO | C6: Verificar el cumplimiento del presupuesto,conocer la utilidad generada y comparar lo vendido con lo radicado con el fin de conocer el estado financiero de la Organización.
A8: INDICADOR | B8: Cumplimiento de presupuesto
A9: FORMULA | B9: Gasto real / Presupuesto
A10: Meses | B10: Gasto real | C10: Gasto presupuestado | D10: % de Cumplimiento (>90%)
A11: Enero | B11: 1870552433 | C11: 1799523549 | D11: =B11/C11 -> 1.0394709
A12: Febrero | B12: 1527139050 | C12: 1178535790 | D12: =B12/C12 -> 1.2957935
A13: Marzo | B13: 2393203262 | C13: 2319840747 | D13: =B13/C13 -> 1.0316239
A14: Abril | B14: 1.4971448e+09 | C14: 1550439786 | D14: =B14/C14 -> 0.96562588
A15: Mayo | B15: 1917090244 | C15: 2099700746 | D15: =B15/C15 -> 0.91303022
A16: Junio | B16: 1385409449 | C16: 1245494620 | D16: =B16/C16 -> 1.1123368
A17: Julio | B17: 1.5275069e+09 | C17: 1637046513 | D17: =B17/C17 -> 0.93308703
A18: Agosto | B18: 1.5148746e+09 | C18: 1690452307 | D18: =B18/C18 -> 0.89613564
A19: Septiembre | B19: 1906561385 | C19: 2063161843 | D19: =B19/C19 -> 0.92409686
A20: Octubre | B20: 1113878338 | C20: 1377545722 | D20: =B20/C20 -> 0.80859627
A21: Noviembre | B21: 1.1435213e+09 | C21: 1.6472892e+09 | D21: =B21/C21 -> 0.6941837
A22: Diciembre | B22: 1.2188946e+09 | C22: 1505814663 | D22: =B22/C22 -> 0.80945856
A24: INDICADOR | B24: Utilidad Mensual
A25: FORMULA | B25: Ventas - Cuentas por pagar - Gastos
A26: Meses | B26: Ingresos | C26: Gastos | D26: Costo | E26: Utilidad (>1,000,000,000)
A27: Enero | B27: 3097726784 | C27: 180196675 | D27: 1.2181151e+09 | E27: =B27-C27-D27 -> 1.699415e+09
A28: Febrero | B28: 1926518569 | C28: 209434311 | D28: 7.8825106e+08 | E28: =B28-C28-D28 -> 9.2883319e+08
A29: Marzo | B29: 2957975259 | C29: 4.0398504e+08 | D29: 1.2181151e+09 | E29: =B29-C29-D29 -> 1.3358751e+09
A30: Abril | B30: 2576507119 | C30: 177647374 | D30: 1.2181151e+09 | E30: =B30-C30-D30 -> 1.1807446e+09
A31: Mayo | B31: 2708772247 | C31: 2.229398e+08 | D31: 1.2181151e+09 | E31: =B31-C31-D31 -> 1.2677173e+09
A32: Junio | B32: 2627397706 | C32: 191268154 | D32: 1.1507988e+09 | E32: =B32-C32-D32 -> 1.2853307e+09
A33: Julio | B33: 2805059680 | C33: 2.3836471e+08 | D33: 1.1507988e+09 | E33: =B33-C33-D33 -> 1.4158962e+09
A34: Agosto | B34: 2551762024 | C34: 2.5437239e+08 | D34: 1.1507988e+09 | E34: =B34-C34-D34 -> 1.1465908e+09
A35: Septiembre | B35: 3158847571 | C35: 3.1877597e+08 | D35: 1.1507988e+09 | E35: =B35-C35-D35 -> 1.6892728e+09
A36: Octubre | B36: 2666913591 | C36: 2.4482798e+08 | D36: 1.0264944e+09 | E36: =B36-C36-D36 -> 1.3955912e+09
A37: Noviembre | B37: 3463886297 | C37: 2.4124624e+08 | D37: 1.3329874e+09 | E37: =B37-C37-D37 -> 1.8896526e+09
A38: Diciembre | B38: 3055740585 | C38: 2.8410568e+08 | D38: 1.1412394e+09 | E38: =B38-C38-D38 -> 1.6303955e+09
A40: INDICADOR | B40: % Cumplimiento de Facturación y Radicado
A41: FORMULA | B41: Total ventas/ Total Facturado Total Facturado/ Total Radicado
A42: Meses | B42: Total Ventas Mensual | C42: Total facturado mensual | D42: Total radicado | E42: % de cumplimiento de facturación (>90%) | F42: % de cumplimiento de radicado (>95%)
A43: Enero | B43: 4375599842 | C43: 5273079603 | D43: 4972975450 | E43: =C43/B43 -> 1.2051101 | F43: =D43/C43 -> 0.9430875 | H43: =AVERAGE(E43:E51) -> 0.99246481 | I43: =AVERAGE(F43:F51) -> 0.95850079 | J43: =AVERAGE(H43:I43) -> 0.9754828
A44: Febrero | B44: 3884455523 | C44: 3360788034 | D44: 3067221567 | E44: =C44/B44 -> 0.86518896 | F44: =D44/C44 -> 0.91264951
...

Sheet 6
C1: INDICADORES | I1: CODIGO: FOR-GC-011
I2: VERSION: 0
I3: PAGINA: 6 DE 8
A4: OBJETIVO | C4: Establecer programas de formación permanentes, los cuales permitirán disponer de un personal con mayor nivel de cualificación para desempeñar las actividades comprendidas en el Sistema de gestión
A6: OBJETIVO ESPECIFICO | C6: Verificar el cumplimiento y eficacia del plan de formacion por medio de la evaluacion de capacitacion, la cual nos permita disponer de un personal con mayor nivel de cualificacion para desempeñar las actividades comprometidas en el sistema de gestion.
A8: INDICADOR | B8: Ejecución del programa de capacitación
A9: FORMULA | B9: Capacitaciones ejecutadas / Capacitaciones planeadas
A10: Meses | B10: Capacitaciones ejecutadas | C10: Capacitaciones planeadas | D10: % de Cumplimiento (>70%)
A11: Enero | B11: 1 | C11: 1 | D11: =B11/C11 -> 1
A12: Febrero | B12: 1 | C12: 2 | D12: =B12/C12 -> 0.5
A13: Marzo | B13: 1 | C13: 1 | D13: =B13/C13 -> 1
A14: Abril | B14: 1 | C14: 2 | D14: =B14/C14 -> 0.5
A15: Mayo | B15: 4 | C15: 5 | D15: =B15/C15 -> 0.8
A16: Junio | B16: 2 | C16: 2 | D16: =B16/C16 -> 1
A17: Julio | B17: 4 | C17: 4 | D17: =B17/C17 -> 1
A18: Agosto | B18: 4 | C18: 6 | D18: =B18/C18 -> 0.66666667
A19: Septiembre | B19: 10 | C19: 12 | D19: =B19/C19 -> 0.83333333
A20: Octubre | B20: 0 | C20: 4 | D20: =B20/C20 -> 0
A21: Noviembre | B21: 1 | C21: 4 | D21: =B21/C21 -> 0.25
A22: Diciembre | B22: 7 | C22: 7 | D22: =B22/C22 -> 1
B23: =SUM(B11:B22) -> 36 | C23: =SUM(C11:C22) -> 50 | D23: =(B23/C23)*100% -> 0.72
A24: Responsable: Lider de Gestion Humana

Sheet 7
C1: INDICADORES | I1: CODIGO: FOR-GC-011
I2: VERSION: 0
I3: PAGINA: 7 DE 8
A4: OBJETIVO | C4: Expandir y consolidar la relacion con proveedores buscando nuevas opciones en el mercado, diseñando herramientas y concertando acuerdos para adquirir beneficio mutuo.
A6: OBJETIVO ESPECIFICO | C6: Analizar el cumpliento de nuestros proveedores a traves de un seguimiento mensual para determinar el desempeño con la empresa y consolidar la relacion con el proveedor, creando acuerdos para adquirir beneficios mutuos.
A8: INDICADOR | B8: Evalución de Cumplimiento Proveedores
A9: FORMULA | B9: Sumatoria del resultado de todas las evaluaciones/ El total de las evaluaciones.
A10: Meses | B10: Sumatoria del resultado de todas las evaluaciones | C10: No. total de evaluaciones realizadas. | D10: Calificación (>95)
A11: Enero | B11: 1598 | C11: 16 | D11: =B11/C11 -> 99.875
A12: Febrero | B12: 1986 | C12: 20 | D12: =B12/C12 -> 99.3
A13: Marzo | B13: 1757 | C13: 18 | D13: =B13/C13 -> 97.611111
A14: Abril | B14: 2053 | C14: 21 | D14: =B14/C14 -> 97.761905
A15: Mayo | B15: 1668 | C15: 17 | D15: =B15/C15 -> 98.117647
A16: Junio | B16: 1944 | C16: 20 | D16: =B16/C16 -> 97.2
A17: Julio | B17: 1913 | C17: 20 | D17: =B17/C17 -> 95.65
A18: Agosto | B18: 1705 | C18: 18 | D18: =B18/C18 -> 94.722222
A19: Septiembre | B19: 1802 | C19: 19 | D19: =B19/C19 -> 94.842105
A20: Octubre | B20: 1736 | C20: 18 | D20: =B20/C20 -> 96.444444
A21: Noviembre | B21: 1830 | C21: 19 | D21: =B21/C21 -> 96.315789
A22: Diciembre | B22: 1929 | C22: 20 | D22: =B22/C22 -> 96.45
A24: Responsable: Jefe De Almacén | B24: Coordinador Logistico

Sheet 8
C1: INDICADORES | I1: CODIGO: FOR-GC-011
I2: VERSION: 0
I3: PAGINA: 8 DE 8
A4: OBJETIVO | C4: Fortalecer las relaciones comerciales con los clientes brindadoles credibilidad en la comercilización de nuestros productos y en la prestación de un buen servicio, atraves de facilidades de pago, entregas oportunas y atención de requerimientos.
A6: OBJETIVO ESPECIFICO | C6: Conocer el grado de aceptacion de nuestros clientes mediante la encuesta de satisfaccion con la finalidad de fortalecer las relaciones comerciales, brindandoles credibilidad en la comercializacion de nuestros productos y la prestacion de un buen servicio.
A8: INDICADOR | B8: Satisfacción del Cliente
A9: FORMULA | B9: Sumatoria del resultado de todas las evaluaciones/ El total de las evaluaciones.
A10: Meses | B10: Sumatoria del resultado de todas las evaluaciones | C10: No. total de evaluaciones realizadas. | D10: Calificación (>4.5)
A11: Primer Semestre | B11: 23.2 | C11: 5 | D11: =B11/C11 -> 4.64
A17: Segundo Semestre | B17: 25 | C17: 5 | D17: =B17/C17 -> 5
A24: Responsable: Coordinador Asistencial / Coordinador de calidad
L36: 3

Sheet ANALISIS
A1: ANALISIS DE INDICADORES
A2: 1 | B2: RESPONSABLE | C2: MESES | D2: ENERO | E2: FEBRERO | F2: MARZO | G2: ABRIL | H2: MAYO | I2: JUNIO | J2: JULIO | K2: AGOSTO | L2: SEPTIEMBRE | M2: OCTUBRE | N2: NOVIEMBRE | O2: DICIEMBRE
C3: INDICADOR
B4: Almacen Coordinador Logistico | C4: % de Ordenes de Compra recibidas completas | D4: En el mes de Enero de 2017 se cumplió con el indicador de compras debido a que los proveedores fueron oportunos en los tiempos de entrega. | E4: En el mes de Febrero de 2017 se cumplió con el indicador de compras debido a que los proveedores fueron oportunos en los tiempos de entrega. | F4: En el mes de Marzo de 2017 se cumplió con el indicador de compras debido a que los proveedores fueron oportunos en los tiempos de entrega. | G4: En el mes de Abril de 2017 se cumplió con el indicador de compras debido a que los proveedores fueron oportunos en los tiempos de entrega. | H4: En el mes de Mayo de 2017 se cumplió con el indicador de compras debido a que los proveedores fueron oportunos en los tiempos de entrega. | I4: En el mes de Junio de 2017 se cumplió con el indicador de compras debido a que los proveedores fueron oportunos en los tiempos de entrega. | J4: En el mes de Julio de 2017 se cumplió con el indicador de compras debido a que los proveedores fueron oportunos en los tiempos de entrega. | K4: En el mes de Agosto de 2017 se cumplió con el indicador de compras debido a que los proveedores fueron oportunos en los tiempos de entrega. | L4: En el mes de Septiembre de 2017 se cumplió con el indicador de compras debido a que los proveedores fueron oportunos en los tiempos de entrega. | M4: En el mes de Octubre de 2017 se cumplió con el indicador de compras debido a que los proveedores fueron oportunos en los tiempos de entrega. | N4: En el mes de Noviembre de 2017 se cumplió con el indicador de compras debido a que los proveedores fueron oportunos en los tiempos de entrega. | O4: En el mes de Diciembre de 2017 se cumplió con el indicador de compras debido a que los proveedores fueron oportunos en los tiempos de entrega.
B5: Almacen Coordinador Logistico | C5: % de incumplimiento de disponibilidad de dispositivos médicos
A6: 2 | B6: Asistencia Tecnica Coordinador Asistencial | C6: Evaluaciones de Seguimiento | D6: En el mes de Enero se cumplio con el indicador, ya que el servicio fue oportuno, tanto por la asesoria quirurgica como por el material utilizado. | E6: En el mes de febrero se cumplio satisfactoriamente con el indicador, ya que el material utilizado fue el adecuado y fue oportuna el servicio. | F6: En el mes de Marzo se cumplio con el indicador, ya que el servicio fue oportuno,, tanto por la asesoria quirurgica como por el material utilizado. | G6: En el mes de abril se alcanzaron los objetivos propuestos en nuestros indicadores , teniendo buen servicio, cumpliendo con buenas condiciones del material y prestando buenas asesorias quirurgicas. | H6: En el mes de mayo, se logro mantener el buen servicio, tannto en el material como en la prestacion de asesorias quirurgicas. | I6: En el mes de junio se cumplio satisfactoriamente con el indicador, ya que el material utilizado fue el adecuado y fue oportuna el servicio. | J6: En el mes de julio, no tuvimos inconvenientes por materiales, por loq ue se pudo cimplir satisfactoriamente con el servicio, dansole asesorias quirurgicas a cada procedimiento que lo requirio. | K6: En el mes de agosto se capacito a los asesres quirurgicos actualizandolos en ciertos procedimientos, para seguir ofreciendo el mejr servicio, este indicador se cumplio con éxito. | L6: En el mes de Septiembre se cumplio con el indicador, ya que el servicio fue oportuno, tanto por la asesoria quirurgica como por el material utilizado. | M6: se cumplio satisfactoriamente con el indioador, se va a la vanguadia con los asesores quirurgicos en la presentacion de nuevos productos se les hace capacitacion para que puedan ofrecer un servicio completo a los especialistas. | N6: En el mes de Noviembre se cumplio satisfactoriamente con el indicador, ya que el material utilizado fue el adecuado y fue oportuna el servicio. | O6: Culminamos el año, no solo cumpliendo con éxito el indicador, gracias al buen desempeño de los asesores y buena calidad en los productos utilizados.
B7: Asistencia Tecnica Coordinador Asistencial | C7: Atención a Quejas, Reclamos y/o Sugerencias | F7: en el mes de marzo se realizo por parte del artrscopista de una de nuestras bodegas, una sugerencia, el cual se dio respuesta por medio de una carta y enviando lo solicitado, para que no se viera afectado nuestro servicio.
A8: 3 | B8: Almacen Coordinador Logistico | C8: % de cumplimientos de especificaciones técnicas | D8: En el mes de Enero de 2017 se cumplió con el indicador de cumplimiento de especificaciones tecnicas porque los dispositivos fueron recibidos en optimas condiciones. | E8: En el mes de Febrero de 2017 se cumplió con el indicador de cumplimiento de especificaciones tecnicas porque los dispositivos fueron recibidos en optimas condiciones. | F8: En el mes de Marzo de 2017 se cumplió con el indicador de cumplimiento de especificaciones tecnicas porque los dispositivos fueron recibidos en optimas condiciones. | G8: En el mes de Abril de 2017 se cumplió con el indicador de cumplimiento de especificaciones tecnicas porque los dispositivos fueron recibidos en optimas condiciones. | H8: En el mes de Mayo de 2017 se cumplió con el indicador de cumplimiento de especificaciones tecnicas porque los dispositivos fueron recibidos en optimas condiciones. | I8: En el mes de Junio de 2017 se cumplió con el indicador de cumplimiento de especificaciones tecnicas porque los dispositivos fueron recibidos en optimas condiciones. | J8: En el mes de Julio de 2017 se cumplió con el indicador de cumplimiento de especificaciones tecnicas porque los dispositivos fueron recibidos en optimas condiciones. | K8: En el mes de Agosto de 2017 se cumplió con el indicador de cumplimiento de especificaciones tecnicas porque los dispositivos fueron recibidos en optimas condiciones. | L8: En el mes de Septiembre de 2017 se cumplió con el indicador de cumplimiento de especificaciones tecnicas porque los dispositivos fueron recibidos en optimas condiciones. | M8: En el mes de Octubre de 2017 se cumplió con el indicador de cumplimiento de especificaciones tecnicas porque los dispositivos fueron recibidos en optimas condiciones. | N8: En el mes de Noviembre de 2017 se cumplió con el indicador de cumplimiento de especificaciones tecnicas porque los dispositivos fueron recibidos en optimas condiciones. | O8: En el mes de Diciembre de 2017 se cumplió con el indicador de cumplimiento de especificaciones tecnicas porque los dispositivos fueron recibidos en optimas condiciones.
B9: Tecnovigilancia Coordinador Asistencial | C9: Reportes de Tecnovigilancia
A10: 4 | B10: Sistema de Gestion de Calidad Coordinador de Calidad | C10: Cierre de planes de acción
A11: 5 | B11: Contabilidad Lider de Contabilidad | C11: Cumplimiento de presupuesto | D11: En el mes de Enero de 2017 se cumplio el presupuesto porque se recaudo lo esperado para este mes | E11: En el mes de Febrero de 2017 se cumplio el presupuesto porque se recaudo lo esperado para este mes | F11: En el mes de Marzo de 2017 se cumplio el presupuesto porque se recaudo lo esperado para este mes | G11: En el mes de Abril de 2017 se cumplio el presupuesto porque se recaudo lo esperado para este mes | H11: En el mes de Mayo de 2017 se cumplio el presupuesto porque se recaudo lo esperado para este mes | I11: En el mes de Junio de 2017 se cumplio el presupuesto porque se recaudo lo esperado para este mes | J11: En el mes de Julio de 2017 se cumplio el presupuesto porque se recaudo lo esperado para este mes | K11: En el mes de Agosto de 2017 se cumplio el presupuesto porque se recaudo lo esperado para este mes | L11: En el mes de Septiembre de 2017 se cumplio el presupuesto porque se recaudo lo esperado para este mes | M11: En el mes de Octubre de 2017 no se cumplio el presupuesto debido a que no se recaudo lo esperado para este mes | N11: En el mes de Noviembre de 2017 no se cumplio el presupuesto debido a que no se recaudo lo esperado para este mes | O11: En el mes de Diciembre de 2017 no se cumplio el presupuesto debido a que no se recaudo lo esperado para este mes
B12: Contabilidad Lider de Contabilidad | C12: Utilidad Mensual | D12: En el mes de Enero del 2017 se cumplio el indicador de utilidad porque las ventas superaron las expectativas. | E12: En el mes de Febrero del 2017 no se cumplio el indicador de utilidad debido a que este mes solo fueron 28 dias por lo tanto no se alcanzaron las ventas deseadas | F12: En el mes de Marzo del 2017 se cumplio el indicador de utilidad porque las ventas superaron las expectativas. | G12: En el mes de Abril del 2017 se cumplio el indicador de utilidad porque las ventas superaron las expectativas. | H12: En el mes de Mayo del 2017 se cumplio el indicador de utilidad porque las ventas superaron las expectativas. | I12: En el mes de Junio del 2017 se cumplio el indicador de utilidad porque las ventas superaron las expectativas. | J12: En el mes de Julio del 2017 se cumplio el indicador de utilidad porque las ventas superaron las expectativas. | K12: En el mes de Agosto del 2017 se cumplio el indicador de utilidad porque las ventas superaron las expectativas. | L12: En el mes de Septiembre del 2017 se cumplio el indicador de utilidad porque las ventas superaron las expectativas. | M12: En el mes de Octubre del 2017 se cumplio el indicador de utilidad porque las ventas superaron las expectativas. | N12: En el mes de Noviembre del 2017 se cumplio el indicador de utilidad porque las ventas superaron las expectativas. | O12: En el mes de Diciembre del 2017 se cumplio el indicador de utilidad porque las ventas superaron las expectativas.
B13: Facturación Lider de Facturación | C13: % Cumplimiento de Facturación y Radicado | D13: En el mes de Enero del 2017 se cumplio con el indicador de lo facturado ya que se facturo lo vendido del mes en curso y lo pendiente del mes anterior. No se cumplio el indicador de lo Radicado ya que quedaron relaciones radicadas con fecha del mes siguiente por parte de las Ips. | E13: En el mes de Febrero del 2017 no se cumplio con el indicador de lo facturado ya que todo lo vendido no se facturo Oportunamente por cierre de mes. No se cumplio el indicador de lo Radicado ya que quedaron relaciones radicadas con fecha del mes siguiente por parte de las Ips. | F13: En el mes de Marzo del 2017 se cumplio con el indicador de lo facturado ya que se facturo lo vendido del mes en curso y lo pendiente del mes anterior. No se cumplio el indicador de lo Radicado ya que quedaron relaciones radicadas con fecha del mes siguiente por parte de las Ips. | G13: En el mes de Abril del 2017 se cumplio con el indicador de lo facturado ya que se facturo lo vendido del mes en curso y lo pendiente del mes anterior. se cumplio el indicador de lo Radicado ya que quedaron dos relaciones radicadas con fecha del mes siguiente por parte de las Ips. | H13: En el mes de Mayo del 2017 se cumplio con el indicador de lo facturado ya que se facturo lo vendido del mes en curso y lo pendiente del mes anterior. se cumplio el indicador de lo Radicado ya que quedo una relacion radicada con fecha del mes siguiente por parte de las Ips. | I13: En el mes de Junio del 2017 se cumplio con el indicador de lo facturado ya que lo vendido del mes en curso se facturo teniendo en cuenta los cortes de cierre. se cumplio el indicador de lo Radicado ya que todas las relaciones de facturas se radicaron dentro del mes por parte de las Ips. | J13: En el mes de Julio del 2017 se cumplio con el indicador de lo facturado ya que lo vendido del mes en curso se facturo teniendo en cuenta los cortes de cierre. se cumplio el indicador de lo Radicado ya que todas las relaciones de facturas se radicaron dentro del mes por parte de las Ips. | K13: En el mes de Agosto del 2017 se cumplio con el indicador de lo facturado ya que lo vendido del mes en curso se facturo teniendo en cuenta los cortes de cierre. se cumplio el indicador de lo Radicado ya que todas las relaciones de facturas se radicaron dentro del mes por parte de las Ips. | L13: En el mes de Septiembre del 2017 se cumplio con el indicador de lo facturado ya que lo vendido del mes en curso se facturo teniendo en cuenta los cortes de cierre. se cumplio el indicador de lo Radicado ya que todas las relaciones de facturas se radicaron dentro del mes por parte de las Ips. | M13: En el mes de Octubre del 2017 se cumplio con el indicador de lo facturado ya que lo vendido del mes en curso se facturo teniendo en cuenta los cortes de cierre. se cumplio el indicador de lo Radicado ya que todas las relaciones de facturas se radicaron dentro del mes por parte de las Ips. | N13: En el mes de Noviembre del 2017 se cumplio con el indicador de lo facturado ya que lo vendido del mes en curso se facturo teniendo en cuenta los cortes de cierre. se cumplio el indicador de lo Radicado ya que todas las relaciones de facturas se radicaron dentro del mes por parte de las Ips. | O13: En el mes de Diciembre del 2017 se cumplio con el indicador de lo facturado ya que se facturo lo vendido del mes en curso y lo pendiente del mes anterior. No se cumplio el indicador de lo Radicado ya que quedaron tres relaciones radicadas con fecha del mes siguiente por parte de las Ips.
B14: Facturación Lider de Facturación | C14: % Facturas Anuladas | D14: En el mes de Enero del 2017 se cumplio con el indicador de Anuladas ya que no hubo un alto nivel de error en las facturas Generadas | E14: En el mes de Febrero del 2017 se cumplio con el indicador de Anuladas ya que no hubo un alto nivel de error en las facturas Generadas | F14: En el mes de Marzo del 2017 se cumplio con el indicador de Anuladas ya que no hubo un alto nivel de error en las facturas Generadas | G14: En el mes de Abril del 2017 se cumplio con el indicador de Anuladas ya que no hubo un alto nivel de error en las facturas Generadas | H14: En el mes de Mayo del 2017 se cumplio con el indicador de Anuladas ya que no hubo un alto nivel de error en las facturas Generadas | I14: En el mes de Junio del 2017 se cumplio con el indicador de Anuladas ya que no hubo un alto nivel de error en las facturas Generadas | J14: En el mes de Julio del 2017 se cumplio con el indicador de Anuladas ya que no hubo un alto nivel de error en las facturas Generadas | K14: En el mes de Agosto del 2017 se cumplio con el indicador de Anuladas ya que no hubo un alto nivel de error en las facturas Generadas | L14: En el mes de Septiembre del 2017 se cumplio con el indicador de Anuladas ya que no hubo un alto nivel de error en las facturas Generadas | M14: En el mes de Octubre del 2017 se cumplio con el indicador de Anuladas ya que no hubo un alto nivel de error en las facturas Generadas | N14: En el mes de Noviembre del 2017 se cumplio con el indicador de Anuladas ya que no hubo un alto nivel de error en las facturas Generadas | O14: En el mes de Diciembre del 2017 se cumplio con el indicador de Anuladas ya que no hubo un alto nivel de error en las facturas Generadas
B15: Facturación Lider de Facturación | C15: % Facturas Glosadas por EPS | D15: En el mes de Enero del 2017 no se objetaron facturas por glosas. | E15: En el mes de Febrero del 2017 no se objetaron facturas por glosas. | F15: En el mes de Marzo del 2017 no se objetaron facturas por glosas. | G15: En el mes de Abril del 2017 no se objetaron facturas por glosas. | H15: En el mes de Mayo del 2017 no se objetaron facturas por glosas. | I15: En el mes de Junio del 2017 no se objetaron facturas por glosas. | J15: En el mes de Julio del 2017 no se objetaron facturas por glosas. | K15: En el mes de Agosto del 2017 no se objetaron facturas por glosas. | L15: En el mes de Septiembre del 2017 se cumplio el indicativo ya que se objetaron 3 Glosas por parte de Barrios Unidos | M15: En el mes de Octubre del 2017 no se objetaron facturas por glosas. | N15: En el mes de Noviembre del 2017 no se objetaron facturas por glosas. | O15: En el mes de Diciembre del 2017 no se objetaron facturas por glosas.
A16: 6 | B16: Gestion Humana Lider de Gestión Humana | C16: Ejecución del programa de capacitación | D16: En el mes de Enero el indicador se cumplió debido a que el facilitador de la capacitacion fue miembro de nuestra organización y por lo tanto no se requeria inversion economica para tal fin. | E16: El indicador no se cumplio debido a que no haubo flujo de dinero porque las IPS no cumplieron los acuerdos de pagos que se trazaron con Gerencia, lo cual afecto en la inversion en capacitaciones . | F16: En el mes de Marzo el indicador se cumplio debido a que se hizo una alianza estrategica con la camara de comercio el cual nos facilitó la realizacion de las capacitaciones planeadas. | G16: En el mes de Abril el indicador no se cumplio porque
A17: 7 | B17: Almacen Coordinador Logistico | C17: Evaluación de Cumplimiento Proveedores | D17: En el mes de Enero del 2017 se cumplió el indicador de evaluación de cumplimiento de proveedores, debido a que cumplieron con los parametros establecidos en la evaluación mensual, | E17: En el mes de Febrero del 2017 se cumplió el indicador de evaluación de cumplimiento de proveedores, debido a que cumplieron con los parametros establecidos en la evaluación mensual, | F17: En el mes de Marzo del 2017 se cumplió el indicador de evaluación de cumplimiento de proveedores, debido a que cumplieron con los parametros establecidos en la evaluación mensual, | G17: En el mes de Abril del 2017 se cumplió el indicador de evaluación de cumplimiento de proveedores, debido a que cumplieron con los parametros establecidos en la evaluación mensual, | H17: En el mes de Mayo del 2017 se cumplió el indicador de evaluación de cumplimiento de proveedores, debido a que cumplieron con los parametros establecidos en la evaluación mensual, | I17: En el mes de Junio del 2017 se cumplió el indicador de evaluación de cumplimiento de proveedores, debido a que cumplieron con los parametros establecidos en la evaluación mensual, | J17: En el mes de Julio del 2017 se cumplió el indicador de evaluación de cumplimiento de proveedores, debido a que cumplieron con los parametros establecidos en la evaluación mensual, | K17: En el mes de Agosto del 2017 se cumplió el indicador de evaluación de cumplimiento de proveedores, debido a que cumplieron con los parametros establecidos en la evaluación mensual, | L17: En el mes de Septiembre del 2017 se cumplió el indicador de evaluación de cumplimiento de proveedores, debido a que cumplieron con los parametros establecidos en la evaluación mensual, | M17: En el mes de Octubre del 2017 se cumplió el indicador de evaluación de cumplimiento de proveedores, debido a que cumplieron con los parametros establecidos en la evaluación mensual, | N17: En el mes de Noviembre del 2017 se cumplió el indicador de evaluación de cumplimiento de proveedores, debido a que cumplieron con los parametros establecidos en la evaluación mensual, | O17: En el mes de Diciembre del 2017 se cumplió el indicador de evaluación de cumplimiento de proveedores, debido a que cumplieron con los parametros establecidos en la evaluación mensual,
A18: 8 | B18: Asistencia Tecnica Coordinador Asistencial | C18: Satisfacción del Cliente
