Workbook

Sheet MATRIZ
A1: MATRIZ DE DESPLIEGUE DE POLÍTICA DE CALIDAD DE BIOSTEEL DE COLOMBIA
A4: POLITICA DE CALIDAD | C4: En Biosteel de Colombia S.A, somos una empresa dedicada a la importación, comercialización y distribución de dispositivos médicos de alta calidad. Por ello, nuestros esfuerzos se centran en satisfacer las necesidades y expectativas de especialistas, instituciones del área de la salud y usuarios mediante el compromiso de ejecutar los procedimientos bajo el direccionamiento de altos estándares de calidad, garantizando el cumplimiento de los requisitos legales exigibles, el mejoramiento continuo de nuestros procesos, la optimización de nuestros recursos, el desarrollo integral de nuestros colaboradores, la consolidación de alianzas estratégicas con nuestros proveedores y el fortalecimiento de las relaciones comerciales con los clientes.
A9: PREMISAS | C9: OBJETIVOS | H9: PROCESO | I9: RESPONSABLE | J9: INVOLUCRADOS DEL PROCESO | K9: PERSONAL RELACIONADO | L9: INDICADOR | M9: FORMULACIÓN | N9: META | O9: FRECUENCIA | P9: FUENTE DE DATOS | Q9: ENERO | R9: FEBRERO | S9: MARZO | T9: ABRIL | U9: MAYO | V9: JUNIO | W9: JULIO | X9: AGOSTO | Y9: SEPTIEMBRE | Z9: OCTUBRE | AA9: NOVIEMBRE | AB9: DICIEMBRE
A10: 1 | B10: Importación, comercialización y distribución | C10: Respaldar los procesos de importación, comercialización y distribuición a los clientes mediante la recepción, acondicionamento, almacenamiento, manejo y suministro de dispositivo médicos acorde a las normas vigentes de sanidad. | H10: Almacén Gerencia Administrativa | I10: Jefe de Almacén, Coordinador Asistencial, Gerente Administrativo | J10: Auxiliar de almacén, Asesor Quirúrgico, Auxiliar Administrativo | K10: Todo el personal de Biosteel De Colombia S.A | L10: % de Ordenes de Compra recibidas completas | M10: (No. Ordenes de Compra recibidas completas/ No. Ordenes recibidas) X 100 | N10: >70% | O10: Mensual | P10: Formato de Seguimiento a Proveedores | Q10: ='1'!D10 -> 0.97106109 | R10: ='1'!D11 -> 0.98344371 | S10: ='1'!D12 -> 0.98119122 | T10: ='1'!D13 -> 0.98823529 | U10: ='1'!D14 -> 0.98119122 | V10: ='1'!D15 -> 0.99431818 | W10: ='1'!D16 -> 0.98876404 | X10: ='1'!D17 -> 0.9862259 | Y10: ='1'!D18 -> 0.96043165 | Z10: ='1'!D19 -> 0.97115385 | AA10: ='1'!D20 -> 0.9559322 | AB10: ='1'!D21 -> 0.94555874
L11: Incumplimiento de disponibilidad de dispositivos médicos | M11: Número de Cirugías canceladas por falta de disponibilidad DM/ Número de Cirugías programas con requerimientos de DM | N11: 0 | O11: Mensual | P11: Formato de Ostesintesis Programas | Q11: ='1'!D26 -> 0 | R11: ='1'!D27 -> 0 | S11: ='1'!D28 -> 0 | T11: ='1'!D29 -> 0 | U11: ='1'!D30 -> 0 | V11: ='1'!D31 -> 0 | W11: ='1'!D32 -> 0 | X11: ='1'!D33 -> #DIV/0! | Y11: ='1'!D34 -> #DIV/0! | Z11: ='1'!D35 -> #DIV/0! | AA11: ='1'!D36 -> #DIV/0! | AB11: ='1'!D37 -> #DIV/0!
A12: 2 | B12: satisfacer las necesidades y expectativas de especialistas, instituciones del área de la salud y usuarios | C12: Crear estrategías de buen servicio que permitan optimizar el manejo de procesos y recursos con el fin de establecer mecanismos para garantizar la satisfacción del cliente. | H12: Asistencia Técnica | I12: Coordinador Asistencial | J12: Asesor Quirúrgico | K12: Todo el personal de Biosteel De Colombia S.A | L12: Atención a Quejas y Reclamos | M12: No. Quejas y reclamos recibidos = a No. De quejas y reclamos atendidos | N12: 1 | O12: Mensual | P12: Formato de quejas y reclamos | Q12: ='2'!D26 -> 1 | R12: ='2'!D27 -> N/A | S12: ='2'!D28 -> N/A | T12: ='2'!D29 -> 1 | U12: ='2'!D30 -> N/A | V12: ='2'!D31 -> N/A | W12: ='2'!D32 -> N/A | X12: ='2'!D33 -> N/A | Y12: ='2'!D34 -> N/A | Z12: ='2'!D35 -> N/A | AA12: ='2'!D36 -> N/A | AB12: ='2'!D37 -> N/A
L13: Evaluaciones de Seguimiento | M13: Sumatoria del resultado de todas las evaluaciones/ El total de las evaluaciones. | N13: 4 | O13: Mensual | P13: Evaluación de seguimiento de asesorías quirúrgicas | Q13: =('2'!B10+'2'!C10+'2'!D10)/3 -> 4.7521368 | R13: =('2'!B11+'2'!C11+'2'!D11)/3 -> 4.6767677 | S13: =('2'!B12+'2'!C12+'2'!D12)/3 -> 4.7536232 | T13: =('2'!B13+'2'!C13+'2'!D13)/3 -> 4.82 | U13: =('2'!B14+'2'!C14+'2'!D14)/3 -> 4.5666667 | V13: =('2'!B15+'2'!C15+'2'!D15)/3 -> 4.5666667 | W13: =('2'!B16+'2'!C16+'2'!D16)/3 -> 4.6333333 | X13: =('2'!B17+'2'!C17+'2'!D17)/3 -> 4.6333333 | Y13: =('2'!B18+'2'!C18+'2'!D18)/3 -> 4.4 | Z13: =('2'!B19+'2'!C19+'2'!D19)/3 -> 4.6 | AA13: =('2'!B20+'2'!C20+'2'!D20)/3 -> 4.4666667 | AB13: =('2'!B21+'2'!C21+'2'!D21)/3 -> #DIV/0!
A14: 3 | B14: garantizando el cumplimiento de los requisitos legales exigibles, | C14: Garantizar a los clientes confiabilidad con el cumpliento del manual de requisitos de Capacidad de Almacenamiento y/o Acondicionamiento para dispositivos médicos. | H14: Almacén, Asistencia Técnica | I14: Jefe de Almacén, Coordinador Asistencial | J14: Auxiliar de almacén, Asesor Quirúrgico | K14: Todo el personal de Biosteel De Colombia S.A | L14: Reportes de Tecnivigilancia | M14: No. De Reportes presentados/ No. De Reportes Notificacos al INVIMA | N14: 1 | O14: Trimestral | P14: Formato de Eventos o Incidentes Adversos | Q14: N/A | R14: N/A | S14: ='3'!D26 -> N/A | T14: N/A | U14: N/A | V14: ='3'!D29 -> 1 | W14: N/A | X14: N/A | Y14: ='3'!D32 -> N/A | Z14: N/A | AA14: N/A | AB14: ='3'!D35 -> N/A
L15: % de cumplimientos de especificaciones técnicas | M15: (No. De desviaciones encontradas/ No. De muestras verificadas) X 100 | N15: 1 | O15: Mensual | P15: Formato de Seguimiento a Proveedores | Q15: ='3'!D10 -> 1 | R15: ='3'!D11 -> 1 | S15: ='3'!D12 -> 1 | T15: ='3'!D13 -> 1 | U15: ='3'!D14 -> 1 | V15: ='3'!D15 -> 1 | W15: ='3'!D16 -> 1 | X15: ='3'!D17 -> #DIV/0! | Y15: ='3'!D18 -> #DIV/0! | Z15: ='3'!D19 -> #DIV/0! | AA15: ='3'!D20 -> #DIV/0! | AB15: ='3'!D21 -> #DIV/0!
A16: 4 | B16: el mejoramiento continuo de nuestros procesos | C16: Planificar, ejecutar, verificar y retroalimentar el sistema de gestión de calidad, a través de identificaciones de acciones correctivas, preventivas y de mejora continúa. | H16: Gestión de Calidad | I16: Coordinador de Calidad | J16: _ | K16: Todo el personal de Biosteel De Colombia S.A | L16: Cierre de planes de acción | M16: Planes de acción cerrados / No. Total de planes de acción | N16: >70% | O16: Trimestral | P16: Consolidado de acciones correctivas, preventivas y de mejora. | Q16: N/A | R16: N/A | S16: ='4'!D10 -> 0.98 | T16: N/A | U16: N/A | V16: ='4'!D13 -> 1 | W16: N/A | X16: N/A | Y16: ='4'!D16 -> #DIV/0! | Z16: N/A | AA16: N/A | AB16: ='4'!D19 -> #DIV/0!
A17: 5 | B17: optimización de nuestros recursos | C17: Consolidar un adecuado manejo financiero a traves de la contabilización adecuada, con el fin de generar confiabilidad entre los stakeholders de la compañía. | H17: Contabilidad Facturación | I17: Líder de Contabilidad y Líder de Facturación | J17: Auxiliar de Contabilidad | K17: Todo el personal de Biosteel De Colombia S.A | L17: % Cumplimiento de presupuesto | M17: Gasto real / Presupuesto | N17: >70% | O17: Mensual | P17: Formato de Informe de Presupuestos | Q17: ='5'!D10 -> 1.300452 | R17: ='5'!D11 -> 1.4904969 | S17: ='5'!D12 -> 1.5312719 | T17: ='5'!D13 -> 1.2727649 | U17: ='5'!D14 -> 1.0950831 | V17: ='5'!D15 -> 1.2393646 | W17: ='5'!D16 -> #DIV/0! | X17: ='5'!D17 -> #DIV/0! | Y17: ='5'!D18 -> #DIV/0! | Z17: ='5'!D19 -> #DIV/0! | AA17: ='5'!D20 -> #DIV/0! | AB17: ='5'!D21 -> #DIV/0!
L18: Utilidad Mensual | M18: Ventas - Cuentas por pagar - Gastos | N18: 1000000000 | O18: Mensual | P18: Informes de cuentas por pagar y cuentas por cobrar | Q18: ='5'!E26 -> 1230273658 | R18: ='5'!E27 -> 1037529326 | S18: ='5'!E28 -> 999422576 | T18: ='5'!E29 -> 1277198841 | U18: ='5'!E30 -> 1398372865 | V18: ='5'!E31 -> 1177689086 | W18: ='5'!E32 -> 0 | X18: ='5'!E33 -> 0 | Y18: ='5'!E34 -> 0 | Z18: ='5'!E35 -> 0 | AA18: ='5'!E36 -> 0 | AB18: ='5'!E37 -> 0
L19: % Cumplimiento Facturado | M19: Total ventas/ Total Facturado | N19: 0.9 | O19: Mensual | P19: Informes de Facturación | Q19: ='5'!E42 -> 0.94283266 | R19: ='5'!E43 -> 0.9299746 | S19: ='5'!E44 -> 1.0537578 | T19: ='5'!E45 -> 0.9048447 | U19: ='5'!E46 -> 1.0490492 | V19: ='5'!E47 -> 1.0429537 | W19: ='5'!E48 -> 0.95820692 | X19: ='5'!E49 -> 0.99202638 | Y19: ='5'!E50 -> #DIV/0! | Z19: ='5'!E51 -> #DIV/0! | AA19: ='5'!E52 -> #DIV/0! | AB19: ='5'!E53 -> #DIV/0!
L20: % Cumplimiento Radicado | M20: Total Facturado/ Total Radicado | N20: 0.95 | O20: Mensual | P20: Informes de Facturación | Q20: ='5'!F42 -> 1.0400919 | R20: ='5'!F43 -> 1.2102235 | S20: ='5'!F44 -> 0.92091103 | T20: ='5'!F45 -> 1.1107546 | U20: ='5'!F46 -> 1.0861161 | V20: ='5'!F47 -> 1.0146306 | W20: ='5'!F48 -> 1.0497046 | X20: ='5'!F49 -> 0.93421028 | Y20: ='5'!F50 -> #DIV/0! | Z20: ='5'!F51 -> #DIV/0! | AA20: ='5'!F52 -> #DIV/0! | AB20: ='5'!F53 -> #DIV/0!
L21: % Facturas Anuladas | M21: Facturas anuladas/ Facturas Generadas | N21: <5% | O21: Mensual | P21: Cuadro de Control Facturas
L22: % Facturas Glosadas por EPS | M22: Facturas Glosadas por EPS/ Facturas Generadas a EPS | N22: <5% | O22: Mensual | P22: Notificaciones de Glosas
A23: 6 | B23: el desarrollo integral de nuestros colaboradores, | C23: Establecer programas de formación permanentes, los cuales permitirán disponer de un personal con mayor nivel de cualificación para desempeñar las actividades comprendidas en el Sistema de gestión. | H23: Gestión Administrativa | I23: Gerente Administrativa | J23: _ | K23: Todo el personal de Biosteel De Colombia S.A | L23: Ejecución del programa de capacitación | M23: (Capacitaciones ejecutadas / Capacitaciones planeadas)*100% | N23: >70% | O23: Mensual | P23: Cronograma de capacitación | Q23: ='6'!D10 -> 0.75 | R23: ='6'!D11 -> 0.6 | S23: ='6'!D12 -> 0.16666667 | T23: ='6'!D13 -> 1 | U23: ='6'!D14 -> 0.75 | V23: ='6'!D15 -> 0.33333333 | W23: ='6'!D16 -> 0 | X23: ='6'!D17 -> 0 | Y23: ='6'!D18 -> 0 | Z23: ='6'!D19 -> 0 | AA23: ='6'!D20 -> 0 | AB23: ='6'!D21 -> 0
A24: 7 | B24: la consolidación de alianzas estratégicas solidas con nuestros proveedores | C24: Expandir y consolidar la relacion con proveedores buscando nuevas opciones en el mercado, diseñando herramientas y concertando acuerdos para adquirir beneficio mutuo. | H24: Almacén, Gestión Administrativa | I24: Jefe de Almacén | J24: _ | K24: Todo el personal de Biosteel De Colombia S.A | L24: Evalución de Cumplimiento Proveedores | M24: Sumatoria del resultado de todas las evaluaciones/ El total de las evaluaciones. | N24: >95 | O24: Mensual | P24: Formato de Evaluación de Proveedores | Q24: ='7'!D10 -> 94.692308 | R24: ='7'!D11 -> 94.416667 | S24: ='7'!D12 -> 94.833333 | T24: ='7'!D13 -> 94.25 | U24: ='7'!D14 -> 93.833333 | V24: ='7'!D15 -> 95 | W24: ='7'!D16 -> 94.5 | X24: ='7'!D17 -> 98.45 | Y24: ='7'!D18 -> #DIV/0! | Z24: ='7'!D19 -> #DIV/0! | AA24: ='7'!D20 -> #DIV/0! | AB24: ='7'!D21 -> #DIV/0!
A25: 8 | B25: el fortalecimiento de las relaciones comerciales con los clientes. | C25: Fortalecer las relaciones comerciales con los clientes brindadoles credibilidad en la comercilización de nuestros productos y en la prestación de un buen servicio, atraves de facilidades de pago, entregas oportunas y atención de requerimientos. | H25: Asistencia Técnica, Almacén, Facturación | I25: Coordinador Asistencial | J25: Auxiliar de Almacén, Asesor Quirúrgico, Auxiliar de Facturación, Auxiliar Administrativo | K25: Todo el personal de Biosteel De Colombia S.A | L25: Satisfacción del Cliente | M25: Sumatoria del resultado de todas las evaluaciones/ El total de las evaluaciones. | N25: >4.5 | O25: Semestral | P25: Formato de Satisfacción del Cliente | Q25: N/A | R25: N/A | S25: N/A | T25: N/A | U25: N/A | V25: ='8'!D10 -> 4.56 | W25: N/A | X25: N/A | Y25: N/A | Z25: N/A | AA25: N/A | AB25: ='8'!D16 -> #DIV/0!

Sheet 1
C1: INDICADORES | I1: CODIGO: FOR-GC-011
I2: VERSION: 0
I3: PAGINA: 1 DE 8
A4: OBJETIVO | B4: Respaldar los procesos de importación, comercialización y distribuición a los clientes mediante la recepción, acondicionamento, almacenamiento, manejo y suministro de dispositivo médicos acorde a las normas vigentes de sanidad.
A7: INDICADOR | B7: % de Ordenes de Compra recibidas completas
A8: FORMULA | B8: (No. Ordenes de Compra recibidas completas/ No. Ordenes totales recibidas)
A9: Meses | B9: No. Ordenes de Compra recibidas Completas | C9: No. De ordenes totales recibidas | D9: % de Cumplimiento (>70%)
A10: Enero | B10: 302 | C10: 311 | D10: =B10/C10 -> 0.97106109
A11: Febrero | B11: 297 | C11: 302 | D11: =B11/C11 -> 0.98344371
A12: Marzo | B12: 313 | C12: 319 | D12: =B12/C12 -> 0.98119122
A13: Abril | B13: 336 | C13: 340 | D13: =B13/C13 -> 0.98823529
A14: Mayo | B14: 313 | C14: 319 | D14: =B14/C14 -> 0.98119122
A15: Junio | B15: 350 | C15: 352 | D15: =B15/C15 -> 0.99431818
A16: Julio | B16: 440 | C16: 445 | D16: =B16/C16 -> 0.98876404
A17: Agosto | B17: 358 | C17: 363 | D17: =B17/C17 -> 0.9862259
A18: Septiembre | B18: 267 | C18: 278 | D18: =B18/C18 -> 0.96043165
A19: Octubre | B19: 303 | C19: 312 | D19: =B19/C19 -> 0.97115385
A20: Noviembre | B20: 282 | C20: 295 | D20: =B20/C20 -> 0.9559322
A21: Diciembre | B21: 330 | C21: 349 | D21: =B21/C21 -> 0.94555874
A23: INDICADOR | B23: % de incumplimiento de disponibilidad de dispositivos médicos
A24: FORMULA | B24: Número de Cirugías canceladas por falta de disponibilidad DM/ Número de Cirugías programas con requerimientos de DM
A25: Meses | B25: Número de Cirugías canceladas por falta de disponibilidad DM | C25: Número de Cirugías programas con requerimientos de DM | D25: % Incumplimiento de disponibilidad de DM
A26: Enero | B26: 0 | C26: 59 | D26: =B26/C26 -> 0
A27: Febrero | B27: 0 | C27: 133 | D27: =B27/C27 -> 0
A28: Marzo | B28: 0 | C28: 133 | D28: =B28/C28 -> 0
A29: Abril | B29: 0 | C29: 76 | D29: =B29/C29 -> 0
A30: Mayo | B30: 0 | C30: 102 | D30: =B30/C30 -> 0
A31: Junio | B31: 0 | C31: 108 | D31: =B31/C31 -> 0
A32: Julio | B32: 0 | C32: 127 | D32: =B32/C32 -> 0
A33: Agosto | D33: =B33/C33 -> #DIV/0!
A34: Septiembre | D34: =B34/C34 -> #DIV/0!
A35: Octubre | D35: =B35/C35 -> #DIV/0!
A36: Noviembre | D36: =B36/C36 -> #DIV/0!
A37: Diciembre | D37: =B37/C37 -> #DIV/0!
A39: Responsable: Jefe De Almacén

Sheet 2
C1: INDICADORES | I1: CODIGO: FOR-GC-011
I2: VERSION: 0
I3: PAGINA: 2 DE 8
A4: OBJETIVO | B4: Crear estrategías de buen servicio que permitan optimizar el manejo de procesos y recursos con el fin de establecer mecanismos para garantizar la satisfacción del cliente.
A7: INDICADOR | B7: Evaluaciones de Seguimiento
A8: FORMULA | B8: Sumatoria del resultado de todas las evaluaciones/ El No. total de evaluaciones realizadas.
A9: Meses | B9: Cumplimiento del servicio (>4.0) | C9: Condiciones del Material Utilizado (>4.0) | D9: Habilidad Soporte Técnico (>4.0)
A10: Enero | B10: =188/39 -> 4.8205128 | C10: =183/39 -> 4.6923077 | D10: =185/39 -> 4.7435897
A11: Febrero | B11: =317/66 -> 4.8030303 | C11: =280/66 -> 4.2424242 | D11: =329/66 -> 4.9848485
A12: Marzo | B12: =223/46 -> 4.8478261 | C12: =216/46 -> 4.6956522 | D12: =217/46 -> 4.7173913
A13: Abril | B13: =242/50 -> 4.84 | C13: =241/50 -> 4.82 | D13: =240/50 -> 4.8
A14: Mayo | B14: 4.6 | C14: 4.5 | D14: 4.6
A15: Junio | B15: 4.5 | C15: 4.5 | D15: 4.7
A16: Julio | B16: 4.6 | C16: 4.6 | D16: 4.7
A17: Agosto | B17: 4.7 | C17: 4.6 | D17: 4.6
A18: Septiembre | B18: 4.5 | C18: 4.3 | D18: 4.4
A19: Octubre | B19: 4.6 | C19: 4.6 | D19: 4.6
A20: Noviembre | B20: 4.4 | C20: 4.5 | D20: 4.5
A21: Diciembre | D21: =B21/C21 -> #DIV/0!
A23: INDICADOR | B23: Atención a Quejas y Reclamos
A24: FORMULA | B24: No. Quejas y reclamos atendidas / a No. De quejas y reclamos presentados * 100
A25: Meses | B25: Total de quejas o reclamos presentados | C25: Total de Quejas o Reclamos atendido | D25: Porcentaje de atención de Quejas y Reclamos
A26: Enero | B26: 1 | C26: 1 | D26: =C26/B26 -> 1
A27: Febrero | B27: 0 | C27: 0 | D27: N/A
A28: Marzo | B28: 0 | C28: 0 | D28: N/A
A29: Abril | B29: 1 | C29: 1 | D29: =C29/B29 -> 1
A30: Mayo | B30: 0 | C30: 0 | D30: N/A
A31: Junio | B31: 0 | C31: 0 | D31: N/A
A32: Julio | B32: 0 | C32: 0 | D32: N/A
A33: Agosto | B33: 0 | C33: 0 | D33: N/A
A34: Septiembre | B34: 0 | C34: 0 | D34: N/A
A35: Octubre | B35: 0 | C35: 0 | D35: N/A
A36: Noviembre | B36: 0 | C36: 0 | D36: N/A
A37: Diciembre | B37: 0 | C37: 0 | D37: N/A
A40: Responsable: Coordinador Asistencial

Sheet 3
C1: INDICADORES | I1: CODIGO: FOR-GC-011
I2: VERSION: 0
I3: PAGINA: 3 DE 8
A4: OBJETIVO | B4: Garantizar a los clientes confiabilidad con el cumpliento del manual de requisitos de Capacidad de Almacenamiento y/o Acondicionamiento para dispositivos médicos.
A7: INDICADOR | B7: % de cumplimientos de especificaciones técnicas
A8: FORMULA | B8: (No. De desviaciones encontradas/ No. De muestras verificadas)
A9: Meses | B9: No. De evaluaciones recibidas satisfactoriamente | C9: No. De muestras verificadas | D9: % de Cumplimiento (100%)
A10: Enero | B10: 17 | C10: 17 | D10: =B10/C10 -> 1
A11: Febrero | B11: 101 | C11: 101 | D11: =B11/C11 -> 1
A12: Marzo | B12: 45 | C12: 45 | D12: =B12/C12 -> 1
A13: Abril | B13: 77 | C13: 77 | D13: =B13/C13 -> 1
A14: Mayo | B14: 114 | C14: 114 | D14: =B14/C14 -> 1
A15: Junio | B15: 99 | C15: 99 | D15: =B15/C15 -> 1
A16: Julio | B16: 106 | C16: 106 | D16: =B16/C16 -> 1
A17: Agosto | D17: =B17/C17 -> #DIV/0!
A18: Septiembre | D18: =B18/C18 -> #DIV/0!
A19: Octubre | D19: =B19/C19 -> #DIV/0!
A20: Noviembre | D20: =B20/C20 -> #DIV/0!
A21: Diciembre | D21: =B21/C21 -> #DIV/0!
A23: INDICADOR | B23: Reportes de Tecnivigilancia
A24: FORMULA | B24: No. De Reportes Notificados al INVIMA / No. De Reportes Presentados * 100
A25: Meses | B25: No. De Reportes presentados | C25: No. De Reportes Notificacos al INVIMA | D25: % de Cumplimiento (100%)
A26: Enero - Marzo | B26: 0 | C26: 0 | D26: N/A
A29: Abril - Junio | B29: 1 | C29: 1 | D29: =C29/B29 -> 1
A32: Julio - Septiembre | B32: 0 | C32: 0 | D32: N/A
A35: Octubre - Dicembre | B35: 0 | C35: 0 | D35: N/A
A39: Responsable: Jefe De Almacén y Coordinador Asistencial

Sheet 4
C1: INDICADORES | I1: CODIGO: FOR-GC-011
I2: VERSION: 0
I3: PAGINA: 4 DE 8
A4: OBJETIVO | B4: Planificar, ejecutar, verificar y retroalimentar el sistema de gestión de calidad, a través de identificaciones de acciones correctivas, preventivas y de mejora continúa.
A7: INDICADOR | B7: Cierre de planes de acción
A8: FORMULA | B8: Planes de acción cerrados / No. Total de planes de acción
A9: Meses | B9: Planes de acción cerrados | C9: No. Total de planes de Accion | D9: % de Cumplimiento (100%)
A10: Enero - Marzo | B10: 98 | C10: 100 | D10: =B10/C10 -> 0.98
A13: Abril - Junio | B13: 100 | C13: 100 | D13: =B13/C13 -> 1
A16: Julio - Septiembre | D16: =B16/C16 -> #DIV/0!
A19: Octubre - Dicembre | D19: =B19/C19 -> #DIV/0!
A24: Responsable: Coordinador De Calidad

Sheet 5
C1: INDICADORES | I1: CODIGO: FOR-GC-011
I2: VERSION: 0
I3: PAGINA: 5 DE 8
A4: OBJETIVO | B4: Consolidar un adecuado manejo financiero a traves de la contabilización adecuada, con el fin de generar confiabilidad entre los stakeholders de la compañía.
A7: INDICADOR | B7: Cumplimiento de presupuesto
A8: FORMULA | B8: Gasto real / Presupuesto
A9: Meses | B9: Gasto real | C9: Gasto presupuestado | D9: % de Cumplimiento (>90%)
A10: Enero | B10: 890037560 | C10: 684406309 | D10: =B10/C10 -> 1.300452
A11: Febrero | B11: 1044104513 | C11: 700507680 | D11: =B11/C11 -> 1.4904969
A12: Marzo | B12: 1072667743 | C12: 700507680 | D12: =B12/C12 -> 1.5312719
A13: Abril | B13: 886490524 | C13: 696507680 | D13: =B13/C13 -> 1.2727649
A14: Mayo | B14: 871162169 | C14: 795521517 | D14: =B14/C14 -> 1.0950831
A15: Junio | B15: 989907138 | C15: 798721517 | D15: =B15/C15 -> 1.2393646
A16: Julio | D16: =B16/C16 -> #DIV/0!
A17: Agosto | D17: =B17/C17 -> #DIV/0!
A18: Septiembre | D18: =B18/C18 -> #DIV/0!
A19: Octubre | D19: =B19/C19 -> #DIV/0!
A20: Noviembre | D20: =B20/C20 -> #DIV/0!
A21: Diciembre | D21: =B21/C21 -> #DIV/0!
A23: INDICADOR | B23: Utilidad Mensual
A24: FORMULA | B24: Ventas - Cuentas por pagar - Gastos
A25: Meses | B25: Ingresos | C25: Gastos | D25: Costo | E25: Utilidad (>1,000,000,000)
A26: Enero | B26: 2075180140 | C26: 157302988 | D26: 687603494 | E26: =B26-C26-D26 -> 1230273658
A27: Febrero | B27: 2149769247 | C27: 256532006 | D27: 855707915 | E27: =B27-C27-D27 -> 1037529326
A28: Marzo | B28: 2035284265 | C28: 292629093 | D28: 743232596 | E28: =B28-C28-D28 -> 999422576
A29: Abril | B29: 2089127820 | C29: 130180740 | D29: 681748239 | E29: =B29-C29-D29 -> 1277198841
A30: Mayo | B30: 2093356352 | C30: 172254349 | D30: 522729138 | E30: =B30-C30-D30 -> 1398372865
A31: Junio | B31: 2165308873 | C31: 286053388 | D31: 701566399 | E31: =B31-C31-D31 -> 1177689086
A32: Julio | E32: =B32-C32-D32 -> 0
A33: Agosto | E33: =B33-C33-D33 -> 0
A34: Septiembre | E34: =B34-C34-D34 -> 0
A35: Octubre | E35: =B35-C35-D35 -> 0
A36: Noviembre | E36: =B36-C36-D36 -> 0
A37: Diciembre | E37: =B37-C37-D37 -> 0
A39: INDICADOR | B39: % Cumplimiento de Facturación y Radicado
A40: FORMULA | B40: Total ventas/ Total Facturado Total Facturado/ Total Radicado
A41: Meses | B41: Total Ventas Mensual | C41: Total facturado mensual | D41: Total radicado | E41: % de cumplimiento de facturación (<90%) | F41: % de cumplimiento de radicado (<95%)
A42: Enero | B42: 2616452486 | C42: 2775097428 | D42: 2668127233 | E42: =B42/C42 -> 0.94283266 | F42: =+C42/D42 -> 1.0400919
A43: Febrero | B43: 2669309527 | C43: 2870303698 | D43: 2371713744 | E43: =B43/C43 -> 0.9299746 | F43: =C43/D43 -> 1.2102235
A44: Marzo | B44: 2932716544 | C44: 2783103174 | D44: 3022119494 | E44: =B44/C44 -> 1.0537578 | F44: =C44/D44 -> 0.92091103
...

Sheet 6
C1: INDICADORES | I1: CODIGO: FOR-GC-011
I2: VERSION: 0
I3: PAGINA: 6 DE 8
A4: OBJETIVO | B4: Establecer programas de formación permanentes, los cuales permitirán disponer de un personal con mayor nivel de cualificación para desempeñar las actividades comprendidas en el Sistema de gestión
A7: INDICADOR | B7: Ejecución del programa de capacitación
A8: FORMULA | B8: Capacitaciones ejecutadas / Capacitaciones planeadas
A9: Meses | B9: Capacitaciones ejecutadas | C9: Capacitaciones planeadas | D9: % de Cumplimiento (>70%)
A10: Enero | B10: 3 | C10: 4 | D10: =B10/C10 -> 0.75
A11: Febrero | B11: 3 | C11: 5 | D11: =B11/C11 -> 0.6
A12: Marzo | B12: 1 | C12: 6 | D12: =B12/C12 -> 0.16666667
A13: Abril | B13: 4 | C13: 4 | D13: =B13/C13 -> 1
A14: Mayo | B14: 3 | C14: 4 | D14: =B14/C14 -> 0.75
A15: Junio | B15: 2 | C15: 6 | D15: =B15/C15 -> 0.33333333
A16: Julio | C16: 3 | D16: =B16/C16 -> 0
A17: Agosto | C17: 2 | D17: =B17/C17 -> 0
A18: Septiembre | C18: 3 | D18: =B18/C18 -> 0
A19: Octubre | C19: 2 | D19: =B19/C19 -> 0
A20: Noviembre | C20: 1 | D20: =B20/C20 -> 0
A21: Diciembre | C21: 1 | D21: =B21/C21 -> 0
B22: =SUM(B10:B21)/41 -> 0.3902439 | C22: =SUM(C10:C21)/41 -> 1
A23: Responsable: Gerente Administrativo

Sheet 7
C1: INDICADORES | I1: CODIGO: FOR-GC-011
I2: VERSION: 0
I3: PAGINA: 7 DE 8
A4: OBJETIVO | B4: Expandir y consolidar la relacion con proveedores buscando nuevas opciones en el mercado, diseñando herramientas y concertando acuerdos para adquirir beneficio mutuo.
A7: INDICADOR | B7: Evalución de Cumplimiento Proveedores
A8: FORMULA | B8: Sumatoria del resultado de todas las evaluaciones/ El total de las evaluaciones.
A9: Meses | B9: Sumatoria del resultado de todas las evaluaciones | C9: No. total de evaluaciones realizadas. | D9: Calificación (>95)
A10: Enero | B10: 1231 | C10: 13 | D10: =B10/C10 -> 94.692308
A11: Febrero | B11: 1133 | C11: 12 | D11: =B11/C11 -> 94.416667
A12: Marzo | B12: 1138 | C12: 12 | D12: =B12/C12 -> 94.833333
A13: Abril | B13: 1508 | C13: 16 | D13: =B13/C13 -> 94.25
A14: Mayo | B14: 1126 | C14: 12 | D14: =B14/C14 -> 93.833333
A15: Junio | B15: 1140 | C15: 12 | D15: =B15/C15 -> 95
A16: Julio | B16: 1134 | C16: 12 | D16: =B16/C16 -> 94.5
A17: Agosto | B17: 1969 | C17: 20 | D17: =B17/C17 -> 98.45
A18: Septiembre | D18: =B18/C18 -> #DIV/0!
A19: Octubre | D19: =B19/C19 -> #DIV/0!
A20: Noviembre | D20: =B20/C20 -> #DIV/0!
A21: Diciembre | D21: =B21/C21 -> #DIV/0!
A23: Responsable: Jefe De Almacén

Sheet 8
C1: INDICADORES | I1: CODIGO: FOR-GC-011
I2: VERSION: 0
I3: PAGINA: 8 DE 8
A4: OBJETIVO | B4: Fortalecer las relaciones comerciales con los clientes brindadoles credibilidad en la comercilización de nuestros productos y en la prestación de un buen servicio, atraves de facilidades de pago, entregas oportunas y atención de requerimientos.
A7: INDICADOR | B7: Satisfacción del Cliente
A8: FORMULA | B8: Sumatoria del resultado de todas las evaluaciones/ El total de las evaluaciones.
A9: Meses | B9: Sumatoria del resultado de todas las evaluaciones | C9: No. total de evaluaciones realizadas. | D9: Calificación (>4.5)
A10: Primer Semestre | B10: 22.8 | C10: 5 | D10: =B10/C10 -> 4.56
A16: Segundo Semestre | D16: =B16/C16 -> #DIV/0!
A23: Responsable: Coordinador Asistencial
