Workbook
Name AÑO: PARAMETROS!$H$3:$H$7
Name BD_AÑO_FINAL: OFFSET(NOVEDADES!$L$4,0,0,NOVEDADES!$A$2,1)
Name BD_AÑO_INICIO: OFFSET(NOVEDADES!$I$4,0,0,NOVEDADES!$A$2,1)
Name BD_DIA_FINAL: OFFSET(NOVEDADES!$J$4,0,0,NOVEDADES!$A$2,1)
Name BD_DIA_INCIO: OFFSET(NOVEDADES!$G$4,0,0,NOVEDADES!$A$2,1)
Name BD_DIAS_NOVEDAD: OFFSET(NOVEDADES!#REF!,0,0,NOVEDADES!$A$2,1)
Name BD_MES_FINAL: OFFSET(NOVEDADES!$K$4,0,0,NOVEDADES!$A$2,1)
Name BD_MES_INICIO: OFFSET(NOVEDADES!$H$4,0,0,NOVEDADES!$A$2,1)
Name BD_NOMBRE: OFFSET(NOVEDADES!$A$4,0,0,NOVEDADES!$A$2,1)
Name BD_NOVEDAD: OFFSET(NOVEDADES!$D$4,0,0,NOVEDADES!$A$2,1)
Name FECHA_FINAL: OFFSET(NOVEDADES!$F$4,0,0,NOVEDADES!$A$2,1)
Name FECHA_INICIO: OFFSET(NOVEDADES!$E$4,0,0,NOVEDADES!$A$2,1)
Name MESES: PARAMETROS!$E$3:$E$14
Name MTZ_CARGO: OFFSET(PARAMETROS!$A$3,0,0,PARAMETROS!$A$1,3)
Name MTZ_DIAS_NOVEDAD: OFFSET(NOVEDADES!$A$4,0,0,NOVEDADES!$A$2,8)
Name MTZ_DPTO: OFFSET(PARAMETROS!$A$3,0,0,PARAMETROS!$A$1,2)
Name MTZ_NOMBRE: OFFSET(PARAMETROS!$A$3,0,0,PARAMETROS!$A$1,1)
Name MTZ_NOVEDAD: OFFSET(NOVEDADES!$D$4,0,0,NOVEDADES!$A$2,5)
Name NOVEDADES: OFFSET(PARAMETROS!$G$4,0,0,PARAMETROS!$G$3,1)

Sheet PARAMETROS
A1: =COUNTA(A3:A1048576) -> 51
A2: NOMBRE | B2: DEPARTAMENTO | C2: CARGO
A3: Stefany Uribe | B3: Asistencial | C3: Coordinadora | G3: =COUNTA(G4:G1048576) -> 19
A4: Karina Jimenez | B4: Contabilidad | C4: Auxiliar | G4: Examenes Medicos
A5: Paula De Leon | B5: Gestion Humana | C5: Coordinadora | G5: Diligencia Personal
A6: Martha Orozco | B6: Contabilidad | C6: Lider | G6: Universidad
A7: Jeissy Gutierrez | B7: Asistencial | C7: Instrumentadora | G7: Cita Medica
A8: Frank Egurrola | B8: Facturacion | C8: Auxiliar | G8: Cita odontologica
A9: Melissa Charris | B9: Facturacion | C9: lider | G9: Enfermedad Familiar
A10: Yanina Vargas | B10: Almacen | C10: Lider | G10: Registro Civil
A11: Anthony Orrego | B11: Almacen | C11: Auxiliar | G11: Permiso Diligencia de la Empresa
A12: Andreina Cequea | B12: Facturacion | C12: Lider | G12: Compromiso Familiar
A13: Zullys Bernal | B13: Facturacion | C13: Auxiliar | G13: Dia compensatorio
A14: Angelica Rivera | B14: Contabilidad | C14: Auxiliar | G14: Control Prenatal
A15: Maria Angelica Parejo | B15: Contabilidad | C15: Auxiliar | G15: Malestar General
... A22: Frank Egurrola | B22: Contabilidad | C22: Auxiliar | G22: Sufragio elecciones
A23: Felix orrejanegra | B23: Contabilidad | C23: Auxiliar
A24: Jorge Gomez | B24: Facturacion | C24: Auxiliar
A25: Adriana De La Cruz | B25: Almacen | C25: Cotizaciones
A26: Carlos Orrego | B26: Almacen | C26: Auxiliar
A27: Ronnie Figueroa | B27: Almacen | C27: Auxiliar
A28: Kerlys Carrat | B28: Almacen | C28: Auxiliar
A29: Flor Herrera | B29: Servicios Generales | C29: Auxiliar
A30: Jose Henao | B30: Recepcion | C30: Recepcion
A31: Karine De Aguas | B31: Gestion Humana | C31: Lider
A32: German Miranda | B32: Asistencial | C32: Instrumentador
A33: Fahyzully Rios | B33: Asistencial | C33: Instrumentador
A34: Fahy rouz Maldonado | B34: Asistencial | C34: Instrumentador
... A53: Antony Orrego | B53: Almacen | C53: Auxiliar

Sheet NOVEDADES
A1: INDICADOR DE AUSENTISMO 2018
A2: =COUNTA(A4:A1048576) -> 29
A3: NOMBRE | B3: PROCESO | C3: CARGO | D3: MOTIVO DEL PERMISO | E3: FECHA | F3: MES | N3: NOMBRE | O3: DEPARTAMENTO | P3: CARGO | Q3: No PERMISOS
A4: JORGE GOMEZ | B4: FACTURACION | C4: AUX DE FACTURACION | D4: Universidad | E4: 43117 | F4: ENERO | G4: =IF($E4="","",DAY($E4)) -> 17 | H4: =IF($E4="","",MONTH($E4)) -> 1 | I4: =IF($E4="","",YEAR($E4)) -> 2018 | J4: =IF($F4="","",DAY($F4)) -> #VALUE! | K4: =IF($F4="","",MONTH($F4)) -> #VALUE! | L4: =IF($F4="","",YEAR($F4)) -> #VALUE! | N4: JORGE GOMEZ | O4: FACTURACION | P4: AUX DE FACTURACION | Q4: 2
A5: JESNY LOMBO | B5: ASISTENCIA TECNICA | C5: LIDER ASESORIA QUIRURGICA | D5: Diligencia Personal | E5: 43124 | F5: ENERO | G5: =IF($E5="","",DAY($E5)) -> 24 | H5: =IF($E5="","",MONTH($E5)) -> 1 | I5: =IF($E5="","",YEAR($E5)) -> 2018 | J5: =IF($F5="","",DAY($F5)) -> #VALUE! | K5: =IF($F5="","",MONTH($F5)) -> #VALUE! | L5: =IF($F5="","",YEAR($F5)) -> #VALUE! | N5: JESNY LOMBO | O5: ASISTENCIA TECNICA | P5: LIDER DE ASESORIA QUIRURGICA | Q5: 1
A6: ANA FAHYZULLY RIOS | B6: ASISTENCIA TECNICA | C6: LIDER ASESORIA QUIRURGICA | D6: Diligencia Personal | E6: 43129 | F6: ENERO | G6: =IF($E6="","",DAY($E6)) -> 29 | H6: =IF($E6="","",MONTH($E6)) -> 1 | I6: =IF($E6="","",YEAR($E6)) -> 2018 | J6: =IF($F6="","",DAY($F6)) -> #VALUE! | K6: =IF($F6="","",MONTH($F6)) -> #VALUE! | L6: =IF($F6="","",YEAR($F6)) -> #VALUE! | N6: ANA FAHYZULLY RIOS | O6: ASISTENCIA TECNICA | P6: LIDER DE ASESORIA QUIRURGICA | Q6: 2
A7: NIURKA MARTINEZ NIETO | B7: CONTABILIDAD | C7: AUX CONTABLE | D7: Enfermedad Familiar | E7: 43133 | F7: FEBRERO | G7: =IF($E7="","",DAY($E7)) -> 2 | H7: =IF($E7="","",MONTH($E7)) -> 2 | I7: =IF($E7="","",YEAR($E7)) -> 2018 | J7: =IF($F7="","",DAY($F7)) -> #VALUE! | K7: =IF($F7="","",MONTH($F7)) -> #VALUE! | L7: =IF($F7="","",YEAR($F7)) -> #VALUE! | N7: NIURKA MARTINEZ | O7: CONTABILIDAD | P7: AUX DE CONTABILIDAD | Q7: 1
A8: MARIA ANGELICA PAREJO | B8: FACTURACION | C8: LIDER DE FACTURACION | D8: Diligencia Personal | E8: 43133 | F8: FEBRERO | G8: =IF($E8="","",DAY($E8)) -> 2 | H8: =IF($E8="","",MONTH($E8)) -> 2 | I8: =IF($E8="","",YEAR($E8)) -> 2018 | J8: =IF($F8="","",DAY($F8)) -> #VALUE! | K8: =IF($F8="","",MONTH($F8)) -> #VALUE! | L8: =IF($F8="","",YEAR($F8)) -> #VALUE! | N8: MARIA ANGELICA PAREJO | O8: FACTURACION | P8: LIDER DE FACTURACION | Q8: 4
A9: EMIRO VEGA | B9: ASISTENCIA TECNICA | C9: ASESOR QUIRURGICO | D9: Diligencia Personal | E9: 43133 | F9: FEBRERO | G9: =IF($E9="","",DAY($E9)) -> 2 | H9: =IF($E9="","",MONTH($E9)) -> 2 | I9: =IF($E9="","",YEAR($E9)) -> 2018 | J9: =IF($F9="","",DAY($F9)) -> #VALUE! | K9: =IF($F9="","",MONTH($F9)) -> #VALUE! | L9: =IF($F9="","",YEAR($F9)) -> #VALUE! | N9: EMIRO VEGA | O9: ASISTENCIA TECNICA | P9: ASESOR QUIRURGICO | Q9: 1
A10: MELISSA CHARRIS | B10: ALMACEN | C10: AUX DE ALMACEN | D10: Adquisicion de vivienda | E10: 43159 | F10: FEBRERO | G10: =IF($E10="","",DAY($E10)) -> 28 | H10: =IF($E10="","",MONTH($E10)) -> 2 | I10: =IF($E10="","",YEAR($E10)) -> 2018 | J10: =IF($F10="","",DAY($F10)) -> #VALUE! | K10: =IF($F10="","",MONTH($F10)) -> #VALUE! | L10: =IF($F10="","",YEAR($F10)) -> #VALUE! | N10: MELISSA CHARRIS | O10: ALMACEN | P10: AUX DE ALMACEN | Q10: 1
A11: ANA FAHYZULLY RIOS | B11: ASISTENCIA TECNICA | C11: LIDER ASESORIA QUIRURGICA | D11: Diligencia Personal | E11: 43159 | F11: FEBRERO | G11: =IF($E11="","",DAY($E11)) -> 28 | H11: =IF($E11="","",MONTH($E11)) -> 2 | I11: =IF($E11="","",YEAR($E11)) -> 2018 | J11: =IF($F11="","",DAY($F11)) -> #VALUE! | K11: =IF($F11="","",MONTH($F11)) -> #VALUE! | L11: =IF($F11="","",YEAR($F11)) -> #VALUE! | N11: JOSE CARLOS HENAO | O11: CALIDAD | P11: AUX DE CALIDAD | Q11: 1
A12: MARIA ANGELICA PAREJO | B12: FACTURACION | C12: LIDER DE FACTURACION | D12: Jurado de votacion | E12: 43160 | F12: MARZO | G12: =IF($E12="","",DAY($E12)) -> 1 | H12: =IF($E12="","",MONTH($E12)) -> 3 | I12: =IF($E12="","",YEAR($E12)) -> 2018 | J12: =IF($F12="","",DAY($F12)) -> #VALUE! | K12: =IF($F12="","",MONTH($F12)) -> #VALUE! | L12: =IF($F12="","",YEAR($F12)) -> #VALUE! | N12: ALEXANDER FIGUEROA | O12: ALMACEN | P12: AUX DE ALMACEN | Q12: 3
A13: JOSE CARLOS HENAO | B13: CALIDAD | C13: AUX DE CALIDAD | D13: Diligencia Personal | E13: 43162 | F13: MARZO | G13: =IF($E13="","",DAY($E13)) -> 3 | H13: =IF($E13="","",MONTH($E13)) -> 3 | I13: =IF($E13="","",YEAR($E13)) -> 2018 | J13: =IF($F13="","",DAY($F13)) -> #VALUE! | K13: =IF($F13="","",MONTH($F13)) -> #VALUE! | L13: =IF($F13="","",YEAR($F13)) -> #VALUE! | N13: KARINA JIMENEZ | O13: CONTABILIDAD | P13: AUX CONTABLE | Q13: 1
A14: ALEXANDER FIGUEROA | B14: ALMACEN | C14: AUX DE ALMACEN | D14: Diligencia Personal | E14: 43166 | F14: MARZO | G14: =IF($E15="","",DAY($E15)) -> 7 | H14: =IF($E15="","",MONTH($E15)) -> 3 | I14: =IF($E15="","",YEAR($E15)) -> 2018 | J14: =IF($F15="","",DAY($F15)) -> #VALUE! | K14: =IF($F15="","",MONTH($F15)) -> #VALUE! | L14: =IF($F15="","",YEAR($F15)) -> #VALUE! | N14: KERLYS CARATT | O14: ALMACEN | P14: AUX DE ALMACEN | Q14: 1
A15: ALEXANDER FIGUEROA | B15: ALMACEN | C15: AUX DE ALMACEN | D15: Diligencia Personal | E15: 43166 | F15: MARZO | G15: =IF($E16="","",DAY($E16)) -> 27 | H15: =IF($E16="","",MONTH($E16)) -> 3 | I15: =IF($E16="","",YEAR($E16)) -> 2018 | J15: =IF($F16="","",DAY($F16)) -> #VALUE! | K15: =IF($F16="","",MONTH($F16)) -> #VALUE! | L15: =IF($F16="","",YEAR($F16)) -> #VALUE! | N15: JEINS TORTELLO | O15: ALMACEN | P15: AUX DE ALMACEN | Q15: 1
A16: KARINA JIMENEZ | B16: CONTABILIDAD | C16: AUX CONTABLE | D16: Cita Medica | E16: 43186 | F16: MARZO | G16: =IF($E17="","",DAY($E17)) -> 5 | H16: =IF($E17="","",MONTH($E17)) -> 4 | I16: =IF($E17="","",YEAR($E17)) -> 2018 | J16: =IF($F17="","",DAY($F17)) -> #VALUE! | K16: =IF($F17="","",MONTH($F17)) -> #VALUE! | L16: =IF($F17="","",YEAR($F17)) -> #VALUE! | N16: ANGELICA RIVERA | O16: CONTABILIDAD | P16: AUX CONTABLE | Q16: 1
A17: ALEXANDER FIGUEROA | B17: ALMACEN | C17: AUX DE ALMACEN | D17: Permiso Diligencia de la Empresa | E17: 43195 | F17: ABRIL | G17: =IF($E18="","",DAY($E18)) -> 6 | H17: =IF($E18="","",MONTH($E18)) -> 4 | I17: =IF($E18="","",YEAR($E18)) -> 2018 | J17: =IF($F18="","",DAY($F18)) -> #VALUE! | K17: =IF($F18="","",MONTH($F18)) -> #VALUE! | L17: =IF($F18="","",YEAR($F18)) -> #VALUE! | N17: MARIO OROZCO TRILLO | O17: ALMACEN | P17: AUX DE ALMACEN | Q17: 1
A18: KERLYS CARATT | B18: ASISTENCIA TECNICA | C18: AUX DE ALMACEN | D18: Diligencia Personal | E18: 43196 | F18: ABRIL | G18: =IF($E20="","",DAY($E20)) -> 9 | H18: =IF($E20="","",MONTH($E20)) -> 4 | I18: =IF($E20="","",YEAR($E20)) -> 2018 | J18: =IF($F20="","",DAY($F20)) -> #VALUE! | K18: =IF($F20="","",MONTH($F20)) -> #VALUE! | L18: =IF($F20="","",YEAR($F20)) -> #VALUE! | N18: YURY LOZANO | O18: FACTURACION | P18: AUX DE FACTURACION | Q18: 3
A19: JEINS TORTELLO | B19: ALMACEN | C19: AUX DE ALMACEN | D19: Diligencia Personal | E19: 43196 | F19: ABRIL | G19: =IF($E21="","",DAY($E21)) -> 9 | H19: =IF($E21="","",MONTH($E21)) -> 4 | I19: =IF($E21="","",YEAR($E21)) -> 2018 | J19: =IF($F21="","",DAY($F21)) -> #VALUE! | K19: =IF($F21="","",MONTH($F21)) -> #VALUE! | L19: =IF($F21="","",YEAR($F21)) -> #VALUE! | N19: SANDRA NIEBLES | O19: ASISTENCIA TECNICA | P19: ASESOR QUIRURGICO | Q19: 1
A20: ANGELICA RIVERA | B20: CONTABILIDAD | C20: AUX CONTABLE | D20: Examenes Medicos | E20: 43199 | F20: ABRIL | G20: =IF($E22="","",DAY($E22)) -> 13 | H20: =IF($E22="","",MONTH($E22)) -> 4 | I20: =IF($E22="","",YEAR($E22)) -> 2018 | J20: =IF($F22="","",DAY($F22)) -> #VALUE! | K20: =IF($F22="","",MONTH($F22)) -> #VALUE! | L20: =IF($F22="","",YEAR($F22)) -> #VALUE! | N20: KEYLA PEREZ | O20: ASISTENCIA TECNICA | P20: COORDINADOR ASISTENCIAL | Q20: 1
A21: YURY LOZANO | B21: FACTURACION | C21: AUX DE FACTURACION | D21: Compromiso Familiar | E21: 43199 | F21: ABRIL | G21: =IF($E23="","",DAY($E23)) -> 20 | H21: =IF($E23="","",MONTH($E23)) -> 4 | I21: =IF($E23="","",YEAR($E23)) -> 2018 | J21: =IF($F23="","",DAY($F23)) -> #VALUE! | K21: =IF($F23="","",MONTH($F23)) -> #VALUE! | L21: =IF($F23="","",YEAR($F23)) -> #VALUE! | N21: SIGILFREDO SANTANA | O21: GESTION HUMANA | P21: AUX DE SISTEMAS | Q21: 1
A22: MARIO OROZCO | B22: ALMACEN | C22: AUX DE ALMACEN | D22: Diligencia Personal | E22: 43203 | F22: ABRIL | G22: =IF($E24="","",DAY($E24)) -> 20 | H22: =IF($E24="","",MONTH($E24)) -> 4 | I22: =IF($E24="","",YEAR($E24)) -> 2018 | J22: =IF($F24="","",DAY($F24)) -> #VALUE! | K22: =IF($F24="","",MONTH($F24)) -> #VALUE! | L22: =IF($F24="","",YEAR($F24)) -> #VALUE! | N22: FRANK EGURROLA | O22: FACTURACION | P22: AUX DE FACTURACION | Q22: 1
A23: YURY LOZANO | B23: FACTURACION | C23: AUX DE FACTURACION | D23: Enfermedad Familiar | E23: 43210 | F23: ABRIL | G23: =IF($E26="","",DAY($E26)) -> 7 | H23: =IF($E26="","",MONTH($E26)) -> 5 | I23: =IF($E26="","",YEAR($E26)) -> 2018 | J23: =IF($F26="","",DAY($F26)) -> #VALUE! | K23: =IF($F26="","",MONTH($F26)) -> #VALUE! | L23: =IF($F26="","",YEAR($F26)) -> #VALUE!
A24: MARIA ANGELICA PAREJO | B24: FACTURACION | C24: LIDER DE FACTURACION | D24: Curso de conduccion | E24: 43210 | F24: ABRIL | G24: =IF($E27="","",DAY($E27)) -> 30 | H24: =IF($E27="","",MONTH($E27)) -> 4 | I24: =IF($E27="","",YEAR($E27)) -> 2018 | J24: =IF($F27="","",DAY($F27)) -> #VALUE! | K24: =IF($F27="","",MONTH($F27)) -> #VALUE! | L24: =IF($F27="","",YEAR($F27)) -> #VALUE!
A25: MARIA ANGELICA PAREJO | B25: FACTURACION | C25: LIDER DE FACTURACION | D25: Universidad | E25: 43216 | F25: ABRIL
A26: YURY LOZANO | B26: FACTURACION | C26: AUX DE FACTURACION | D26: Calamidad domestica | E26: 43227 | F26: ABRIL | G26: =IF($E29="","",DAY($E29)) -> 29 | H26: =IF($E29="","",MONTH($E29)) -> 5 | I26: =IF($E29="","",YEAR($E29)) -> 2018 | J26: =IF($F29="","",DAY($F29)) -> #VALUE! | K26: =IF($F29="","",MONTH($F29)) -> #VALUE! | L26: =IF($F29="","",YEAR($F29)) -> #VALUE!
A27: SANDRA NIEBLES | B27: FACTURACION | C27: ASESOR QUIRURGICO | D27: Sufragio elecciones | E27: 43220 | F27: ABRIL | G27: =IF($E30="","",DAY($E30)) -> 16 | H27: =IF($E30="","",MONTH($E30)) -> 5 | I27: =IF($E30="","",YEAR($E30)) -> 2018 | J27: =IF($F30="","",DAY($F30)) -> #VALUE! | K27: =IF($F30="","",MONTH($F30)) -> #VALUE! | L27: =IF($F30="","",YEAR($F30)) -> #VALUE!
A28: JORGE GOMEZ | B28: FACTURACION | C28: AUX DE FACTURACION | D28: Dia compensatorio | E28: 43220 | F28: ABRIL
A29: KEYLA PEREZ | B29: ASISTENCIA TECNICA | C29: COORDINADOR ASISTENCIAL | D29: Cita odontologica | E29: 43249 | F29: MAYO | G29: =IF($E31="","",DAY($E31)) -> 17 | H29: =IF($E31="","",MONTH($E31)) -> 5 | I29: =IF($E31="","",YEAR($E31)) -> 2018 | J29: =IF($F31="","",DAY($F31)) -> #VALUE! | K29: =IF($F31="","",MONTH($F31)) -> #VALUE! | L29: =IF($F31="","",YEAR($F31)) -> #VALUE!
A30: SIGILFREDO SANTANA | B30: GESTION HUMANA | C30: AUX SISTEMAS | D30: Universidad | E30: 43236 | F30: MAYO | G30: =IF($E32="","",DAY($E32)) -> 12 | H30: =IF($E32="","",MONTH($E32)) -> 5 | I30: =IF($E32="","",YEAR($E32)) -> 2018 | J30: =IF($F32="","",DAY($F32)) -> #VALUE! | K30: =IF($F32="","",MONTH($F32)) -> #VALUE! | L30: =IF($F32="","",YEAR($F32)) -> #VALUE!
A31: MELISSA CHARRIS | B31: ALMACEN | C31: AUX DE ALMACEN | D31: Jurado de votacion | E31: 43237 | F31: MAYO | G31: =IF($E33="","",DAY($E33)) | H31: =IF($E33="","",MONTH($E33)) | I31: =IF($E33="","",YEAR($E33)) | J31: =IF($F33="","",DAY($F33)) | K31: =IF($F33="","",MONTH($F33)) | L31: =IF($F33="","",YEAR($F33))
A32: FRANK EGURROLA | B32: FACTURACION | C32: AUX DE FACTURACION | D32: Jurado de votacion | E32: 43232 | F32: MAYO | G32: =IF($E34="","",DAY($E34)) | H32: =IF($E34="","",MONTH($E34)) | I32: =IF($E34="","",YEAR($E34)) | J32: =IF($F34="","",DAY($F34)) | K32: =IF($F34="","",MONTH($F34)) | L32: =IF($F34="","",YEAR($F34))
G33: =IF($E35="","",DAY($E35)) | H33: =IF($E35="","",MONTH($E35)) | I33: =IF($E35="","",YEAR($E35)) | J33: =IF($F35="","",DAY($F35)) | K33: =IF($F35="","",MONTH($F35)) | L33: =IF($F35="","",YEAR($F35))
G34: =IF($E36="","",DAY($E36)) | H34: =IF($E36="","",MONTH($E36)) | I34: =IF($E36="","",YEAR($E36)) | J34: =IF($F36="","",DAY($F36)) | K34: =IF($F36="","",MONTH($F36)) | L34: =IF($F36="","",YEAR($F36))
G35: =IF($E37="","",DAY($E37)) | H35: =IF($E37="","",MONTH($E37)) | I35: =IF($E37="","",YEAR($E37)) | J35: =IF($F37="","",DAY($F37)) | K35: =IF($F37="","",MONTH($F37)) | L35: =IF($F37="","",YEAR($F37))
G36: =IF($E38="","",DAY($E38)) | H36: =IF($E38="","",MONTH($E38)) | I36: =IF($E38="","",YEAR($E38)) | J36: =IF($F38="","",DAY($F38)) | K36: =IF($F38="","",MONTH($F38)) | L36: =IF($F38="","",YEAR($F38))
G37: =IF($E40="","",DAY($E40)) | H37: =IF($E40="","",MONTH($E40)) | I37: =IF($E40="","",YEAR($E40)) | J37: =IF($F40="","",DAY($F40)) | K37: =IF($F40="","",MONTH($F40)) | L37: =IF($F40="","",YEAR($F40))
G38: =IF($E41="","",DAY($E41)) | H38: =IF($E41="","",MONTH($E41)) | I38: =IF($E41="","",YEAR($E41)) | J38: =IF($F41="","",DAY($F41)) | K38: =IF($F41="","",MONTH($F41)) | L38: =IF($F41="","",YEAR($F41))
G40: =IF($E42="","",DAY($E42)) | H40: =IF($E42="","",MONTH($E42)) | I40: =IF($E42="","",YEAR($E42)) | J40: =IF($F42="","",DAY($F42)) | K40: =IF($F42="","",MONTH($F42)) | L40: =IF($F42="","",YEAR($F42))
G41: =IF($E43="","",DAY($E43)) | H41: =IF($E43="","",MONTH($E43)) | I41: =IF($E43="","",YEAR($E43)) | J41: =IF($F43="","",DAY($F43)) | K41: =IF($F43="","",MONTH($F43)) | L41: =IF($F43="","",YEAR($F43))
...

Sheet CONSULTA
B2: INCAPACIDAD
B3: MES
B4: MAYO
B5: AÑO
B6: 2016 | F6: =MATCH(B4,MESES,0) -> #N/A
B7: NOMBRE | C7: DEPARTAMENTO | D7: CARGO | E7: NOVEDAD | F7: CANTIDAD
A8: 1 | B8: =+PARAMETROS!$A3 -> Stefany Uribe | C8: =IFERROR(VLOOKUP(B8,MTZ_DPTO,2,0),"") -> Asistencial | D8: =IFERROR(VLOOKUP(B8,MTZ_CARGO,3,0),"") -> Coordinadora | F8: =IF(SUMIFS(BD_DIAS_NOVEDAD,BD_NOMBRE,$B8,BD_MES_INICIO,$F$6,BD_AÑO_INICIO,$B$6,BD_NOVEDAD,$B$2)=0,"",SUMIFS(BD_DIAS_NOVEDAD,BD_NOMBRE,$B8,BD_MES_INICIO,$F$6,BD_AÑO_INICIO,$B$6,BD_NOVEDAD,$B$2)) -> #REF! | G8: =IFERROR(_xlfn.RANK.EQ(F8,$F$8:$F$149,0),"") | H8: =IFERROR(INDEX($B$8:$B$149,MATCH(A8,$G$8:$G$149,0)),"") | I8: =IFERROR(INDEX($F$8:$F$1048576,MATCH(A8,$G$8:$G$1048576,0)),"")
A9: 2 | B9: =+PARAMETROS!$A4 -> Karina Jimenez | C9: =IFERROR(VLOOKUP(B9,MTZ_DPTO,2,0),"") -> Contabilidad | D9: =IFERROR(VLOOKUP(B9,MTZ_CARGO,3,0),"") -> Auxiliar | F9: =IF(SUMIFS(BD_DIAS_NOVEDAD,BD_NOMBRE,$B9,BD_MES_INICIO,$F$6,BD_AÑO_INICIO,$B$6,BD_NOVEDAD,$B$2)=0,"",SUMIFS(BD_DIAS_NOVEDAD,BD_NOMBRE,$B9,BD_MES_INICIO,$F$6,BD_AÑO_INICIO,$B$6,BD_NOVEDAD,$B$2)) -> #REF! | G9: =IFERROR(_xlfn.RANK.EQ(F9,$F$8:$F$149,0),"") | H9: =IFERROR(INDEX($B$8:$B$149,MATCH(A9,$G$8:$G$149,0)),"") | I9: =IFERROR(INDEX($F$8:$F$1048576,MATCH(A9,$G$8:$G$1048576,0)),"")
A10: 3 | B10: =+PARAMETROS!$A5 -> Paula De Leon | C10: =IFERROR(VLOOKUP(B10,MTZ_DPTO,2,0),"") -> Gestion Humana | D10: =IFERROR(VLOOKUP(B10,MTZ_CARGO,3,0),"") -> Coordinadora | F10: =IF(SUMIFS(BD_DIAS_NOVEDAD,BD_NOMBRE,$B10,BD_MES_INICIO,$F$6,BD_AÑO_INICIO,$B$6,BD_NOVEDAD,$B$2)=0,"",SUMIFS(BD_DIAS_NOVEDAD,BD_NOMBRE,$B10,BD_MES_INICIO,$F$6,BD_AÑO_INICIO,$B$6,BD_NOVEDAD,$B$2)) -> #REF! | G10: =IFERROR(_xlfn.RANK.EQ(F10,$F$8:$F$149,0),"") | H10: =IFERROR(INDEX($B$8:$B$149,MATCH(A10,$G$8:$G$149,0)),"") | I10: =IFERROR(INDEX($F$8:$F$1048576,MATCH(A10,$G$8:$G$1048576,0)),"")
A11: 5 | B11: =+PARAMETROS!$A6 -> Martha Orozco | C11: =IFERROR(VLOOKUP(B11,MTZ_DPTO,2,0),"") -> Contabilidad | D11: =IFERROR(VLOOKUP(B11,MTZ_CARGO,3,0),"") -> Lider | F11: =IF(SUMIFS(BD_DIAS_NOVEDAD,BD_NOMBRE,$B11,BD_MES_INICIO,$F$6,BD_AÑO_INICIO,$B$6,BD_NOVEDAD,$B$2)=0,"",SUMIFS(BD_DIAS_NOVEDAD,BD_NOMBRE,$B11,BD_MES_INICIO,$F$6,BD_AÑO_INICIO,$B$6,BD_NOVEDAD,$B$2)) -> #REF! | G11: =IFERROR(_xlfn.RANK.EQ(F11,$F$8:$F$149,0),"") | H11: =IFERROR(INDEX($B$8:$B$149,MATCH(A11,$G$8:$G$149,0)),"") | I11: =IFERROR(INDEX($F$8:$F$1048576,MATCH(A11,$G$8:$G$1048576,0)),"")
A12: 6 | B12: =+PARAMETROS!$A7 -> Jeissy Gutierrez | C12: =IFERROR(VLOOKUP(B12,MTZ_DPTO,2,0),"") -> Asistencial | D12: =IFERROR(VLOOKUP(B12,MTZ_CARGO,3,0),"") -> Instrumentadora | F12: =IF(SUMIFS(BD_DIAS_NOVEDAD,BD_NOMBRE,$B12,BD_MES_INICIO,$F$6,BD_AÑO_INICIO,$B$6,BD_NOVEDAD,$B$2)=0,"",SUMIFS(BD_DIAS_NOVEDAD,BD_NOMBRE,$B12,BD_MES_INICIO,$F$6,BD_AÑO_INICIO,$B$6,BD_NOVEDAD,$B$2)) -> #REF! | G12: =IFERROR(_xlfn.RANK.EQ(F12,$F$8:$F$149,0),"") | H12: =IFERROR(INDEX($B$8:$B$149,MATCH(A12,$G$8:$G$149,0)),"") | I12: =IFERROR(INDEX($F$8:$F$1048576,MATCH(A12,$G$8:$G$1048576,0)),"")
A13: 7 | B13: =+PARAMETROS!$A8 -> Frank Egurrola | C13: =IFERROR(VLOOKUP(B13,MTZ_DPTO,2,0),"") -> Facturacion | D13: =IFERROR(VLOOKUP(B13,MTZ_CARGO,3,0),"") -> Auxiliar | F13: =IF(SUMIFS(BD_DIAS_NOVEDAD,BD_NOMBRE,$B13,BD_MES_INICIO,$F$6,BD_AÑO_INICIO,$B$6,BD_NOVEDAD,$B$2)=0,"",SUMIFS(BD_DIAS_NOVEDAD,BD_NOMBRE,$B13,BD_MES_INICIO,$F$6,BD_AÑO_INICIO,$B$6,BD_NOVEDAD,$B$2)) -> #REF! | G13: =IFERROR(_xlfn.RANK.EQ(F13,$F$8:$F$149,0),"") | H13: =IFERROR(INDEX($B$8:$B$149,MATCH(A13,$G$8:$G$149,0)),"") | I13: =IFERROR(INDEX($F$8:$F$1048576,MATCH(A13,$G$8:$G$1048576,0)),"")
A14: 8 | B14: =+PARAMETROS!$A9 -> Melissa Charris | C14: =IFERROR(VLOOKUP(B14,MTZ_DPTO,2,0),"") -> Facturacion | D14: =IFERROR(VLOOKUP(B14,MTZ_CARGO,3,0),"") -> lider | F14: =IF(SUMIFS(BD_DIAS_NOVEDAD,BD_NOMBRE,$B14,BD_MES_INICIO,$F$6,BD_AÑO_INICIO,$B$6,BD_NOVEDAD,$B$2)=0,"",SUMIFS(BD_DIAS_NOVEDAD,BD_NOMBRE,$B14,BD_MES_INICIO,$F$6,BD_AÑO_INICIO,$B$6,BD_NOVEDAD,$B$2)) -> #REF! | G14: =IFERROR(_xlfn.RANK.EQ(F14,$F$8:$F$149,0),"") | H14: =IFERROR(INDEX($B$8:$B$149,MATCH(A14,$G$8:$G$149,0)),"") | I14: =IFERROR(INDEX($F$8:$F$1048576,MATCH(A14,$G$8:$G$1048576,0)),"")
A15: 9 | B15: =+PARAMETROS!$A10 -> Yanina Vargas | C15: =IFERROR(VLOOKUP(B15,MTZ_DPTO,2,0),"") -> Almacen | D15: =IFERROR(VLOOKUP(B15,MTZ_CARGO,3,0),"") -> Lider | F15: =IF(SUMIFS(BD_DIAS_NOVEDAD,BD_NOMBRE,$B15,BD_MES_INICIO,$F$6,BD_AÑO_INICIO,$B$6,BD_NOVEDAD,$B$2)=0,"",SUMIFS(BD_DIAS_NOVEDAD,BD_NOMBRE,$B15,BD_MES_INICIO,$F$6,BD_AÑO_INICIO,$B$6,BD_NOVEDAD,$B$2)) -> #REF! | G15: =IFERROR(_xlfn.RANK.EQ(F15,$F$8:$F$149,0),"") | H15: =IFERROR(INDEX($B$8:$B$149,MATCH(A15,$G$8:$G$149,0)),"") | I15: =IFERROR(INDEX($F$8:$F$1048576,MATCH(A15,$G$8:$G$1048576,0)),"")
A16: 10 | B16: =+PARAMETROS!$A11 -> Anthony Orrego | C16: =IFERROR(VLOOKUP(B16,MTZ_DPTO,2,0),"") -> Almacen | D16: =IFERROR(VLOOKUP(B16,MTZ_CARGO,3,0),"") -> Auxiliar | F16: =IF(SUMIFS(BD_DIAS_NOVEDAD,BD_NOMBRE,$B16,BD_MES_INICIO,$F$6,BD_AÑO_INICIO,$B$6,BD_NOVEDAD,$B$2)=0,"",SUMIFS(BD_DIAS_NOVEDAD,BD_NOMBRE,$B16,BD_MES_INICIO,$F$6,BD_AÑO_INICIO,$B$6,BD_NOVEDAD,$B$2)) -> #REF! | G16: =IFERROR(_xlfn.RANK.EQ(F16,$F$8:$F$149,0),"") | H16: =IFERROR(INDEX($B$8:$B$149,MATCH(A16,$G$8:$G$149,0)),"") | I16: =IFERROR(INDEX($F$8:$F$1048576,MATCH(A16,$G$8:$G$1048576,0)),"")
A17: 11 | B17: =+PARAMETROS!$A12 -> Andreina Cequea | C17: =IFERROR(VLOOKUP(B17,MTZ_DPTO,2,0),"") -> Facturacion | D17: =IFERROR(VLOOKUP(B17,MTZ_CARGO,3,0),"") -> Lider | F17: =IF(SUMIFS(BD_DIAS_NOVEDAD,BD_NOMBRE,$B17,BD_MES_INICIO,$F$6,BD_AÑO_INICIO,$B$6,BD_NOVEDAD,$B$2)=0,"",SUMIFS(BD_DIAS_NOVEDAD,BD_NOMBRE,$B17,BD_MES_INICIO,$F$6,BD_AÑO_INICIO,$B$6,BD_NOVEDAD,$B$2)) -> #REF! | G17: =IFERROR(_xlfn.RANK.EQ(F17,$F$8:$F$149,0),"") | H17: =IFERROR(INDEX($B$8:$B$149,MATCH(A17,$G$8:$G$149,0)),"") | I17: =IFERROR(INDEX($F$8:$F$1048576,MATCH(A17,$G$8:$G$1048576,0)),"")
A18: 12 | B18: =+PARAMETROS!$A13 -> Zullys Bernal | C18: =IFERROR(VLOOKUP(B18,MTZ_DPTO,2,0),"") -> Facturacion | D18: =IFERROR(VLOOKUP(B18,MTZ_CARGO,3,0),"") -> Auxiliar | F18: =IF(SUMIFS(BD_DIAS_NOVEDAD,BD_NOMBRE,$B18,BD_MES_INICIO,$F$6,BD_AÑO_INICIO,$B$6,BD_NOVEDAD,$B$2)=0,"",SUMIFS(BD_DIAS_NOVEDAD,BD_NOMBRE,$B18,BD_MES_INICIO,$F$6,BD_AÑO_INICIO,$B$6,BD_NOVEDAD,$B$2)) -> #REF! | G18: =IFERROR(_xlfn.RANK.EQ(F18,$F$8:$F$149,0),"") | H18: =IFERROR(INDEX($B$8:$B$149,MATCH(A18,$G$8:$G$149,0)),"") | I18: =IFERROR(INDEX($F$8:$F$1048576,MATCH(A18,$G$8:$G$1048576,0)),"")
A19: 13 | B19: =+PARAMETROS!$A14 -> Angelica Rivera | C19: =IFERROR(VLOOKUP(B19,MTZ_DPTO,2,0),"") -> Contabilidad | D19: =IFERROR(VLOOKUP(B19,MTZ_CARGO,3,0),"") -> Auxiliar | F19: =IF(SUMIFS(BD_DIAS_NOVEDAD,BD_NOMBRE,$B19,BD_MES_INICIO,$F$6,BD_AÑO_INICIO,$B$6,BD_NOVEDAD,$B$2)=0,"",SUMIFS(BD_DIAS_NOVEDAD,BD_NOMBRE,$B19,BD_MES_INICIO,$F$6,BD_AÑO_INICIO,$B$6,BD_NOVEDAD,$B$2)) -> #REF! | G19: =IFERROR(_xlfn.RANK.EQ(F19,$F$8:$F$149,0),"") | H19: =IFERROR(INDEX($B$8:$B$149,MATCH(A19,$G$8:$G$149,0)),"") | I19: =IFERROR(INDEX($F$8:$F$1048576,MATCH(A19,$G$8:$G$1048576,0)),"")
A20: 14 | B20: =+PARAMETROS!$A16 -> Angie Ulchur | C20: =IFERROR(VLOOKUP(B20,MTZ_DPTO,2,0),"") -> Administrativa Cali | D20: =IFERROR(VLOOKUP(B20,MTZ_CARGO,3,0),"") -> Auxiliar | F20: =IF(SUMIFS(BD_DIAS_NOVEDAD,BD_NOMBRE,$B20,BD_MES_INICIO,$F$6,BD_AÑO_INICIO,$B$6,BD_NOVEDAD,$B$2)=0,"",SUMIFS(BD_DIAS_NOVEDAD,BD_NOMBRE,$B20,BD_MES_INICIO,$F$6,BD_AÑO_INICIO,$B$6,BD_NOVEDAD,$B$2)) -> #REF! | G20: =IFERROR(_xlfn.RANK.EQ(F20,$F$8:$F$149,0),"") | H20: =IFERROR(INDEX($B$8:$B$149,MATCH(A20,$G$8:$G$149,0)),"") | I20: =IFERROR(INDEX($F$8:$F$1048576,MATCH(A20,$G$8:$G$1048576,0)),"")
A21: 15 | B21: =+PARAMETROS!$A17 -> Julian Montealegre | C21: =IFERROR(VLOOKUP(B21,MTZ_DPTO,2,0),"") -> Asistencial | D21: =IFERROR(VLOOKUP(B21,MTZ_CARGO,3,0),"") -> Instrumentador | F21: =IF(SUMIFS(BD_DIAS_NOVEDAD,BD_NOMBRE,$B21,BD_MES_INICIO,$F$6,BD_AÑO_INICIO,$B$6,BD_NOVEDAD,$B$2)=0,"",SUMIFS(BD_DIAS_NOVEDAD,BD_NOMBRE,$B21,BD_MES_INICIO,$F$6,BD_AÑO_INICIO,$B$6,BD_NOVEDAD,$B$2)) -> #REF! | G21: =IFERROR(_xlfn.RANK.EQ(F21,$F$8:$F$149,0),"") | H21: =IFERROR(INDEX($B$8:$B$149,MATCH(A21,$G$8:$G$149,0)),"") | I21: =IFERROR(INDEX($F$8:$F$1048576,MATCH(A21,$G$8:$G$1048576,0)),"")
A22: 16 | B22: =+PARAMETROS!$A18 -> Mercedes Moreno | C22: =IFERROR(VLOOKUP(B22,MTZ_DPTO,2,0),"") -> Asistencial | D22: =IFERROR(VLOOKUP(B22,MTZ_CARGO,3,0),"") -> Instrumentadora | F22: =IF(SUMIFS(BD_DIAS_NOVEDAD,BD_NOMBRE,$B22,BD_MES_INICIO,$F$6,BD_AÑO_INICIO,$B$6,BD_NOVEDAD,$B$2)=0,"",SUMIFS(BD_DIAS_NOVEDAD,BD_NOMBRE,$B22,BD_MES_INICIO,$F$6,BD_AÑO_INICIO,$B$6,BD_NOVEDAD,$B$2)) -> #REF! | G22: =IFERROR(_xlfn.RANK.EQ(F22,$F$8:$F$149,0),"") | H22: =IFERROR(INDEX($B$8:$B$149,MATCH(A22,$G$8:$G$149,0)),"") | I22: =IFERROR(INDEX($F$8:$F$1048576,MATCH(A22,$G$8:$G$1048576,0)),"")
A23: 17 | B23: =+PARAMETROS!$A19 -> Loreley Jimenez | C23: =IFERROR(VLOOKUP(B23,MTZ_DPTO,2,0),"") -> Asistencial | D23: =IFERROR(VLOOKUP(B23,MTZ_CARGO,3,0),"") -> Instrumentadora | F23: =IF(SUMIFS(BD_DIAS_NOVEDAD,BD_NOMBRE,$B23,BD_MES_INICIO,$F$6,BD_AÑO_INICIO,$B$6,BD_NOVEDAD,$B$2)=0,"",SUMIFS(BD_DIAS_NOVEDAD,BD_NOMBRE,$B23,BD_MES_INICIO,$F$6,BD_AÑO_INICIO,$B$6,BD_NOVEDAD,$B$2)) -> #REF! | G23: =IFERROR(_xlfn.RANK.EQ(F23,$F$8:$F$149,0),"") | H23: =IFERROR(INDEX($B$8:$B$149,MATCH(A23,$G$8:$G$149,0)),"") | I23: =IFERROR(INDEX($F$8:$F$1048576,MATCH(A23,$G$8:$G$1048576,0)),"")
A24: 19 | C24: =IFERROR(VLOOKUP(B24,MTZ_DPTO,2,0),"") | D24: =IFERROR(VLOOKUP(B24,MTZ_CARGO,3,0),"") | F24: =IF(SUMIFS(BD_DIAS_NOVEDAD,BD_NOMBRE,$B24,BD_MES_INICIO,$F$6,BD_AÑO_INICIO,$B$6,BD_NOVEDAD,$B$2)=0,"",SUMIFS(BD_DIAS_NOVEDAD,BD_NOMBRE,$B24,BD_MES_INICIO,$F$6,BD_AÑO_INICIO,$B$6,BD_NOVEDAD,$B$2)) -> #REF! | G24: =IFERROR(_xlfn.RANK.EQ(F24,$F$8:$F$149,0),"") | H24: =IFERROR(INDEX($B$8:$B$149,MATCH(A24,$G$8:$G$149,0)),"") | I24: =IFERROR(INDEX($F$8:$F$1048576,MATCH(A24,$G$8:$G$1048576,0)),"")
A25: 20 | C25: =IFERROR(VLOOKUP(B25,MTZ_DPTO,2,0),"") | D25: =IFERROR(VLOOKUP(B25,MTZ_CARGO,3,0),"") | F25: =IF(SUMIFS(BD_DIAS_NOVEDAD,BD_NOMBRE,$B25,BD_MES_INICIO,$F$6,BD_AÑO_INICIO,$B$6,BD_NOVEDAD,$B$2)=0,"",SUMIFS(BD_DIAS_NOVEDAD,BD_NOMBRE,$B25,BD_MES_INICIO,$F$6,BD_AÑO_INICIO,$B$6,BD_NOVEDAD,$B$2)) -> #REF! | G25: =IFERROR(_xlfn.RANK.EQ(F25,$F$8:$F$149,0),"") | H25: =IFERROR(INDEX($B$8:$B$149,MATCH(A25,$G$8:$G$149,0)),"") | I25: =IFERROR(INDEX($F$8:$F$1048576,MATCH(A25,$G$8:$G$1048576,0)),"")
A26: 21 | C26: =IFERROR(VLOOKUP(B26,MTZ_DPTO,2,0),"") | D26: =IFERROR(VLOOKUP(B26,MTZ_CARGO,3,0),"") | F26: =IF(SUMIFS(BD_DIAS_NOVEDAD,BD_NOMBRE,$B26,BD_MES_INICIO,$F$6,BD_AÑO_INICIO,$B$6,BD_NOVEDAD,$B$2)=0,"",SUMIFS(BD_DIAS_NOVEDAD,BD_NOMBRE,$B26,BD_MES_INICIO,$F$6,BD_AÑO_INICIO,$B$6,BD_NOVEDAD,$B$2)) -> #REF! | G26: =IFERROR(_xlfn.RANK.EQ(F26,$F$8:$F$149,0),"") | H26: =IFERROR(INDEX($B$8:$B$149,MATCH(A26,$G$8:$G$149,0)),"") | I26: =IFERROR(INDEX($F$8:$F$1048576,MATCH(A26,$G$8:$G$1048576,0)),"")
A27: 22 | C27: =IFERROR(VLOOKUP(B27,MTZ_DPTO,2,0),"") | D27: =IFERROR(VLOOKUP(B27,MTZ_CARGO,3,0),"") | F27: =IF(SUMIFS(BD_DIAS_NOVEDAD,BD_NOMBRE,$B27,BD_MES_INICIO,$F$6,BD_AÑO_INICIO,$B$6,BD_NOVEDAD,$B$2)=0,"",SUMIFS(BD_DIAS_NOVEDAD,BD_NOMBRE,$B27,BD_MES_INICIO,$F$6,BD_AÑO_INICIO,$B$6,BD_NOVEDAD,$B$2)) -> #REF! | G27: =IFERROR(_xlfn.RANK.EQ(F27,$F$8:$F$149,0),"") | H27: =IFERROR(INDEX($B$8:$B$149,MATCH(A27,$G$8:$G$149,0)),"") | I27: =IFERROR(INDEX($F$8:$F$1048576,MATCH(A27,$G$8:$G$1048576,0)),"")
A28: 23 | C28: =IFERROR(VLOOKUP(B28,MTZ_DPTO,2,0),"") | D28: =IFERROR(VLOOKUP(B28,MTZ_CARGO,3,0),"") | F28: =IF(SUMIFS(BD_DIAS_NOVEDAD,BD_NOMBRE,$B28,BD_MES_INICIO,$F$6,BD_AÑO_INICIO,$B$6,BD_NOVEDAD,$B$2)=0,"",SUMIFS(BD_DIAS_NOVEDAD,BD_NOMBRE,$B28,BD_MES_INICIO,$F$6,BD_AÑO_INICIO,$B$6,BD_NOVEDAD,$B$2)) -> #REF! | G28: =IFERROR(_xlfn.RANK.EQ(F28,$F$8:$F$149,0),"") | H28: =IFERROR(INDEX($B$8:$B$149,MATCH(A28,$G$8:$G$149,0)),"") | I28: =IFERROR(INDEX($F$8:$F$1048576,MATCH(A28,$G$8:$G$1048576,0)),"")
A29: 24 | C29: =IFERROR(VLOOKUP(B29,MTZ_DPTO,2,0),"") | D29: =IFERROR(VLOOKUP(B29,MTZ_CARGO,3,0),"") | F29: =IF(SUMIFS(BD_DIAS_NOVEDAD,BD_NOMBRE,$B29,BD_MES_INICIO,$F$6,BD_AÑO_INICIO,$B$6,BD_NOVEDAD,$B$2)=0,"",SUMIFS(BD_DIAS_NOVEDAD,BD_NOMBRE,$B29,BD_MES_INICIO,$F$6,BD_AÑO_INICIO,$B$6,BD_NOVEDAD,$B$2)) -> #REF! | G29: =IFERROR(_xlfn.RANK.EQ(F29,$F$8:$F$149,0),"") | H29: =IFERROR(INDEX($B$8:$B$149,MATCH(A29,$G$8:$G$149,0)),"") | I29: =IFERROR(INDEX($F$8:$F$1048576,MATCH(A29,$G$8:$G$1048576,0)),"")
A30: 25 | C30: =IFERROR(VLOOKUP(B30,MTZ_DPTO,2,0),"") | D30: =IFERROR(VLOOKUP(B30,MTZ_CARGO,3,0),"") | F30: =IF(SUMIFS(BD_DIAS_NOVEDAD,BD_NOMBRE,$B30,BD_MES_INICIO,$F$6,BD_AÑO_INICIO,$B$6,BD_NOVEDAD,$B$2)=0,"",SUMIFS(BD_DIAS_NOVEDAD,BD_NOMBRE,$B30,BD_MES_INICIO,$F$6,BD_AÑO_INICIO,$B$6,BD_NOVEDAD,$B$2)) -> #REF! | G30: =IFERROR(_xlfn.RANK.EQ(F30,$F$8:$F$149,0),"") | H30: =IFERROR(INDEX($B$8:$B$149,MATCH(A30,$G$8:$G$149,0)),"") | I30: =IFERROR(INDEX($F$8:$F$1048576,MATCH(A30,$G$8:$G$1048576,0)),"")
A31: 26 | C31: =IFERROR(VLOOKUP(B31,MTZ_DPTO,2,0),"") | D31: =IFERROR(VLOOKUP(B31,MTZ_CARGO,3,0),"") | F31: =IF(SUMIFS(BD_DIAS_NOVEDAD,BD_NOMBRE,$B31,BD_MES_INICIO,$F$6,BD_AÑO_INICIO,$B$6,BD_NOVEDAD,$B$2)=0,"",SUMIFS(BD_DIAS_NOVEDAD,BD_NOMBRE,$B31,BD_MES_INICIO,$F$6,BD_AÑO_INICIO,$B$6,BD_NOVEDAD,$B$2)) -> #REF! | G31: =IFERROR(_xlfn.RANK.EQ(F31,$F$8:$F$149,0),"") | H31: =IFERROR(INDEX($B$8:$B$149,MATCH(A31,$G$8:$G$149,0)),"") | I31: =IFERROR(INDEX($F$8:$F$1048576,MATCH(A31,$G$8:$G$1048576,0)),"")
A32: 27 | C32: =IFERROR(VLOOKUP(B32,MTZ_DPTO,2,0),"") | D32: =IFERROR(VLOOKUP(B32,MTZ_CARGO,3,0),"") | F32: =IF(SUMIFS(BD_DIAS_NOVEDAD,BD_NOMBRE,$B32,BD_MES_INICIO,$F$6,BD_AÑO_INICIO,$B$6,BD_NOVEDAD,$B$2)=0,"",SUMIFS(BD_DIAS_NOVEDAD,BD_NOMBRE,$B32,BD_MES_INICIO,$F$6,BD_AÑO_INICIO,$B$6,BD_NOVEDAD,$B$2)) -> #REF! | G32: =IFERROR(_xlfn.RANK.EQ(F32,$F$8:$F$149,0),"") | H32: =IFERROR(INDEX($B$8:$B$149,MATCH(A32,$G$8:$G$149,0)),"") | I32: =IFERROR(INDEX($F$8:$F$1048576,MATCH(A32,$G$8:$G$1048576,0)),"")
A33: 28 | C33: =IFERROR(VLOOKUP(B33,MTZ_DPTO,2,0),"") | D33: =IFERROR(VLOOKUP(B33,MTZ_CARGO,3,0),"") | F33: =IF(SUMIFS(BD_DIAS_NOVEDAD,BD_NOMBRE,$B33,BD_MES_INICIO,$F$6,BD_AÑO_INICIO,$B$6,BD_NOVEDAD,$B$2)=0,"",SUMIFS(BD_DIAS_NOVEDAD,BD_NOMBRE,$B33,BD_MES_INICIO,$F$6,BD_AÑO_INICIO,$B$6,BD_NOVEDAD,$B$2)) -> #REF! | G33: =IFERROR(_xlfn.RANK.EQ(F33,$F$8:$F$149,0),"") | H33: =IFERROR(INDEX($B$8:$B$149,MATCH(A33,$G$8:$G$149,0)),"") | I33: =IFERROR(INDEX($F$8:$F$1048576,MATCH(A33,$G$8:$G$1048576,0)),"")
A34: 29 | C34: =IFERROR(VLOOKUP(B34,MTZ_DPTO,2,0),"") | D34: =IFERROR(VLOOKUP(B34,MTZ_CARGO,3,0),"") | F34: =IF(SUMIFS(BD_DIAS_NOVEDAD,BD_NOMBRE,$B34,BD_MES_INICIO,$F$6,BD_AÑO_INICIO,$B$6,BD_NOVEDAD,$B$2)=0,"",SUMIFS(BD_DIAS_NOVEDAD,BD_NOMBRE,$B34,BD_MES_INICIO,$F$6,BD_AÑO_INICIO,$B$6,BD_NOVEDAD,$B$2)) -> #REF! | G34: =IFERROR(_xlfn.RANK.EQ(F34,$F$8:$F$149,0),"") | H34: =IFERROR(INDEX($B$8:$B$149,MATCH(A34,$G$8:$G$149,0)),"") | I34: =IFERROR(INDEX($F$8:$F$1048576,MATCH(A34,$G$8:$G$1048576,0)),"")
A35: 30 | C35: =IFERROR(VLOOKUP(B35,MTZ_DPTO,2,0),"") | D35: =IFERROR(VLOOKUP(B35,MTZ_CARGO,3,0),"") | F35: =IF(SUMIFS(BD_DIAS_NOVEDAD,BD_NOMBRE,$B35,BD_MES_INICIO,$F$6,BD_AÑO_INICIO,$B$6,BD_NOVEDAD,$B$2)=0,"",SUMIFS(BD_DIAS_NOVEDAD,BD_NOMBRE,$B35,BD_MES_INICIO,$F$6,BD_AÑO_INICIO,$B$6,BD_NOVEDAD,$B$2)) -> #REF! | G35: =IFERROR(_xlfn.RANK.EQ(F35,$F$8:$F$149,0),"") | H35: =IFERROR(INDEX($B$8:$B$149,MATCH(A35,$G$8:$G$149,0)),"") | I35: =IFERROR(INDEX($F$8:$F$1048576,MATCH(A35,$G$8:$G$1048576,0)),"")
... A149: 144 | C149: =IFERROR(VLOOKUP(B149,MTZ_DPTO,2,0),"") | D149: =IFERROR(VLOOKUP(B149,MTZ_CARGO,3,0),"") | F149: =IF(SUMIFS(BD_DIAS_NOVEDAD,BD_NOMBRE,$B149,BD_MES_INICIO,$F$6,BD_AÑO_INICIO,$B$6,BD_NOVEDAD,$B$2)=0,"",SUMIFS(BD_DIAS_NOVEDAD,BD_NOMBRE,$B149,BD_MES_INICIO,$F$6,BD_AÑO_INICIO,$B$6,BD_NOVEDAD,$B$2)) -> #REF! | G149: =IFERROR(_xlfn.RANK.EQ(F149,$F$8:$F$149,0),"") | H149: =IFERROR(INDEX($B$8:$B$149,MATCH(A149,$G$8:$G$149,0)),"") | I149: =IFERROR(INDEX($F$8:$F$1048576,MATCH(A149,$G$8:$G$1048576,0)),"")
